Workbook

Sheet ESPN
A1: Rank | B1: Name | C1: Team | D1: Position | E1: Avg Price
A2: 1 | B2: Le'Veon Bell | C2: PIT | D2: RB | E2: 29
A3: 2 | B3: Todd Gurley | C3: LAR | D3: RB | E3: 28
A4: 3 | B4: David Johnson | C4: ARI | D4: RB | E4: 28
A5: 4 | B5: Ezekiel Elliott | C5: DAL | D5: RB | E5: 27
A6: 5 | B6: Rex Burkhead | C6: NE | D6: RB | E6: 5
A7: 5 | B7: Antonio Brown | C7: PIT | D7: WR | E7: 26
A8: 6 | B8: Saquon Barkley | C8: NYG | D8: RB | E8: 26
A9: 7 | B9: Alvin Kamara | C9: NO | D9: RB | E9: 25
A10: 8 | B10: Julio Jones | C10: ATL | D10: WR | E10: 25
A11: 9 | B11: Odell Beckham | C11: NYG | D11: WR | E11: 24
A12: 10 | B12: DeAndre Hopkins | C12: HOU | D12: WR | E12: 24
A13: 11 | B13: Kareem Hunt | C13: KC | D13: RB | E13: 23
... A281: 319 | B281: Jacoby Brissett | C281: IND | D281: QB | E281: 0

Sheet Scout.com
A1: Rank | B1: Name | C1: Team | D1: Position | E1: Avg Price
A2: 1 | B2: Saquon Barkley | C2: NYG | D2: RB | E2: 27
A3: 2 | B3: Todd Gurley | C3: LAR | D3: RB | E3: 19
A4: 3 | B4: Ezekiel Elliott | C4: DAL | D4: RB | E4: 19
A5: 4 | B5: Antonio Brown | C5: PIT | D5: WR | E5: 17
A6: 5 | B6: Le'Veon Bell | C6: PIT | D6: RB | E6: 17
A7: 6 | B7: David Johnson | C7: ARI | D7: RB | E7: 17
A8: 7 | B8: DeAndre Hopkins | C8: HOU | D8: WR | E8: 16
A9: 8 | B9: Odell Beckham | C9: NYG | D9: WR | E9: 16
A10: 9 | B10: Alvin Kamara | C10: NO | D10: RB | E10: 16
A11: 10 | B11: Michael Thomas | C11: NO | D11: WR | E11: 15
A12: 11 | B12: Derrius Guice | C12: WAS | D12: RB | E12: 14
A13: 12 | B13: Julio Jones | C13: ATL | D13: WR | E13: 14
... A159: 196 | B159: Houston Texans | C159: HOU | D159: D/ST | E159: 2

Sheet FantasyPro
A1: # | B1: Name | C1: Team | D1: Pos | E1: Value
A2: 1 | B2: Todd Gurley | C2: LAR | D2: RB | E2: 33
A3: 2 | B3: Le'Veon Bell | C3: PIT | D3: RB | E3: 31
A4: 3 | B4: Antonio Brown | C4: PIT | D4: WR | E4: 30
A5: 4 | B5: David Johnson | C5: ARI | D5: RB | E5: 27
A6: 5 | B6: Ezekiel Elliott | C6: DAL | D6: RB | E6: 27
A7: 6 | B7: DeAndre Hopkins | C7: HOU | D7: WR | E7: 24
A8: 7 | B8: Julio Jones | C8: ATL | D8: WR | E8: 24
A9: 8 | B9: Melvin Gordon | C9: LAC | D9: RB | E9: 22
A10: 9 | B10: Alvin Kamara | C10: NO | D10: RB | E10: 22
A11: 10 | B11: Odell Beckham | C11: NYG | D11: WR | E11: 22
A12: 11 | B12: Leonard Fournette | C12: JAC | D12: RB | E12: 21
A13: 12 | B13: Kareem Hunt | C13: KC | D13: RB | E13: 21
... A307: 306 | B307: Sebastian Janikowski | C307: SEA | D307: K | E307: 0

Sheet RotoWire
A1: Rank | B1: Name | C1: Team | D1: Pos | E1: Value
A2: 1 | B2: David Johnson | C2: ARI | D2: RB | E2: 29
A3: 2 | B3: Le'Veon Bell | C3: PIT | D3: RB | E3: 29
A4: 3 | B4: Saquon Barkley | C4: NYG | D4: RB | E4: 28
A5: 4 | B5: Todd Gurley | C5: LAR | D5: RB | E5: 28
A6: 5 | B6: Ezekiel Elliott | C6: DAL | D6: RB | E6: 26
A7: 6 | B7: Kareem Hunt | C7: KC | D7: RB | E7: 25
A8: 7 | B8: Alvin Kamara | C8: NO | D8: RB | E8: 25
A9: 8 | B9: Leonard Fournette | C9: JAC | D9: RB | E9: 21
A10: 9 | B10: Melvin Gordon | C10: LAC | D10: RB | E10: 21
A11: 10 | B11: Tom Brady | C11: NE | D11: QB | E11: 20
A12: 11 | B12: Jordan Howard | C12: CHI | D12: RB | E12: 19
A13: 12 | B13: Dalvin Cook | C13: MIN | D13: RB | E13: 19
... A619: 618 | B619: Miami Dolphins | C619: MIA | D619: D/ST | E619: 0

Sheet Masterview
A1: Name | B1: Team | C1: Position | D1: Bye Week | E1: ESPN | F1: Scout | G1: FantasyPro | H1: RotoWire | I1: Avg Going Rate | J1: Variation
A2: Todd Gurley | B2: LAR | C2: RB | D2: 12 | E2: =if(ISNA(vlookup($A2, ESPN!$B$2:$E$281, 4, false)), 0, vlookup($A2, ESPN!$B$2:$E$281, 4, false)) -> 28 | F2: =if(ISNA(vlookup($A2, Scout.com!$B$2:$E$239, 4, false)), 0, vlookup($A2, Scout.com!$B$2:$E$239, 4, false)) -> 19 | G2: =if(ISNA(vlookup($A2, FantasyPro!$B$2:$E$318, 4, false)), 0, vlookup($A2, FantasyPro!$B$2:$E$318, 4, false)) -> 33 | H2: =if(ISNA(vlookup($A2, RotoWire!$B$2:$E$681, 4, false)), 0, vlookup($A2, RotoWire!$B$2:$E$681, 4, false)) -> 28 | I2: =Average(E2:H2) -> 27 | J2: =max(E2:H2)-min(E2:H2) -> 14
A3: Le'Veon Bell | B3: PIT | C3: RB | D3: 7 | E3: =if(ISNA(vlookup($A3, ESPN!$B$2:$E$281, 4, false)), 0, vlookup($A3, ESPN!$B$2:$E$281, 4, false)) -> 29 | F3: =if(ISNA(vlookup($A3, Scout.com!$B$2:$E$239, 4, false)), 0, vlookup($A3, Scout.com!$B$2:$E$239, 4, false)) -> 17 | G3: =if(ISNA(vlookup($A3, FantasyPro!$B$2:$E$318, 4, false)), 0, vlookup($A3, FantasyPro!$B$2:$E$318, 4, false)) -> 31 | H3: =if(ISNA(vlookup($A3, RotoWire!$B$2:$E$681, 4, false)), 0, vlookup($A3, RotoWire!$B$2:$E$681, 4, false)) -> 29 | I3: =Average(E3:H3) -> 26.5 | J3: =max(E3:H3)-min(E3:H3) -> 14
A4: David Johnson | B4: ARI | C4: RB | D4: 9 | E4: =if(ISNA(vlookup($A4, ESPN!$B$2:$E$281, 4, false)), 0, vlookup($A4, ESPN!$B$2:$E$281, 4, false)) -> 28 | F4: =if(ISNA(vlookup($A4, Scout.com!$B$2:$E$239, 4, false)), 0, vlookup($A4, Scout.com!$B$2:$E$239, 4, false)) -> 17 | G4: =if(ISNA(vlookup($A4, FantasyPro!$B$2:$E$318, 4, false)), 0, vlookup($A4, FantasyPro!$B$2:$E$318, 4, false)) -> 27 | H4: =if(ISNA(vlookup($A4, RotoWire!$B$2:$E$681, 4, false)), 0, vlookup($A4, RotoWire!$B$2:$E$681, 4, false)) -> 29 | I4: =Average(E4:H4) -> 25.25 | J4: =max(E4:H4)-min(E4:H4) -> 12
A5: Saquon Barkley | B5: NYG | C5: RB | D5: 9 | E5: =if(ISNA(vlookup($A5, ESPN!$B$2:$E$281, 4, false)), 0, vlookup($A5, ESPN!$B$2:$E$281, 4, false)) -> 26 | F5: =if(ISNA(vlookup($A5, Scout.com!$B$2:$E$239, 4, false)), 0, vlookup($A5, Scout.com!$B$2:$E$239, 4, false)) -> 27 | G5: =if(ISNA(vlookup($A5, FantasyPro!$B$2:$E$318, 4, false)), 0, vlookup($A5, FantasyPro!$B$2:$E$318, 4, false)) -> 20 | H5: =if(ISNA(vlookup($A5, RotoWire!$B$2:$E$681, 4, false)), 0, vlookup($A5, RotoWire!$B$2:$E$681, 4, false)) -> 28 | I5: =Average(E5:H5) -> 25.25 | J5: =max(E5:H5)-min(E5:H5) -> 8
A6: Ezekiel Elliott | B6: DAL | C6: RB | D6: 8 | E6: =if(ISNA(vlookup($A6, ESPN!$B$2:$E$281, 4, false)), 0, vlookup($A6, ESPN!$B$2:$E$281, 4, false)) -> 27 | F6: =if(ISNA(vlookup($A6, Scout.com!$B$2:$E$239, 4, false)), 0, vlookup($A6, Scout.com!$B$2:$E$239, 4, false)) -> 19 | G6: =if(ISNA(vlookup($A6, FantasyPro!$B$2:$E$318, 4, false)), 0, vlookup($A6, FantasyPro!$B$2:$E$318, 4, false)) -> 27 | H6: =if(ISNA(vlookup($A6, RotoWire!$B$2:$E$681, 4, false)), 0, vlookup($A6, RotoWire!$B$2:$E$681, 4, false)) -> 26 | I6: =Average(E6:H6) -> 24.75 | J6: =max(E6:H6)-min(E6:H6) -> 8
A7: Antonio Brown | B7: PIT | C7: WR | D7: 7 | E7: =if(ISNA(vlookup($A7, ESPN!$B$2:$E$281, 4, false)), 0, vlookup($A7, ESPN!$B$2:$E$281, 4, false)) -> 26 | F7: =if(ISNA(vlookup($A7, Scout.com!$B$2:$E$239, 4, false)), 0, vlookup($A7, Scout.com!$B$2:$E$239, 4, false)) -> 17 | G7: =if(ISNA(vlookup($A7, FantasyPro!$B$2:$E$318, 4, false)), 0, vlookup($A7, FantasyPro!$B$2:$E$318, 4, false)) -> 30 | H7: =if(ISNA(vlookup($A7, RotoWire!$B$2:$E$681, 4, false)), 0, vlookup($A7, RotoWire!$B$2:$E$681, 4, false)) -> 17 | I7: =Average(E7:H7) -> 22.5 | J7: =max(E7:H7)-min(E7:H7) -> 13
A8: Alvin Kamara | B8: NO | C8: RB | D8: 6 | E8: =if(ISNA(vlookup($A8, ESPN!$B$2:$E$281, 4, false)), 0, vlookup($A8, ESPN!$B$2:$E$281, 4, false)) -> 25 | F8: =if(ISNA(vlookup($A8, Scout.com!$B$2:$E$239, 4, false)), 0, vlookup($A8, Scout.com!$B$2:$E$239, 4, false)) -> 16 | G8: =if(ISNA(vlookup($A8, FantasyPro!$B$2:$E$318, 4, false)), 0, vlookup($A8, FantasyPro!$B$2:$E$318, 4, false)) -> 22 | H8: =if(ISNA(vlookup($A8, RotoWire!$B$2:$E$681, 4, false)), 0, vlookup($A8, RotoWire!$B$2:$E$681, 4, false)) -> 25 | I8: =Average(E8:H8) -> 22 | J8: =max(E8:H8)-min(E8:H8) -> 9
A9: Kareem Hunt | B9: KC | C9: RB | D9: 12 | E9: =if(ISNA(vlookup($A9, ESPN!$B$2:$E$281, 4, false)), 0, vlookup($A9, ESPN!$B$2:$E$281, 4, false)) -> 23 | F9: =if(ISNA(vlookup($A9, Scout.com!$B$2:$E$239, 4, false)), 0, vlookup($A9, Scout.com!$B$2:$E$239, 4, false)) -> 14 | G9: =if(ISNA(vlookup($A9, FantasyPro!$B$2:$E$318, 4, false)), 0, vlookup($A9, FantasyPro!$B$2:$E$318, 4, false)) -> 21 | H9: =if(ISNA(vlookup($A9, RotoWire!$B$2:$E$681, 4, false)), 0, vlookup($A9, RotoWire!$B$2:$E$681, 4, false)) -> 25 | I9: =Average(E9:H9) -> 20.75 | J9: =max(E9:H9)-min(E9:H9) -> 11
A10: Julio Jones | B10: ATL | C10: WR | D10: 8 | E10: =if(ISNA(vlookup($A10, ESPN!$B$2:$E$281, 4, false)), 0, vlookup($A10, ESPN!$B$2:$E$281, 4, false)) -> 25 | F10: =if(ISNA(vlookup($A10, Scout.com!$B$2:$E$239, 4, false)), 0, vlookup($A10, Scout.com!$B$2:$E$239, 4, false)) -> 14 | G10: =if(ISNA(vlookup($A10, FantasyPro!$B$2:$E$318, 4, false)), 0, vlookup($A10, FantasyPro!$B$2:$E$318, 4, false)) -> 24 | H10: =if(ISNA(vlookup($A10, RotoWire!$B$2:$E$681, 4, false)), 0, vlookup($A10, RotoWire!$B$2:$E$681, 4, false)) -> 16 | I10: =Average(E10:H10) -> 19.75 | J10: =max(E10:H10)-min(E10:H10) -> 11
A11: Leonard Fournette | B11: JAC | C11: RB | D11: 9 | E11: =if(ISNA(vlookup($A11, ESPN!$B$2:$E$281, 4, false)), 0, vlookup($A11, ESPN!$B$2:$E$281, 4, false)) -> 23 | F11: =if(ISNA(vlookup($A11, Scout.com!$B$2:$E$239, 4, false)), 0, vlookup($A11, Scout.com!$B$2:$E$239, 4, false)) -> 14 | G11: =if(ISNA(vlookup($A11, FantasyPro!$B$2:$E$318, 4, false)), 0, vlookup($A11, FantasyPro!$B$2:$E$318, 4, false)) -> 21 | H11: =if(ISNA(vlookup($A11, RotoWire!$B$2:$E$681, 4, false)), 0, vlookup($A11, RotoWire!$B$2:$E$681, 4, false)) -> 21 | I11: =Average(E11:H11) -> 19.75 | J11: =max(E11:H11)-min(E11:H11) -> 9
A12: DeAndre Hopkins | B12: HOU | C12: WR | D12: 10 | E12: =if(ISNA(vlookup($A12, ESPN!$B$2:$E$281, 4, false)), 0, vlookup($A12, ESPN!$B$2:$E$281, 4, false)) -> 24 | F12: =if(ISNA(vlookup($A12, Scout.com!$B$2:$E$239, 4, false)), 0, vlookup($A12, Scout.com!$B$2:$E$239, 4, false)) -> 16 | G12: =if(ISNA(vlookup($A12, FantasyPro!$B$2:$E$318, 4, false)), 0, vlookup($A12, FantasyPro!$B$2:$E$318, 4, false)) -> 24 | H12: =if(ISNA(vlookup($A12, RotoWire!$B$2:$E$681, 4, false)), 0, vlookup($A12, RotoWire!$B$2:$E$681, 4, false)) -> 14 | I12: =Average(E12:H12) -> 19.5 | J12: =max(E12:H12)-min(E12:H12) -> 10
A13: Odell Beckham | B13: NYG | C13: WR | D13: 9 | E13: =if(ISNA(vlookup($A13, ESPN!$B$2:$E$281, 4, false)), 0, vlookup($A13, ESPN!$B$2:$E$281, 4, false)) -> 24 | F13: =if(ISNA(vlookup($A13, Scout.com!$B$2:$E$239, 4, false)), 0, vlookup($A13, Scout.com!$B$2:$E$239, 4, false)) -> 16 | G13: =if(ISNA(vlookup($A13, FantasyPro!$B$2:$E$318, 4, false)), 0, vlookup($A13, FantasyPro!$B$2:$E$318, 4, false)) -> 22 | H13: =if(ISNA(vlookup($A13, RotoWire!$B$2:$E$681, 4, false)), 0, vlookup($A13, RotoWire!$B$2:$E$681, 4, false)) -> 16 | I13: =Average(E13:H13) -> 19.5 | J13: =max(E13:H13)-min(E13:H13) -> 8
... A150: Courtland Sutton | B150: DEN | C150: WR | D150: 10 | E150: =if(ISNA(vlookup($A150, ESPN!$B$2:$E$281, 4, false)), 0, vlookup($A150, ESPN!$B$2:$E$281, 4, false)) -> 0 | F150: =if(ISNA(vlookup($A150, Scout.com!$B$2:$E$239, 4, false)), 0, vlookup($A150, Scout.com!$B$2:$E$239, 4, false)) -> 5 | G150: =if(ISNA(vlookup($A150, FantasyPro!$B$2:$E$318, 4, false)), 0, vlookup($A150, FantasyPro!$B$2:$E$318, 4, false)) -> 0 | H150: =if(ISNA(vlookup($A150, RotoWire!$B$2:$E$681, 4, false)), 0, vlookup($A150, RotoWire!$B$2:$E$681, 4, false)) -> 0 | I150: =Average(E150:H150) -> 1.25 | J150: =max(E150:H150)-min(E150:H150) -> 5
A151: Dez Bryant | B151: FA | C151: WR | E151: =if(ISNA(vlookup($A151, ESPN!$B$2:$E$281, 4, false)), 0, vlookup($A151, ESPN!$B$2:$E$281, 4, false)) -> 1 | F151: =if(ISNA(vlookup($A151, Scout.com!$B$2:$E$239, 4, false)), 0, vlookup($A151, Scout.com!$B$2:$E$239, 4, false)) -> 3 | G151: =if(ISNA(vlookup($A151, FantasyPro!$B$2:$E$318, 4, false)), 0, vlookup($A151, FantasyPro!$B$2:$E$318, 4, false)) -> 0 | H151: =if(ISNA(vlookup($A151, RotoWire!$B$2:$E$681, 4, false)), 0, vlookup($A151, RotoWire!$B$2:$E$681, 4, false)) -> 1 | I151: =Average(E151:H151) -> 1.25 | J151: =max(E151:H151)-min(E151:H151) -> 3
A152: George Kittle | B152: SF | C152: TE | D152: 11 | E152: =if(ISNA(vlookup($A152, ESPN!$B$2:$E$281, 4, false)), 0, vlookup($A152, ESPN!$B$2:$E$281, 4, false)) -> 0 | F152: =if(ISNA(vlookup($A152, Scout.com!$B$2:$E$239, 4, false)), 0, vlookup($A152, Scout.com!$B$2:$E$239, 4, false)) -> 3 | G152: =if(ISNA(vlookup($A152, FantasyPro!$B$2:$E$318, 4, false)), 0, vlookup($A152, FantasyPro!$B$2:$E$318, 4, false)) -> 2 | H152: =if(ISNA(vlookup($A152, RotoWire!$B$2:$E$681, 4, false)), 0, vlookup($A152, RotoWire!$B$2:$E$681, 4, false)) -> 0 | I152: =Average(E152:H152) -> 1.25 | J152: =max(E152:H152)-min(E152:H152) -> 3
A153: Jameis Winston | B153: TB | C153: QB | D153: 5 | E153: =if(ISNA(vlookup($A153, ESPN!$B$2:$E$281, 4, false)), 0, vlookup($A153, ESPN!$B$2:$E$281, 4, false)) -> 0 | F153: =if(ISNA(vlookup($A153, Scout.com!$B$2:$E$239, 4, false)), 0, vlookup($A153, Scout.com!$B$2:$E$239, 4, false)) -> 5 | G153: =if(ISNA(vlookup($A153, FantasyPro!$B$2:$E$318, 4, false)), 0, vlookup($A153, FantasyPro!$B$2:$E$318, 4, false)) -> 0 | H153: =if(ISNA(vlookup($A153, RotoWire!$B$2:$E$681, 4, false)), 0, vlookup($A153, RotoWire!$B$2:$E$681, 4, false)) -> 0 | I153: =Average(E153:H153) -> 1.25 | J153: =max(E153:H153)-min(E153:H153) -> 5
A154: James Washington | B154: PIT | C154: WR | D154: 7 | E154: =if(ISNA(vlookup($A154, ESPN!$B$2:$E$281, 4, false)), 0, vlookup($A154, ESPN!$B$2:$E$281, 4, false)) -> 0 | F154: =if(ISNA(vlookup($A154, Scout.com!$B$2:$E$239, 4, false)), 0, vlookup($A154, Scout.com!$B$2:$E$239, 4, false)) -> 4 | G154: =if(ISNA(vlookup($A154, FantasyPro!$B$2:$E$318, 4, false)), 0, vlookup($A154, FantasyPro!$B$2:$E$318, 4, false)) -> 0 | H154: =if(ISNA(vlookup($A154, RotoWire!$B$2:$E$681, 4, false)), 0, vlookup($A154, RotoWire!$B$2:$E$681, 4, false)) -> 1 | I154: =Average(E154:H154) -> 1.25 | J154: =max(E154:H154)-min(E154:H154) -> 4
A155: John Ross | B155: CIN | C155: WR | D155: 9 | E155: =if(ISNA(vlookup($A155, ESPN!$B$2:$E$281, 4, false)), 0, vlookup($A155, ESPN!$B$2:$E$281, 4, false)) -> 1 | F155: =if(ISNA(vlookup($A155, Scout.com!$B$2:$E$239, 4, false)), 0, vlookup($A155, Scout.com!$B$2:$E$239, 4, false)) -> 0 | G155: =if(ISNA(vlookup($A155, FantasyPro!$B$2:$E$318, 4, false)), 0, vlookup($A155, FantasyPro!$B$2:$E$318, 4, false)) -> 0 | H155: =if(ISNA(vlookup($A155, RotoWire!$B$2:$E$681, 4, false)), 0, vlookup($A155, RotoWire!$B$2:$E$681, 4, false)) -> 4 | I155: =Average(E155:H155) -> 1.25 | J155: =max(E155:H155)-min(E155:H155) -> 4
A156: Jordan Wilkins | B156: IND | C156: RB | D156: 9 | E156: =if(ISNA(vlookup($A156, ESPN!$B$2:$E$281, 4, false)), 0, vlookup($A156, ESPN!$B$2:$E$281, 4, false)) -> 1 | F156: =if(ISNA(vlookup($A156, Scout.com!$B$2:$E$239, 4, false)), 0, vlookup($A156, Scout.com!$B$2:$E$239, 4, false)) -> 0 | G156: =if(ISNA(vlookup($A156, FantasyPro!$B$2:$E$318, 4, false)), 0, vlookup($A156, FantasyPro!$B$2:$E$318, 4, false)) -> 0 | H156: =if(ISNA(vlookup($A156, RotoWire!$B$2:$E$681, 4, false)), 0, vlookup($A156, RotoWire!$B$2:$E$681, 4, false)) -> 4 | I156: =Average(E156:H156) -> 1.25 | J156: =max(E156:H156)-min(E156:H156) -> 4
A157: Mitchell Trubisky | B157: CHI | C157: QB | D157: 5 | E157: =if(ISNA(vlookup($A157, ESPN!$B$2:$E$281, 4, false)), 0, vlookup($A157, ESPN!$B$2:$E$281, 4, false)) -> 0 | F157: =if(ISNA(vlookup($A157, Scout.com!$B$2:$E$239, 4, false)), 0, vlookup($A157, Scout.com!$B$2:$E$239, 4, false)) -> 5 | G157: =if(ISNA(vlookup($A157, FantasyPro!$B$2:$E$318, 4, false)), 0, vlookup($A157, FantasyPro!$B$2:$E$318, 4, false)) -> 0 | H157: =if(ISNA(vlookup($A157, RotoWire!$B$2:$E$681, 4, false)), 0, vlookup($A157, RotoWire!$B$2:$E$681, 4, false)) -> 0 | I157: =Average(E157:H157) -> 1.25 | J157: =max(E157:H157)-min(E157:H157) -> 5
A158: New England Patriots | B158: NE | C158: D/ST | D158: 11 | E158: =if(ISNA(vlookup($A158, ESPN!$B$2:$E$281, 4, false)), 0, vlookup($A158, ESPN!$B$2:$E$281, 4, false)) -> 1 | F158: =if(ISNA(vlookup($A158, Scout.com!$B$2:$E$239, 4, false)), 0, vlookup($A158, Scout.com!$B$2:$E$239, 4, false)) -> 3 | G158: =if(ISNA(vlookup($A158, FantasyPro!$B$2:$E$318, 4, false)), 0, vlookup($A158, FantasyPro!$B$2:$E$318, 4, false)) -> 0 | H158: =if(ISNA(vlookup($A158, RotoWire!$B$2:$E$681, 4, false)), 0, vlookup($A158, RotoWire!$B$2:$E$681, 4, false)) -> 1 | I158: =Average(E158:H158) -> 1.25 | J158: =max(E158:H158)-min(E158:H158) -> 3
A159: Ty Montgomery | B159: GB | C159: RB | D159: 7 | E159: =if(ISNA(vlookup($A159, ESPN!$B$2:$E$281, 4, false)), 0, vlookup($A159, ESPN!$B$2:$E$281, 4, false)) -> 1 | F159: =if(ISNA(vlookup($A159, Scout.com!$B$2:$E$239, 4, false)), 0, vlookup($A159, Scout.com!$B$2:$E$239, 4, false)) -> 0 | G159: =if(ISNA(vlookup($A159, FantasyPro!$B$2:$E$318, 4, false)), 0, vlookup($A159, FantasyPro!$B$2:$E$318, 4, false)) -> 2 | H159: =if(ISNA(vlookup($A159, RotoWire!$B$2:$E$681, 4, false)), 0, vlookup($A159, RotoWire!$B$2:$E$681, 4, false)) -> 2 | I159: =Average(E159:H159) -> 1.25 | J159: =max(E159:H159)-min(E159:H159) -> 2
A160: Austin Ekeler | B160: LAC | C160: RB | D160: 8 | E160: =if(ISNA(vlookup($A160, ESPN!$B$2:$E$281, 4, false)), 0, vlookup($A160, ESPN!$B$2:$E$281, 4, false)) -> 0 | F160: =if(ISNA(vlookup($A160, Scout.com!$B$2:$E$239, 4, false)), 0, vlookup($A160, Scout.com!$B$2:$E$239, 4, false)) -> 0 | G160: =if(ISNA(vlookup($A160, FantasyPro!$B$2:$E$318, 4, false)), 0, vlookup($A160, FantasyPro!$B$2:$E$318, 4, false)) -> 2 | H160: =if(ISNA(vlookup($A160, RotoWire!$B$2:$E$681, 4, false)), 0, vlookup($A160, RotoWire!$B$2:$E$681, 4, false)) -> 2 | I160: =Average(E160:H160) -> 1 | J160: =max(E160:H160)-min(E160:H160) -> 2
A161: Carolina Panthers | B161: CAR | C161: D/ST | D161: 4 | E161: =if(ISNA(vlookup($A161, ESPN!$B$2:$E$281, 4, false)), 0, vlookup($A161, ESPN!$B$2:$E$281, 4, false)) -> 1 | F161: =if(ISNA(vlookup($A161, Scout.com!$B$2:$E$239, 4, false)), 0, vlookup($A161, Scout.com!$B$2:$E$239, 4, false)) -> 2 | G161: =if(ISNA(vlookup($A161, FantasyPro!$B$2:$E$318, 4, false)), 0, vlookup($A161, FantasyPro!$B$2:$E$318, 4, false)) -> 1 | H161: =if(ISNA(vlookup($A161, RotoWire!$B$2:$E$681, 4, false)), 0, vlookup($A161, RotoWire!$B$2:$E$681, 4, false)) -> 0 | I161: =Average(E161:H161) -> 1 | J161: =max(E161:H161)-min(E161:H161) -> 2
A162: Corey Clement | B162: PHI | C162: RB | D162: 9 | E162: =if(ISNA(vlookup($A162, ESPN!$B$2:$E$281, 4, false)), 0, vlookup($A162, ESPN!$B$2:$E$281, 4, false)) -> 0 | F162: =if(ISNA(vlookup($A162, Scout.com!$B$2:$E$239, 4, false)), 0, vlookup($A162, Scout.com!$B$2:$E$239, 4, false)) -> 0 | G162: =if(ISNA(vlookup($A162, FantasyPro!$B$2:$E$318, 4, false)), 0, vlookup($A162, FantasyPro!$B$2:$E$318, 4, false)) -> 2 | H162: =if(ISNA(vlookup($A162, RotoWire!$B$2:$E$681, 4, false)), 0, vlookup($A162, RotoWire!$B$2:$E$681, 4, false)) -> 2 | I162: =Average(E162:H162) -> 1 | J162: =max(E162:H162)-min(E162:H162) -> 2
A163: D'Onta Foreman | B163: HOU | C163: RB | D163: 10 | E163: =if(ISNA(vlookup($A163, ESPN!$B$2:$E$281, 4, false)), 0, vlookup($A163, ESPN!$B$2:$E$281, 4, false)) -> 0 | F163: =if(ISNA(vlookup($A163, Scout.com!$B$2:$E$239, 4, false)), 0, vlookup($A163, Scout.com!$B$2:$E$239, 4, false)) -> 0 | G163: =if(ISNA(vlookup($A163, FantasyPro!$B$2:$E$318, 4, false)), 0, vlookup($A163, FantasyPro!$B$2:$E$318, 4, false)) -> 1 | H163: =if(ISNA(vlookup($A163, RotoWire!$B$2:$E$681, 4, false)), 0, vlookup($A163, RotoWire!$B$2:$E$681, 4, false)) -> 3 | I163: =Average(E163:H163) -> 1 | J163: =max(E163:H163)-min(E163:H163) -> 3
... A236: AJ McCarron | B236: BUF | C236: QB | D236: 11 | E236: =if(ISNA(vlookup($A236, ESPN!$B$2:$E$281, 4, false)), 0, vlookup($A236, ESPN!$B$2:$E$281, 4, false)) -> 0 | F236: =if(ISNA(vlookup($A236, Scout.com!$B$2:$E$239, 4, false)), 0, vlookup($A236, Scout.com!$B$2:$E$239, 4, false)) -> 0 | G236: =if(ISNA(vlookup($A236, FantasyPro!$B$2:$E$318, 4, false)), 0, vlookup($A236, FantasyPro!$B$2:$E$318, 4, false)) -> 0 | H236: =if(ISNA(vlookup($A236, RotoWire!$B$2:$E$681, 4, false)), 0, vlookup($A236, RotoWire!$B$2:$E$681, 4, false)) -> 0 | I236: =Average(E236:H236) -> 0 | J236: =max(E236:H236)-min(E236:H236) -> 0
A237: Akeem Hunt | B237: FA | C237: RB | E237: =if(ISNA(vlookup($A237, ESPN!$B$2:$E$281, 4, false)), 0, vlookup($A237, ESPN!$B$2:$E$281, 4, false)) -> 0 | F237: =if(ISNA(vlookup($A237, Scout.com!$B$2:$E$239, 4, false)), 0, vlookup($A237, Scout.com!$B$2:$E$239, 4, false)) -> 0 | G237: =if(ISNA(vlookup($A237, FantasyPro!$B$2:$E$318, 4, false)), 0, vlookup($A237, FantasyPro!$B$2:$E$318, 4, false)) -> 0 | H237: =if(ISNA(vlookup($A237, RotoWire!$B$2:$E$681, 4, false)), 0, vlookup($A237, RotoWire!$B$2:$E$681, 4, false)) -> 0 | I237: =Average(E237:H237) -> 0 | J237: =max(E237:H237)-min(E237:H237) -> 0
A238: Akrum Wadley | B238: TEN | C238: RB | D238: 8 | E238: =if(ISNA(vlookup($A238, ESPN!$B$2:$E$281, 4, false)), 0, vlookup($A238, ESPN!$B$2:$E$281, 4, false)) -> 0 | F238: =if(ISNA(vlookup($A238, Scout.com!$B$2:$E$239, 4, false)), 0, vlookup($A238, Scout.com!$B$2:$E$239, 4, false)) -> 0 | G238: =if(ISNA(vlookup($A238, FantasyPro!$B$2:$E$318, 4, false)), 0, vlookup($A238, FantasyPro!$B$2:$E$318, 4, false)) -> 0 | H238: =if(ISNA(vlookup($A238, RotoWire!$B$2:$E$681, 4, false)), 0, vlookup($A238, RotoWire!$B$2:$E$681, 4, false)) -> 0 | I238: =Average(E238:H238) -> 0 | J238: =max(E238:H238)-min(E238:H238) -> 0
A239: Aldrick Robinson | B239: SF | C239: WR | D239: 11 | E239: =if(ISNA(vlookup($A239, ESPN!$B$2:$E$281, 4, false)), 0, vlookup($A239, ESPN!$B$2:$E$281, 4, false)) -> 0 | F239: =if(ISNA(vlookup($A239, Scout.com!$B$2:$E$239, 4, false)), 0, vlookup($A239, Scout.com!$B$2:$E$239, 4, false)) -> 0 | G239: =if(ISNA(vlookup($A239, FantasyPro!$B$2:$E$318, 4, false)), 0, vlookup($A239, FantasyPro!$B$2:$E$318, 4, false)) -> 0 | H239: =if(ISNA(vlookup($A239, RotoWire!$B$2:$E$681, 4, false)), 0, vlookup($A239, RotoWire!$B$2:$E$681, 4, false)) -> 0 | I239: =Average(E239:H239) -> 0 | J239: =max(E239:H239)-min(E239:H239) -> 0
A240: Aldrick Rosas | B240: NYG | C240: K | D240: 9 | E240: =if(ISNA(vlookup($A240, ESPN!$B$2:$E$281, 4, false)), 0, vlookup($A240, ESPN!$B$2:$E$281, 4, false)) -> 0 | F240: =if(ISNA(vlookup($A240, Scout.com!$B$2:$E$239, 4, false)), 0, vlookup($A240, Scout.com!$B$2:$E$239, 4, false)) -> 0 | G240: =if(ISNA(vlookup($A240, FantasyPro!$B$2:$E$318, 4, false)), 0, vlookup($A240, FantasyPro!$B$2:$E$318, 4, false)) -> 0 | H240: =if(ISNA(vlookup($A240, RotoWire!$B$2:$E$681, 4, false)), 0, vlookup($A240, RotoWire!$B$2:$E$681, 4, false)) -> 0 | I240: =Average(E240:H240) -> 0 | J240: =max(E240:H240)-min(E240:H240) -> 0
A241: Alex Erickson | B241: CIN | C241: WR | D241: 9 | E241: =if(ISNA(vlookup($A241, ESPN!$B$2:$E$281, 4, false)), 0, vlookup($A241, ESPN!$B$2:$E$281, 4, false)) -> 0 | F241: =if(ISNA(vlookup($A241, Scout.com!$B$2:$E$239, 4, false)), 0, vlookup($A241, Scout.com!$B$2:$E$239, 4, false)) -> 0 | G241: =if(ISNA(vlookup($A241, FantasyPro!$B$2:$E$318, 4, false)), 0, vlookup($A241, FantasyPro!$B$2:$E$318, 4, false)) -> 0 | H241: =if(ISNA(vlookup($A241, RotoWire!$B$2:$E$681, 4, false)), 0, vlookup($A241, RotoWire!$B$2:$E$681, 4, false)) -> 0 | I241: =Average(E241:H241) -> 0 | J241: =max(E241:H241)-min(E241:H241) -> 0
A242: Alex McGough | B242: SEA | C242: QB | D242: 7 | E242: =if(ISNA(vlookup($A242, ESPN!$B$2:$E$281, 4, false)), 0, vlookup($A242, ESPN!$B$2:$E$281, 4, false)) -> 0 | F242: =if(ISNA(vlookup($A242, Scout.com!$B$2:$E$239, 4, false)), 0, vlookup($A242, Scout.com!$B$2:$E$239, 4, false)) -> 0 | G242: =if(ISNA(vlookup($A242, FantasyPro!$B$2:$E$318, 4, false)), 0, vlookup($A242, FantasyPro!$B$2:$E$318, 4, false)) -> 0 | H242: =if(ISNA(vlookup($A242, RotoWire!$B$2:$E$681, 4, false)), 0, vlookup($A242, RotoWire!$B$2:$E$681, 4, false)) -> 0 | I242: =Average(E242:H242) -> 0 | J242: =max(E242:H242)-min(E242:H242) -> 0
A243: Alfred Blue | B243: HOU | C243: RB | D243: 10 | E243: =if(ISNA(vlookup($A243, ESPN!$B$2:$E$281, 4, false)), 0, vlookup($A243, ESPN!$B$2:$E$281, 4, false)) -> 0 | F243: =if(ISNA(vlookup($A243, Scout.com!$B$2:$E$239, 4, false)), 0, vlookup($A243, Scout.com!$B$2:$E$239, 4, false)) -> 0 | G243: =if(ISNA(vlookup($A243, FantasyPro!$B$2:$E$318, 4, false)), 0, vlookup($A243, FantasyPro!$B$2:$E$318, 4, false)) -> 0 | H243: =if(ISNA(vlookup($A243, RotoWire!$B$2:$E$681, 4, false)), 0, vlookup($A243, RotoWire!$B$2:$E$681, 4, false)) -> 0 | I243: =Average(E243:H243) -> 0 | J243: =max(E243:H243)-min(E243:H243) -> 0
A244: Alfred Morris | B244: SF | C244: RB | D244: 11 | E244: =if(ISNA(vlookup($A244, ESPN!$B$2:$E$281, 4, false)), 0, vlookup($A244, ESPN!$B$2:$E$281, 4, false)) -> 0 | F244: =if(ISNA(vlookup($A244, Scout.com!$B$2:$E$239, 4, false)), 0, vlookup($A244, Scout.com!$B$2:$E$239, 4, false)) -> 0 | G244: =if(ISNA(vlookup($A244, FantasyPro!$B$2:$E$318, 4, false)), 0, vlookup($A244, FantasyPro!$B$2:$E$318, 4, false)) -> 0 | H244: =if(ISNA(vlookup($A244, RotoWire!$B$2:$E$681, 4, false)), 0, vlookup($A244, RotoWire!$B$2:$E$681, 4, false)) -> 0 | I244: =Average(E244:H244) -> 0 | J244: =max(E244:H244)-min(E244:H244) -> 0
A245: Allen Lazard | B245: JAC | C245: WR | D245: 9 | E245: =if(ISNA(vlookup($A245, ESPN!$B$2:$E$281, 4, false)), 0, vlookup($A245, ESPN!$B$2:$E$281, 4, false)) -> 0 | F245: =if(ISNA(vlookup($A245, Scout.com!$B$2:$E$239, 4, false)), 0, vlookup($A245, Scout.com!$B$2:$E$239, 4, false)) -> 0 | G245: =if(ISNA(vlookup($A245, FantasyPro!$B$2:$E$318, 4, false)), 0, vlookup($A245, FantasyPro!$B$2:$E$318, 4, false)) -> 0 | H245: =if(ISNA(vlookup($A245, RotoWire!$B$2:$E$681, 4, false)), 0, vlookup($A245, RotoWire!$B$2:$E$681, 4, false)) -> 0 | I245: =Average(E245:H245) -> 0 | J245: =max(E245:H245)-min(E245:H245) -> 0
A246: Amara Darboh | B246: SEA | C246: WR | D246: 7 | E246: =if(ISNA(vlookup($A246, ESPN!$B$2:$E$281, 4, false)), 0, vlookup($A246, ESPN!$B$2:$E$281, 4, false)) -> 0 | F246: =if(ISNA(vlookup($A246, Scout.com!$B$2:$E$239, 4, false)), 0, vlookup($A246, Scout.com!$B$2:$E$239, 4, false)) -> 0 | G246: =if(ISNA(vlookup($A246, FantasyPro!$B$2:$E$318, 4, false)), 0, vlookup($A246, FantasyPro!$B$2:$E$318, 4, false)) -> 0 | H246: =if(ISNA(vlookup($A246, RotoWire!$B$2:$E$681, 4, false)), 0, vlookup($A246, RotoWire!$B$2:$E$681, 4, false)) -> 0 | I246: =Average(E246:H246) -> 0 | J246: =max(E246:H246)-min(E246:H246) -> 0
A247: Ameer Abdullah | B247: DET | C247: RB | D247: 6 | E247: =if(ISNA(vlookup($A247, ESPN!$B$2:$E$281, 4, false)), 0, vlookup($A247, ESPN!$B$2:$E$281, 4, false)) -> 0 | F247: =if(ISNA(vlookup($A247, Scout.com!$B$2:$E$239, 4, false)), 0, vlookup($A247, Scout.com!$B$2:$E$239, 4, false)) -> 0 | G247: =if(ISNA(vlookup($A247, FantasyPro!$B$2:$E$318, 4, false)), 0, vlookup($A247, FantasyPro!$B$2:$E$318, 4, false)) -> 0 | H247: =if(ISNA(vlookup($A247, RotoWire!$B$2:$E$681, 4, false)), 0, vlookup($A247, RotoWire!$B$2:$E$681, 4, false)) -> 0 | I247: =Average(E247:H247) -> 0 | J247: =max(E247:H247)-min(E247:H247) -> 0
A248: Andre Ellington | B248: FA | C248: RB | E248: =if(ISNA(vlookup($A248, ESPN!$B$2:$E$281, 4, false)), 0, vlookup($A248, ESPN!$B$2:$E$281, 4, false)) -> 0 | F248: =if(ISNA(vlookup($A248, Scout.com!$B$2:$E$239, 4, false)), 0, vlookup($A248, Scout.com!$B$2:$E$239, 4, false)) -> 0 | G248: =if(ISNA(vlookup($A248, FantasyPro!$B$2:$E$318, 4, false)), 0, vlookup($A248, FantasyPro!$B$2:$E$318, 4, false)) -> 0 | H248: =if(ISNA(vlookup($A248, RotoWire!$B$2:$E$681, 4, false)), 0, vlookup($A248, RotoWire!$B$2:$E$681, 4, false)) -> 0 | I248: =Average(E248:H248) -> 0 | J248: =max(E248:H248)-min(E248:H248) -> 0
...

Sheet Players We Want
A1: Name | B1: Team | C1: Position | D1: Bye Week | E1: Keeper Price | F1: Start Bid | G1: Avg Price | H1: Max Bid | L1: =100-L19 -> 100
J2: Position | K2: Name | L2: Amount
J3: QB1
J4: RB1
J5: WR1
J6: WR2
J7: TE
J8: RB2
J9: D/ST
J10: K
J11: WR3
J12: WR4
J13: QB2
J14: RB3
... J18: D/ST2
L19: =sum(L3:L18) -> 0

Sheet Team Bye List
A1: Team | B1: Bye Week
A2: ARI | B2: 9
A3: ATL | B3: 8
A4: BAL | B4: 10
A5: BUF | B5: 11
A6: CAR | B6: 4
A7: CHI | B7: 5
A8: CIN | B8: 9
A9: CLE | B9: 11
A10: DAL | B10: 8
A11: DEN | B11: 10
A12: DET | B12: 6
A13: GB | B13: 7
... A33: WAS | B33: 4

Sheet Names_List
A1: Scout | B1: ESPN | C1: Rotowire
A2: A.J. Green | B2: A.J. Green | C2: A.J. Derby | D2: =countif($B$2:$C$581,A2) -> 2
A3: Aaron Donald | B3: Aaron Jones | C3: A.J. Green | D3: =countif($B$2:$C$581,A3) -> 0
A4: Aaron Jones | B4: Aaron Rodgers | C4: Aaron Jones | D4: =countif($B$2:$C$581,A4) -> 2
A5: Aaron Rodgers | B5: Adam Thielen | C5: Aaron Rodgers | D5: =countif($B$2:$C$581,A5) -> 2
A6: Adam Thielen | B6: Adam Vinatieri | C6: Adam Humphries | D6: =countif($B$2:$C$581,A6) -> 2
A7: Adoree Jackson | B7: AJ McCarron | C7: Adam Shaheen | D7: =countif($B$2:$C$581,A7) -> 0
A8: Alec Ogletree | B8: Albert Wilson | C8: Adam Thielen | D8: =countif($B$2:$C$581,A8) -> 0
A9: Alex Collins | B9: Alex Collins | C9: Adam Vinatieri | D9: =countif($B$2:$C$581,A9) -> 2
A10: Alex Smith | B10: Alex Smith | C10: Adrian Peterson | D10: =countif($B$2:$C$581,A10) -> 2
A11: Allen Hurns | B11: Alfred Blue | C11: AJ McCarron | D11: =countif($B$2:$C$581,A11) -> 2
A12: Allen Robinson | B12: Allen Hurns | C12: Akeem Hunt | D12: =countif($B$2:$C$581,A12) -> 2
A13: Alshon Jeffery | B13: Allen Robinson | C13: Akrum Wadley | D13: =countif($B$2:$C$581,A13) -> 2
... A201: Zach Ertz | B201: Nyheim Hines | C201: Durham Smythe | D201: =countif($B$2:$C$581,A201) -> 2
B202: O.J. Howard | C202: Dustin Hopkins | D202: =countif($B$2:$C$581,A202) -> 0
B203: Odell Beckham Jr. | C203: Dwayne Allen | D203: =countif($B$2:$C$581,A203) -> 0
B204: Panthers | C204: Dwayne Washington | D204: =countif($B$2:$C$581,A204) -> 0
B205: Patrick Mahomes | C205: Dylan Cantrell | D205: =countif($B$2:$C$581,A205) -> 0
B206: Patriots | C206: Ed Dickson | D206: =countif($B$2:$C$581,A206) -> 0
B207: Paul Richardson | C207: Eddie Lacy | D207: =countif($B$2:$C$581,A207) -> 0
B208: Peyton Barber | C208: EJ Manuel | D208: =countif($B$2:$C$581,A208) -> 0
B209: Philip Rivers | C209: Eli Manning | D209: =countif($B$2:$C$581,A209) -> 0
B210: Pierre Garcon | C210: Eli Rogers | D210: =countif($B$2:$C$581,A210) -> 0
B211: Quincy Enunwa | C211: Elijah McGuire | D211: =countif($B$2:$C$581,A211) -> 0
B212: Rams | C212: Emmanuel Sanders | D212: =countif($B$2:$C$581,A212) -> 0
B213: Randall Cobb | C213: Equanimeous St. Brown | D213: =countif($B$2:$C$581,A213) -> 0
... B281: Zay Jones | C281: Jeremy McNichols | D281: =countif($B$2:$C$581,A281) -> 0
C282: Jeremy Sprinkle | D282: =countif($B$2:$C$581,A282) -> 0
C283: Jerick McKinnon | D283: =countif($B$2:$C$581,A283) -> 0
C284: Jermaine Gresham | D284: =countif($B$2:$C$581,A284) -> 0
C285: Jermaine Kearse | D285: =countif($B$2:$C$581,A285) -> 0
C286: Jesse James | D286: =countif($B$2:$C$581,A286) -> 0
C287: Jimmy Garoppolo | D287: =countif($B$2:$C$581,A287) -> 0
C288: Jimmy Graham | D288: =countif($B$2:$C$581,A288) -> 0
C289: Joe Flacco | D289: =countif($B$2:$C$581,A289) -> 0
C290: Joe Mixon | D290: =countif($B$2:$C$581,A290) -> 0
C291: Joe Webb | D291: =countif($B$2:$C$581,A291) -> 0
C292: Joe Williams | D292: =countif($B$2:$C$581,A292) -> 0
C293: John Brown | D293: =countif($B$2:$C$581,A293) -> 0
... C581: Zay Jones | D581: =countif($B$2:$C$581,A581) -> 0
