Workbook

Sheet ESPN
A1: Rank | B1: Name | C1: Team | D1: Position | E1: Value
A2: 1 | B2: Saquon Barkley | C2: NYG | D2: RB | E2: 77
A3: 2 | B3: Ezekiel Elliott | C3: DAL | D3: RB | E3: 73
A4: 3 | B4: Travis Kelce | C4: KC | D4: TE | E4: 68
A5: 4 | B5: Tyreek Hill | C5: KC | D5: WR | E5: 67
A6: 5 | B6: Alvin Kamara | C6: NO | D6: RB | E6: 59
A7: 6 | B7: DeAndre Hopkins | C7: HOU | D7: WR | E7: 60
A8: 7 | B8: Julio Jones | C8: ATL | D8: WR | E8: 58
A9: 8 | B9: Christian McCaffrey | C9: CAR | D9: RB | E9: 55
A10: 9 | B10: Todd Gurley | C10: LAR | D10: RB | E10: 54
A11: 10 | B11: David Johnson | C11: ARI | D11: RB | E11: 52
A12: 11 | B12: Davante Adams | C12: GB | D12: WR | E12: 52
A13: 12 | B13: Odell Beckham | C13: CLE | D13: WR | E13: 51
... A774: 1034 | B774: Geno Smith | C774: SEA | D774: QB | E774: 0

Sheet FFToolbox
A1: Rank | B1: Name | C1: Team | D1: Position | E1: Value
A2: 1 | B2: Saquon Barkley | C2: NYG | D2: RB | E2: 53
A3: 2 | B3: Christian McCaffrey | C3: CAR | D3: RB | E3: 50
A4: 3 | B4: Alvin Kamara | C4: NO | D4: RB | E4: 49
A5: 4 | B5: Ezekiel Elliott | C5: DAL | D5: RB | E5: 45
A6: 5 | B6: DeAndre Hopkins | C6: HOU | D6: WR | E6: 44
A7: 6 | B7: Julio Jones | C7: ATL | D7: WR | E7: 44
A8: 7 | B8: Davante Adams | C8: GB | D8: WR | E8: 43
A9: 8 | B9: Michael Thomas | C9: NO | D9: WR | E9: 41
A10: 9 | B10: JuJu Smith-Schuster | C10: PIT | D10: WR | E10: 40
A11: 10 | B11: David Johnson | C11: ARI | D11: RB | E11: 40
A12: 11 | B12: Le'Veon Bell | C12: NYJ | D12: RB | E12: 39
A13: 12 | B13: James Conner | C13: PIT | D13: RB | E13: 38
... A201: 200 | B201: Gardner Minshew | C201: JAX | D201: QB | E201: 0

Sheet Scout.com
A1: Rank | B1: Name | C1: Team | D1: Position | E1: Value
A2: 1
A3: 2
A4: 3
A5: 4
A6: 5
A7: 6
A8: 7
A9: 8
A10: 9
A11: 10
A12: 11
A13: 12
... A159: 196

Sheet FantasyPro
A1: Rank | B1: Name | C1: Team | D1: Position | E1: Value
A2: 1 | B2: Patrick Mahomes | C2: KC | D2: QB | E2: 33
A3: 2 | B3: Deshaun Watson | C3: HOU | D3: QB | E3: 23
A4: 3 | B4: Aaron Rodgers | C4: GB | D4: QB | E4: 20
A5: 4 | B5: Matt Ryan | C5: ATL | D5: QB | E5: 16
A6: 5 | B6: Cam Newton | C6: CAR | D6: QB | E6: 14
A7: 6 | B7: Carson Wentz | C7: PHI | D7: QB | E7: 11
A8: 7 | B8: Drew Brees | C8: NO | D8: QB | E8: 10
A9: 8 | B9: Ben Roethlisberger | C9: PIT | D9: QB | E9: 9
A10: 9 | B10: Baker Mayfield | C10: CLE | D10: QB | E10: 9
A11: 10 | B11: Jameis Winston | C11: TB | D11: QB | E11: 9
A12: 11 | B12: Dak Prescott | C12: DAL | D12: QB | E12: 9
A13: 12 | B13: Jared Goff | C13: LAR | D13: QB | E13: 8
... A305: 304 | B305: OakLARnd Raiders | C305: OAK | D305: D/ST | E305: 0

Sheet RotoWire
A1: Rank | B1: Name | C1: Team | D1: Position | E1: Value
A2: 1 | B2: Patrick Mahomes | C2: KC | D2: QB | E2: 114
A3: 2 | B3: Baker Mayfield | C3: CLE | D3: QB | E3: 97
A4: 3 | B4: Matt Ryan | C4: ATL | D4: QB | E4: 90
A5: 4 | B5: Ben Roethlisberger | C5: PIT | D5: QB | E5: 80
A6: 5 | B6: Jared Goff | C6: LAR | D6: QB | E6: 71
A7: 6 | B7: Saquon Barkley | C7: NYG | D7: RB | E7: 66
A8: 7 | B8: Julio Jones | C8: ATL | D8: WR | E8: 59
A9: 8 | B9: DeShaun Watson | C9: HOU | D9: QB | E9: 56
A10: 9 | B10: Carson Wentz | C10: PHI | D10: QB | E10: 54
A11: 10 | B11: DeAndre Hopkins | C11: HOU | D11: WR | E11: 52
A12: 11 | B12: Travis Kelce | C12: KC | D12: TE | E12: 52
A13: 12 | B13: Aaron Rodgers | C13: GB | D13: QB | E13: 51
... A619: 618 | B619: Miami Dolphins | C619: MIA | D619: D/ST | E619: 0

Sheet Masterview
A1: Name | B1: Keeper | C1: Team | D1: Position | E1: Bye Week | F1: ESPN | G1: FFToolbox | H1: FantasyPro | I1: RotoWire | J1: Avg Going Rate | K1: Variation
A2: Saquon Barkley | B2: No | C2: NYG | D2: RB | E2: =vlookup(C2,'Team Bye List'!$A$1:$B$33,2,False) -> 11 | F2: =if(ISNA(vlookup($A2, ESPN!$B$2:$E$257, 4, false)), 0, vlookup($A2, ESPN!$B$2:$E$257, 4, false)) -> 77 | G2: =if(ISNA(vlookup($A2, FFToolbox!$B$2:$E$239, 4, false)), 0, vlookup($A2, FFToolbox!$B$2:$E$239, 4, false)) -> 53 | H2: =if(ISNA(vlookup($A2, FantasyPro!$B$2:$E$305, 4, false)), 0, vlookup($A2, FantasyPro!$B$2:$E$305, 4, false)) -> 64 | I2: =if(ISNA(vlookup($A2, RotoWire!$B$2:$E$681, 4, false)), 0, vlookup($A2, RotoWire!$B$2:$E$681, 4, false)) -> 66 | J2: =Average(F2:I2) -> 65 | K2: =max(F2:I2)-min(F2:I2) -> 24
A3: Ezekiel Elliott | B3: Yes | C3: DAL | D3: RB | E3: =vlookup(C3,'Team Bye List'!$A$1:$B$33,2,False) -> 8 | F3: =if(ISNA(vlookup($A3, ESPN!$B$2:$E$257, 4, false)), 0, vlookup($A3, ESPN!$B$2:$E$257, 4, false)) -> 73 | G3: =if(ISNA(vlookup($A3, FFToolbox!$B$2:$E$239, 4, false)), 0, vlookup($A3, FFToolbox!$B$2:$E$239, 4, false)) -> 45 | H3: =if(ISNA(vlookup($A3, FantasyPro!$B$2:$E$316, 4, false)), 0, vlookup($A3, FantasyPro!$B$2:$E$316, 4, false)) -> 53 | I3: =if(ISNA(vlookup($A3, RotoWire!$B$2:$E$681, 4, false)), 0, vlookup($A3, RotoWire!$B$2:$E$681, 4, false)) -> 40 | J3: =Average(F3:I3) -> 52.75 | K3: =max(F3:I3)-min(F3:I3) -> 33
A4: Patrick Mahomes | B4: Yes | C4: KC | D4: QB | E4: =vlookup(C4,'Team Bye List'!$A$1:$B$33,2,False) -> 12 | F4: =if(ISNA(vlookup($A4, ESPN!$B$2:$E$257, 4, false)), 0, vlookup($A4, ESPN!$B$2:$E$257, 4, false)) -> 45 | G4: =if(ISNA(vlookup($A4, FFToolbox!$B$2:$E$239, 4, false)), 0, vlookup($A4, FFToolbox!$B$2:$E$239, 4, false)) -> 19 | H4: =if(ISNA(vlookup($A4, FantasyPro!$B$2:$E$316, 4, false)), 0, vlookup($A4, FantasyPro!$B$2:$E$316, 4, false)) -> 33 | I4: =if(ISNA(vlookup($A4, RotoWire!$B$2:$E$681, 4, false)), 0, vlookup($A4, RotoWire!$B$2:$E$681, 4, false)) -> 114 | J4: =Average(F4:I4) -> 52.75 | K4: =max(F4:I4)-min(F4:I4) -> 95
A5: Julio Jones | B5: No | C5: ATL | D5: WR | E5: =vlookup(C5,'Team Bye List'!$A$1:$B$33,2,False) -> 9 | F5: =if(ISNA(vlookup($A5, ESPN!$B$2:$E$257, 4, false)), 0, vlookup($A5, ESPN!$B$2:$E$257, 4, false)) -> 58 | G5: =if(ISNA(vlookup($A5, FFToolbox!$B$2:$E$239, 4, false)), 0, vlookup($A5, FFToolbox!$B$2:$E$239, 4, false)) -> 44 | H5: =if(ISNA(vlookup($A5, FantasyPro!$B$2:$E$316, 4, false)), 0, vlookup($A5, FantasyPro!$B$2:$E$316, 4, false)) -> 46 | I5: =if(ISNA(vlookup($A5, RotoWire!$B$2:$E$681, 4, false)), 0, vlookup($A5, RotoWire!$B$2:$E$681, 4, false)) -> 59 | J5: =Average(F5:I5) -> 51.75 | K5: =max(F5:I5)-min(F5:I5) -> 15
A6: Alvin Kamara | B6: Yes | C6: NO | D6: RB | E6: =vlookup(C6,'Team Bye List'!$A$1:$B$33,2,False) -> 9 | F6: =if(ISNA(vlookup($A6, ESPN!$B$2:$E$257, 4, false)), 0, vlookup($A6, ESPN!$B$2:$E$257, 4, false)) -> 59 | G6: =if(ISNA(vlookup($A6, FFToolbox!$B$2:$E$239, 4, false)), 0, vlookup($A6, FFToolbox!$B$2:$E$239, 4, false)) -> 49 | H6: =if(ISNA(vlookup($A6, FantasyPro!$B$2:$E$316, 4, false)), 0, vlookup($A6, FantasyPro!$B$2:$E$316, 4, false)) -> 57 | I6: =if(ISNA(vlookup($A6, RotoWire!$B$2:$E$681, 4, false)), 0, vlookup($A6, RotoWire!$B$2:$E$681, 4, false)) -> 38 | J6: =Average(F6:I6) -> 50.75 | K6: =max(F6:I6)-min(F6:I6) -> 21
A7: DeAndre Hopkins | B7: Yes | C7: HOU | D7: WR | E7: =vlookup(C7,'Team Bye List'!$A$1:$B$33,2,False) -> 10 | F7: =if(ISNA(vlookup($A7, ESPN!$B$2:$E$257, 4, false)), 0, vlookup($A7, ESPN!$B$2:$E$257, 4, false)) -> 60 | G7: =if(ISNA(vlookup($A7, FFToolbox!$B$2:$E$239, 4, false)), 0, vlookup($A7, FFToolbox!$B$2:$E$239, 4, false)) -> 44 | H7: =if(ISNA(vlookup($A7, FantasyPro!$B$2:$E$316, 4, false)), 0, vlookup($A7, FantasyPro!$B$2:$E$316, 4, false)) -> 47 | I7: =if(ISNA(vlookup($A7, RotoWire!$B$2:$E$681, 4, false)), 0, vlookup($A7, RotoWire!$B$2:$E$681, 4, false)) -> 52 | J7: =Average(F7:I7) -> 50.75 | K7: =max(F7:I7)-min(F7:I7) -> 16
A8: Travis Kelce | B8: Yes | C8: KC | D8: TE | E8: =vlookup(C8,'Team Bye List'!$A$1:$B$33,2,False) -> 12 | F8: =if(ISNA(vlookup($A8, ESPN!$B$2:$E$257, 4, false)), 0, vlookup($A8, ESPN!$B$2:$E$257, 4, false)) -> 68 | G8: =if(ISNA(vlookup($A8, FFToolbox!$B$2:$E$239, 4, false)), 0, vlookup($A8, FFToolbox!$B$2:$E$239, 4, false)) -> 36 | H8: =if(ISNA(vlookup($A8, FantasyPro!$B$2:$E$316, 4, false)), 0, vlookup($A8, FantasyPro!$B$2:$E$316, 4, false)) -> 46 | I8: =if(ISNA(vlookup($A8, RotoWire!$B$2:$E$681, 4, false)), 0, vlookup($A8, RotoWire!$B$2:$E$681, 4, false)) -> 52 | J8: =Average(F8:I8) -> 50.5 | K8: =max(F8:I8)-min(F8:I8) -> 32
A9: Tyreek Hill | B9: Yes | C9: KC | D9: WR | E9: =vlookup(C9,'Team Bye List'!$A$1:$B$33,2,False) -> 12 | F9: =if(ISNA(vlookup($A9, ESPN!$B$2:$E$257, 4, false)), 0, vlookup($A9, ESPN!$B$2:$E$257, 4, false)) -> 67 | G9: =if(ISNA(vlookup($A9, FFToolbox!$B$2:$E$239, 4, false)), 0, vlookup($A9, FFToolbox!$B$2:$E$239, 4, false)) -> 36 | H9: =if(ISNA(vlookup($A9, FantasyPro!$B$2:$E$316, 4, false)), 0, vlookup($A9, FantasyPro!$B$2:$E$316, 4, false)) -> 44 | I9: =if(ISNA(vlookup($A9, RotoWire!$B$2:$E$681, 4, false)), 0, vlookup($A9, RotoWire!$B$2:$E$681, 4, false)) -> 47 | J9: =Average(F9:I9) -> 48.5 | K9: =max(F9:I9)-min(F9:I9) -> 31
A10: Davante Adams | B10: Yes | C10: GB | D10: WR | E10: =vlookup(C10,'Team Bye List'!$A$1:$B$33,2,False) -> 11 | F10: =if(ISNA(vlookup($A10, ESPN!$B$2:$E$257, 4, false)), 0, vlookup($A10, ESPN!$B$2:$E$257, 4, false)) -> 52 | G10: =if(ISNA(vlookup($A10, FFToolbox!$B$2:$E$239, 4, false)), 0, vlookup($A10, FFToolbox!$B$2:$E$239, 4, false)) -> 43 | H10: =if(ISNA(vlookup($A10, FantasyPro!$B$2:$E$316, 4, false)), 0, vlookup($A10, FantasyPro!$B$2:$E$316, 4, false)) -> 43 | I10: =if(ISNA(vlookup($A10, RotoWire!$B$2:$E$681, 4, false)), 0, vlookup($A10, RotoWire!$B$2:$E$681, 4, false)) -> 41 | J10: =Average(F10:I10) -> 44.75 | K10: =max(F10:I10)-min(F10:I10) -> 11
A11: JuJu Smith-Schuster | B11: No | C11: PIT | D11: WR | E11: =vlookup(C11,'Team Bye List'!$A$1:$B$33,2,False) -> 7 | F11: =if(ISNA(vlookup($A11, ESPN!$B$2:$E$257, 4, false)), 0, vlookup($A11, ESPN!$B$2:$E$257, 4, false)) -> 49 | G11: =if(ISNA(vlookup($A11, FFToolbox!$B$2:$E$239, 4, false)), 0, vlookup($A11, FFToolbox!$B$2:$E$239, 4, false)) -> 40 | H11: =if(ISNA(vlookup($A11, FantasyPro!$B$2:$E$316, 4, false)), 0, vlookup($A11, FantasyPro!$B$2:$E$316, 4, false)) -> 40 | I11: =if(ISNA(vlookup($A11, RotoWire!$B$2:$E$681, 4, false)), 0, vlookup($A11, RotoWire!$B$2:$E$681, 4, false)) -> 50 | J11: =Average(F11:I11) -> 44.75 | K11: =max(F11:I11)-min(F11:I11) -> 10
A12: Odell Beckham | B12: No | C12: CLE | D12: WR | E12: =vlookup(C12,'Team Bye List'!$A$1:$B$33,2,False) -> 7 | F12: =if(ISNA(vlookup($A12, ESPN!$B$2:$E$257, 4, false)), 0, vlookup($A12, ESPN!$B$2:$E$257, 4, false)) -> 51 | G12: =if(ISNA(vlookup($A12, FFToolbox!$B$2:$E$239, 4, false)), 0, vlookup($A12, FFToolbox!$B$2:$E$239, 4, false)) -> 37 | H12: =if(ISNA(vlookup($A12, FantasyPro!$B$2:$E$316, 4, false)), 0, vlookup($A12, FantasyPro!$B$2:$E$316, 4, false)) -> 35 | I12: =if(ISNA(vlookup($A12, RotoWire!$B$2:$E$681, 4, false)), 0, vlookup($A12, RotoWire!$B$2:$E$681, 4, false)) -> 49 | J12: =Average(F12:I12) -> 43 | K12: =max(F12:I12)-min(F12:I12) -> 16
A13: David Johnson | B13: Yes | C13: ARI | D13: RB | E13: =vlookup(C13,'Team Bye List'!$A$1:$B$33,2,False) -> 12 | F13: =if(ISNA(vlookup($A13, ESPN!$B$2:$E$257, 4, false)), 0, vlookup($A13, ESPN!$B$2:$E$257, 4, false)) -> 52 | G13: =if(ISNA(vlookup($A13, FFToolbox!$B$2:$E$239, 4, false)), 0, vlookup($A13, FFToolbox!$B$2:$E$239, 4, false)) -> 40 | H13: =if(ISNA(vlookup($A13, FantasyPro!$B$2:$E$316, 4, false)), 0, vlookup($A13, FantasyPro!$B$2:$E$316, 4, false)) -> 41 | I13: =if(ISNA(vlookup($A13, RotoWire!$B$2:$E$681, 4, false)), 0, vlookup($A13, RotoWire!$B$2:$E$681, 4, false)) -> 37 | J13: =Average(F13:I13) -> 42.5 | K13: =max(F13:I13)-min(F13:I13) -> 15
A14: George Kittle | B14: Yes | C14: SF | D14: TE | E14: =vlookup(C14,'Team Bye List'!$A$1:$B$33,2,False) -> 4 | F14: =if(ISNA(vlookup($A14, ESPN!$B$2:$E$257, 4, false)), 0, vlookup($A14, ESPN!$B$2:$E$257, 4, false)) -> 49 | G14: =if(ISNA(vlookup($A14, FFToolbox!$B$2:$E$239, 4, false)), 0, vlookup($A14, FFToolbox!$B$2:$E$239, 4, false)) -> 31 | H14: =if(ISNA(vlookup($A14, FantasyPro!$B$2:$E$316, 4, false)), 0, vlookup($A14, FantasyPro!$B$2:$E$316, 4, false)) -> 36 | I14: =if(ISNA(vlookup($A14, RotoWire!$B$2:$E$681, 4, false)), 0, vlookup($A14, RotoWire!$B$2:$E$681, 4, false)) -> 50 | J14: =Average(F14:I14) -> 41.5 | K14: =max(F14:I14)-min(F14:I14) -> 19
... A382: Daniel Carlson | B382: No | C382: OAK | D382: K | E382: =vlookup(C382,'Team Bye List'!$A$1:$B$33,2,False) -> 6 | F382: =if(ISNA(vlookup($A382, ESPN!$B$2:$E$257, 4, false)), 0, vlookup($A382, ESPN!$B$2:$E$257, 4, false)) -> 0 | G382: =if(ISNA(vlookup($A382, FFToolbox!$B$2:$E$239, 4, false)), 0, vlookup($A382, FFToolbox!$B$2:$E$239, 4, false)) -> 0 | H382: =if(ISNA(vlookup($A382, FantasyPro!$B$2:$E$316, 4, false)), 0, vlookup($A382, FantasyPro!$B$2:$E$316, 4, false)) -> 0 | I382: =if(ISNA(vlookup($A382, RotoWire!$B$2:$E$681, 4, false)), 0, vlookup($A382, RotoWire!$B$2:$E$681, 4, false)) -> 0 | J382: =Average(F382:I382) -> 0 | K382: =max(F382:I382)-min(F382:I382) -> 0
A383: Danny Amendola | C383: DET | D383: WR | E383: =vlookup(C383,'Team Bye List'!$A$1:$B$33,2,False) -> 5 | F383: =if(ISNA(vlookup($A383, ESPN!$B$2:$E$257, 4, false)), 0, vlookup($A383, ESPN!$B$2:$E$257, 4, false)) -> 0 | G383: =if(ISNA(vlookup($A383, FFToolbox!$B$2:$E$239, 4, false)), 0, vlookup($A383, FFToolbox!$B$2:$E$239, 4, false)) -> 0 | H383: =if(ISNA(vlookup($A383, FantasyPro!$B$2:$E$316, 4, false)), 0, vlookup($A383, FantasyPro!$B$2:$E$316, 4, false)) -> 0 | I383: =if(ISNA(vlookup($A383, RotoWire!$B$2:$E$681, 4, false)), 0, vlookup($A383, RotoWire!$B$2:$E$681, 4, false)) -> 0 | J383: =Average(F383:I383) -> 0 | K383: =max(F383:I383)-min(F383:I383) -> 0
A384: Danny Etling | B384: No | C384: ATL | D384: QB | E384: =vlookup(C384,'Team Bye List'!$A$1:$B$33,2,False) -> 9 | F384: =if(ISNA(vlookup($A384, ESPN!$B$2:$E$257, 4, false)), 0, vlookup($A384, ESPN!$B$2:$E$257, 4, false)) -> 0 | G384: =if(ISNA(vlookup($A384, FFToolbox!$B$2:$E$239, 4, false)), 0, vlookup($A384, FFToolbox!$B$2:$E$239, 4, false)) -> 0 | H384: =if(ISNA(vlookup($A384, FantasyPro!$B$2:$E$316, 4, false)), 0, vlookup($A384, FantasyPro!$B$2:$E$316, 4, false)) -> 0 | I384: =if(ISNA(vlookup($A384, RotoWire!$B$2:$E$681, 4, false)), 0, vlookup($A384, RotoWire!$B$2:$E$681, 4, false)) -> 0 | J384: =Average(F384:I384) -> 0 | K384: =max(F384:I384)-min(F384:I384) -> 0
A385: Dare Ogunbowale | B385: No | C385: TB | D385: RB | E385: =vlookup(C385,'Team Bye List'!$A$1:$B$33,2,False) -> 7 | F385: =if(ISNA(vlookup($A385, ESPN!$B$2:$E$257, 4, false)), 0, vlookup($A385, ESPN!$B$2:$E$257, 4, false)) -> 0 | G385: =if(ISNA(vlookup($A385, FFToolbox!$B$2:$E$239, 4, false)), 0, vlookup($A385, FFToolbox!$B$2:$E$239, 4, false)) -> 0 | H385: =if(ISNA(vlookup($A385, FantasyPro!$B$2:$E$316, 4, false)), 0, vlookup($A385, FantasyPro!$B$2:$E$316, 4, false)) -> 0 | I385: =if(ISNA(vlookup($A385, RotoWire!$B$2:$E$681, 4, false)), 0, vlookup($A385, RotoWire!$B$2:$E$681, 4, false)) -> 0 | J385: =Average(F385:I385) -> 0 | K385: =max(F385:I385)-min(F385:I385) -> 0
A386: Darius Jackson | B386: No | C386: DAL | D386: RB | E386: =vlookup(C386,'Team Bye List'!$A$1:$B$33,2,False) -> 8 | F386: =if(ISNA(vlookup($A386, ESPN!$B$2:$E$257, 4, false)), 0, vlookup($A386, ESPN!$B$2:$E$257, 4, false)) -> 0 | G386: =if(ISNA(vlookup($A386, FFToolbox!$B$2:$E$239, 4, false)), 0, vlookup($A386, FFToolbox!$B$2:$E$239, 4, false)) -> 0 | H386: =if(ISNA(vlookup($A386, FantasyPro!$B$2:$E$316, 4, false)), 0, vlookup($A386, FantasyPro!$B$2:$E$316, 4, false)) -> 0 | I386: =if(ISNA(vlookup($A386, RotoWire!$B$2:$E$681, 4, false)), 0, vlookup($A386, RotoWire!$B$2:$E$681, 4, false)) -> 0 | J386: =Average(F386:I386) -> 0 | K386: =max(F386:I386)-min(F386:I386) -> 0
A387: Darius Jennings | B387: No | C387: TEN | D387: WR | E387: =vlookup(C387,'Team Bye List'!$A$1:$B$33,2,False) -> 11 | F387: =if(ISNA(vlookup($A387, ESPN!$B$2:$E$257, 4, false)), 0, vlookup($A387, ESPN!$B$2:$E$257, 4, false)) -> 0 | G387: =if(ISNA(vlookup($A387, FFToolbox!$B$2:$E$239, 4, false)), 0, vlookup($A387, FFToolbox!$B$2:$E$239, 4, false)) -> 0 | H387: =if(ISNA(vlookup($A387, FantasyPro!$B$2:$E$316, 4, false)), 0, vlookup($A387, FantasyPro!$B$2:$E$316, 4, false)) -> 0 | I387: =if(ISNA(vlookup($A387, RotoWire!$B$2:$E$681, 4, false)), 0, vlookup($A387, RotoWire!$B$2:$E$681, 4, false)) -> 0 | J387: =Average(F387:I387) -> 0 | K387: =max(F387:I387)-min(F387:I387) -> 0
A388: Darius Slayton | B388: No | C388: NYG | D388: WR | E388: =vlookup(C388,'Team Bye List'!$A$1:$B$33,2,False) -> 11 | F388: =if(ISNA(vlookup($A388, ESPN!$B$2:$E$257, 4, false)), 0, vlookup($A388, ESPN!$B$2:$E$257, 4, false)) -> 0 | G388: =if(ISNA(vlookup($A388, FFToolbox!$B$2:$E$239, 4, false)), 0, vlookup($A388, FFToolbox!$B$2:$E$239, 4, false)) -> 0 | H388: =if(ISNA(vlookup($A388, FantasyPro!$B$2:$E$316, 4, false)), 0, vlookup($A388, FantasyPro!$B$2:$E$316, 4, false)) -> 0 | I388: =if(ISNA(vlookup($A388, RotoWire!$B$2:$E$681, 4, false)), 0, vlookup($A388, RotoWire!$B$2:$E$681, 4, false)) -> 0 | J388: =Average(F388:I388) -> 0 | K388: =max(F388:I388)-min(F388:I388) -> 0
A389: Darrel Williams | B389: No | C389: KC | D389: RB | E389: =vlookup(C389,'Team Bye List'!$A$1:$B$33,2,False) -> 12 | F389: =if(ISNA(vlookup($A389, ESPN!$B$2:$E$257, 4, false)), 0, vlookup($A389, ESPN!$B$2:$E$257, 4, false)) -> 0 | G389: =if(ISNA(vlookup($A389, FFToolbox!$B$2:$E$239, 4, false)), 0, vlookup($A389, FFToolbox!$B$2:$E$239, 4, false)) -> 0 | H389: =if(ISNA(vlookup($A389, FantasyPro!$B$2:$E$316, 4, false)), 0, vlookup($A389, FantasyPro!$B$2:$E$316, 4, false)) -> 0 | I389: =if(ISNA(vlookup($A389, RotoWire!$B$2:$E$681, 4, false)), 0, vlookup($A389, RotoWire!$B$2:$E$681, 4, false)) -> 0 | J389: =Average(F389:I389) -> 0 | K389: =max(F389:I389)-min(F389:I389) -> 0
A390: Darrell Daniels | B390: No | C390: ARI | D390: TE | E390: =vlookup(C390,'Team Bye List'!$A$1:$B$33,2,False) -> 12 | F390: =if(ISNA(vlookup($A390, ESPN!$B$2:$E$257, 4, false)), 0, vlookup($A390, ESPN!$B$2:$E$257, 4, false)) -> 0 | G390: =if(ISNA(vlookup($A390, FFToolbox!$B$2:$E$239, 4, false)), 0, vlookup($A390, FFToolbox!$B$2:$E$239, 4, false)) -> 0 | H390: =if(ISNA(vlookup($A390, FantasyPro!$B$2:$E$316, 4, false)), 0, vlookup($A390, FantasyPro!$B$2:$E$316, 4, false)) -> 0 | I390: =if(ISNA(vlookup($A390, RotoWire!$B$2:$E$681, 4, false)), 0, vlookup($A390, RotoWire!$B$2:$E$681, 4, false)) -> 0 | J390: =Average(F390:I390) -> 0 | K390: =max(F390:I390)-min(F390:I390) -> 0
A391: Darren Fells | B391: No | C391: HOU | D391: TE | E391: =vlookup(C391,'Team Bye List'!$A$1:$B$33,2,False) -> 10 | F391: =if(ISNA(vlookup($A391, ESPN!$B$2:$E$257, 4, false)), 0, vlookup($A391, ESPN!$B$2:$E$257, 4, false)) -> 0 | G391: =if(ISNA(vlookup($A391, FFToolbox!$B$2:$E$239, 4, false)), 0, vlookup($A391, FFToolbox!$B$2:$E$239, 4, false)) -> 0 | H391: =if(ISNA(vlookup($A391, FantasyPro!$B$2:$E$316, 4, false)), 0, vlookup($A391, FantasyPro!$B$2:$E$316, 4, false)) -> 0 | I391: =if(ISNA(vlookup($A391, RotoWire!$B$2:$E$681, 4, false)), 0, vlookup($A391, RotoWire!$B$2:$E$681, 4, false)) -> 0 | J391: =Average(F391:I391) -> 0 | K391: =max(F391:I391)-min(F391:I391) -> 0
A392: Darren Sproles | B392: No | C392: PHI | D392: RB | E392: =vlookup(C392,'Team Bye List'!$A$1:$B$33,2,False) -> 10 | F392: =if(ISNA(vlookup($A392, ESPN!$B$2:$E$257, 4, false)), 0, vlookup($A392, ESPN!$B$2:$E$257, 4, false)) -> 0 | G392: =if(ISNA(vlookup($A392, FFToolbox!$B$2:$E$239, 4, false)), 0, vlookup($A392, FFToolbox!$B$2:$E$239, 4, false)) -> 0 | H392: =if(ISNA(vlookup($A392, FantasyPro!$B$2:$E$316, 4, false)), 0, vlookup($A392, FantasyPro!$B$2:$E$316, 4, false)) -> 0 | I392: =if(ISNA(vlookup($A392, RotoWire!$B$2:$E$681, 4, false)), 0, vlookup($A392, RotoWire!$B$2:$E$681, 4, false)) -> 0 | J392: =Average(F392:I392) -> 0 | K392: =max(F392:I392)-min(F392:I392) -> 0
A393: Darren Waller | B393: No | C393: OAK | D393: TE | E393: =vlookup(C393,'Team Bye List'!$A$1:$B$33,2,False) -> 6 | F393: =if(ISNA(vlookup($A393, ESPN!$B$2:$E$257, 4, false)), 0, vlookup($A393, ESPN!$B$2:$E$257, 4, false)) -> 0 | G393: =if(ISNA(vlookup($A393, FFToolbox!$B$2:$E$239, 4, false)), 0, vlookup($A393, FFToolbox!$B$2:$E$239, 4, false)) -> 0 | H393: =if(ISNA(vlookup($A393, FantasyPro!$B$2:$E$316, 4, false)), 0, vlookup($A393, FantasyPro!$B$2:$E$316, 4, false)) -> 0 | I393: =if(ISNA(vlookup($A393, RotoWire!$B$2:$E$681, 4, false)), 0, vlookup($A393, RotoWire!$B$2:$E$681, 4, false)) -> 0 | J393: =Average(F393:I393) -> 0 | K393: =max(F393:I393)-min(F393:I393) -> 0
A394: Darvin Kidsy | B394: No | C394: WAS | D394: WR | E394: =vlookup(C394,'Team Bye List'!$A$1:$B$33,2,False) -> 10 | F394: =if(ISNA(vlookup($A394, ESPN!$B$2:$E$257, 4, false)), 0, vlookup($A394, ESPN!$B$2:$E$257, 4, false)) -> 0 | G394: =if(ISNA(vlookup($A394, FFToolbox!$B$2:$E$239, 4, false)), 0, vlookup($A394, FFToolbox!$B$2:$E$239, 4, false)) -> 0 | H394: =if(ISNA(vlookup($A394, FantasyPro!$B$2:$E$316, 4, false)), 0, vlookup($A394, FantasyPro!$B$2:$E$316, 4, false)) -> 0 | I394: =if(ISNA(vlookup($A394, RotoWire!$B$2:$E$681, 4, false)), 0, vlookup($A394, RotoWire!$B$2:$E$681, 4, false)) -> 0 | J394: =Average(F394:I394) -> 0 | K394: =max(F394:I394)-min(F394:I394) -> 0
A395: Daurice Fountain | B395: No | C395: IND | D395: WR | E395: =vlookup(C395,'Team Bye List'!$A$1:$B$33,2,False) -> 6 | F395: =if(ISNA(vlookup($A395, ESPN!$B$2:$E$257, 4, false)), 0, vlookup($A395, ESPN!$B$2:$E$257, 4, false)) -> 0 | G395: =if(ISNA(vlookup($A395, FFToolbox!$B$2:$E$239, 4, false)), 0, vlookup($A395, FFToolbox!$B$2:$E$239, 4, false)) -> 0 | H395: =if(ISNA(vlookup($A395, FantasyPro!$B$2:$E$316, 4, false)), 0, vlookup($A395, FantasyPro!$B$2:$E$316, 4, false)) -> 0 | I395: =if(ISNA(vlookup($A395, RotoWire!$B$2:$E$681, 4, false)), 0, vlookup($A395, RotoWire!$B$2:$E$681, 4, false)) -> 0 | J395: =Average(F395:I395) -> 0 | K395: =max(F395:I395)-min(F395:I395) -> 0
... A641: Noah Brown | B641: No | C641: DAL | D641: WR | E641: =vlookup(C641,'Team Bye List'!$A$1:$B$33,2,False) -> 8 | F641: =if(ISNA(vlookup($A641, ESPN!$B$2:$E$257, 4, false)), 0, vlookup($A641, ESPN!$B$2:$E$257, 4, false)) -> 0 | G641: =if(ISNA(vlookup($A641, FFToolbox!$B$2:$E$239, 4, false)), 0, vlookup($A641, FFToolbox!$B$2:$E$239, 4, false)) -> 0 | H641: =if(ISNA(vlookup($A641, FantasyPro!$B$2:$E$316, 4, false)), 0, vlookup($A641, FantasyPro!$B$2:$E$316, 4, false)) -> 0 | I641: =if(ISNA(vlookup($A641, RotoWire!$B$2:$E$681, 4, false)), 0, vlookup($A641, RotoWire!$B$2:$E$681, 4, false)) -> 0 | J641: =Average(F641:I641) -> 0 | K641: =max(F641:I641)-min(F641:I641) -> 0
A642: Olabisi Johnson | C642: MIN | D642: WR | E642: =vlookup(C642,'Team Bye List'!$A$1:$B$33,2,False) -> 12 | F642: =if(ISNA(vlookup($A642, ESPN!$B$2:$E$257, 4, false)), 0, vlookup($A642, ESPN!$B$2:$E$257, 4, false)) -> 0 | G642: =if(ISNA(vlookup($A642, FFToolbox!$B$2:$E$239, 4, false)), 0, vlookup($A642, FFToolbox!$B$2:$E$239, 4, false)) -> 0 | H642: =if(ISNA(vlookup($A642, FantasyPro!$B$2:$E$316, 4, false)), 0, vlookup($A642, FantasyPro!$B$2:$E$316, 4, false)) -> 0 | I642: =if(ISNA(vlookup($A642, RotoWire!$B$2:$E$681, 4, false)), 0, vlookup($A642, RotoWire!$B$2:$E$681, 4, false)) -> 0 | J642: =Average(F642:I642) -> 0 | K642: =max(F642:I642)-min(F642:I642) -> 0
A643: Orson Charles | B643: No | C643: DEN | D643: TE | E643: =vlookup(C643,'Team Bye List'!$A$1:$B$33,2,False) -> 10 | F643: =if(ISNA(vlookup($A643, ESPN!$B$2:$E$257, 4, false)), 0, vlookup($A643, ESPN!$B$2:$E$257, 4, false)) -> 0 | G643: =if(ISNA(vlookup($A643, FFToolbox!$B$2:$E$239, 4, false)), 0, vlookup($A643, FFToolbox!$B$2:$E$239, 4, false)) -> 0 | H643: =if(ISNA(vlookup($A643, FantasyPro!$B$2:$E$316, 4, false)), 0, vlookup($A643, FantasyPro!$B$2:$E$316, 4, false)) -> 0 | I643: =if(ISNA(vlookup($A643, RotoWire!$B$2:$E$681, 4, false)), 0, vlookup($A643, RotoWire!$B$2:$E$681, 4, false)) -> 0 | J643: =Average(F643:I643) -> 0 | K643: =max(F643:I643)-min(F643:I643) -> 0
A644: Parris Campbell | B644: No | C644: IND | D644: WR | E644: =vlookup(C644,'Team Bye List'!$A$1:$B$33,2,False) -> 6 | F644: =if(ISNA(vlookup($A644, ESPN!$B$2:$E$257, 4, false)), 0, vlookup($A644, ESPN!$B$2:$E$257, 4, false)) -> 0 | G644: =if(ISNA(vlookup($A644, FFToolbox!$B$2:$E$239, 4, false)), 0, vlookup($A644, FFToolbox!$B$2:$E$239, 4, false)) -> 0 | H644: =if(ISNA(vlookup($A644, FantasyPro!$B$2:$E$316, 4, false)), 0, vlookup($A644, FantasyPro!$B$2:$E$316, 4, false)) -> 0 | I644: =if(ISNA(vlookup($A644, RotoWire!$B$2:$E$681, 4, false)), 0, vlookup($A644, RotoWire!$B$2:$E$681, 4, false)) -> 0 | J644: =Average(F644:I644) -> 0 | K644: =max(F644:I644)-min(F644:I644) -> 0
A645: Paul Perkins | B645: No | C645: NYG | D645: RB | E645: =vlookup(C645,'Team Bye List'!$A$1:$B$33,2,False) -> 11 | F645: =if(ISNA(vlookup($A645, ESPN!$B$2:$E$257, 4, false)), 0, vlookup($A645, ESPN!$B$2:$E$257, 4, false)) -> 0 | G645: =if(ISNA(vlookup($A645, FFToolbox!$B$2:$E$239, 4, false)), 0, vlookup($A645, FFToolbox!$B$2:$E$239, 4, false)) -> 0 | H645: =if(ISNA(vlookup($A645, FantasyPro!$B$2:$E$316, 4, false)), 0, vlookup($A645, FantasyPro!$B$2:$E$316, 4, false)) -> 0 | I645: =if(ISNA(vlookup($A645, RotoWire!$B$2:$E$681, 4, false)), 0, vlookup($A645, RotoWire!$B$2:$E$681, 4, false)) -> 0 | J645: =Average(F645:I645) -> 0 | K645: =max(F645:I645)-min(F645:I645) -> 0
A646: Paul Richardson | B646: No | C646: WAS | D646: WR | E646: =vlookup(C646,'Team Bye List'!$A$1:$B$33,2,False) -> 10 | F646: =if(ISNA(vlookup($A646, ESPN!$B$2:$E$257, 4, false)), 0, vlookup($A646, ESPN!$B$2:$E$257, 4, false)) -> 0 | G646: =if(ISNA(vlookup($A646, FFToolbox!$B$2:$E$239, 4, false)), 0, vlookup($A646, FFToolbox!$B$2:$E$239, 4, false)) -> 0 | H646: =if(ISNA(vlookup($A646, FantasyPro!$B$2:$E$316, 4, false)), 0, vlookup($A646, FantasyPro!$B$2:$E$316, 4, false)) -> 0 | I646: =if(ISNA(vlookup($A646, RotoWire!$B$2:$E$681, 4, false)), 0, vlookup($A646, RotoWire!$B$2:$E$681, 4, false)) -> 0 | J646: =Average(F646:I646) -> 0 | K646: =max(F646:I646)-min(F646:I646) -> 0
A647: Paxton Lynch | B647: No | C647: SEA | D647: QB | E647: =vlookup(C647,'Team Bye List'!$A$1:$B$33,2,False) -> 11 | F647: =if(ISNA(vlookup($A647, ESPN!$B$2:$E$257, 4, false)), 0, vlookup($A647, ESPN!$B$2:$E$257, 4, false)) -> 0 | G647: =if(ISNA(vlookup($A647, FFToolbox!$B$2:$E$239, 4, false)), 0, vlookup($A647, FFToolbox!$B$2:$E$239, 4, false)) -> 0 | H647: =if(ISNA(vlookup($A647, FantasyPro!$B$2:$E$316, 4, false)), 0, vlookup($A647, FantasyPro!$B$2:$E$316, 4, false)) -> 0 | I647: =if(ISNA(vlookup($A647, RotoWire!$B$2:$E$681, 4, false)), 0, vlookup($A647, RotoWire!$B$2:$E$681, 4, false)) -> 0 | J647: =Average(F647:I647) -> 0 | K647: =max(F647:I647)-min(F647:I647) -> 0
A648: Pharaoh Brown | B648: No | C648: CLE | D648: TE | E648: =vlookup(C648,'Team Bye List'!$A$1:$B$33,2,False) -> 7 | F648: =if(ISNA(vlookup($A648, ESPN!$B$2:$E$257, 4, false)), 0, vlookup($A648, ESPN!$B$2:$E$257, 4, false)) -> 0 | G648: =if(ISNA(vlookup($A648, FFToolbox!$B$2:$E$239, 4, false)), 0, vlookup($A648, FFToolbox!$B$2:$E$239, 4, false)) -> 0 | H648: =if(ISNA(vlookup($A648, FantasyPro!$B$2:$E$316, 4, false)), 0, vlookup($A648, FantasyPro!$B$2:$E$316, 4, false)) -> 0 | I648: =if(ISNA(vlookup($A648, RotoWire!$B$2:$E$681, 4, false)), 0, vlookup($A648, RotoWire!$B$2:$E$681, 4, false)) -> 0 | J648: =Average(F648:I648) -> 0 | K648: =max(F648:I648)-min(F648:I648) -> 0
A649: Pharoh Cooper | B649: No | C649: ARI | D649: WR | E649: =vlookup(C649,'Team Bye List'!$A$1:$B$33,2,False) -> 12 | F649: =if(ISNA(vlookup($A649, ESPN!$B$2:$E$257, 4, false)), 0, vlookup($A649, ESPN!$B$2:$E$257, 4, false)) -> 0 | G649: =if(ISNA(vlookup($A649, FFToolbox!$B$2:$E$239, 4, false)), 0, vlookup($A649, FFToolbox!$B$2:$E$239, 4, false)) -> 0 | H649: =if(ISNA(vlookup($A649, FantasyPro!$B$2:$E$316, 4, false)), 0, vlookup($A649, FantasyPro!$B$2:$E$316, 4, false)) -> 0 | I649: =if(ISNA(vlookup($A649, RotoWire!$B$2:$E$681, 4, false)), 0, vlookup($A649, RotoWire!$B$2:$E$681, 4, false)) -> 0 | J649: =Average(F649:I649) -> 0 | K649: =max(F649:I649)-min(F649:I649) -> 0
A650: Phillip Dorsett | B650: No | C650: NE | D650: WR | E650: =vlookup(C650,'Team Bye List'!$A$1:$B$33,2,False) -> 10 | F650: =if(ISNA(vlookup($A650, ESPN!$B$2:$E$257, 4, false)), 0, vlookup($A650, ESPN!$B$2:$E$257, 4, false)) -> 0 | G650: =if(ISNA(vlookup($A650, FFToolbox!$B$2:$E$239, 4, false)), 0, vlookup($A650, FFToolbox!$B$2:$E$239, 4, false)) -> 0 | H650: =if(ISNA(vlookup($A650, FantasyPro!$B$2:$E$316, 4, false)), 0, vlookup($A650, FantasyPro!$B$2:$E$316, 4, false)) -> 0 | I650: =if(ISNA(vlookup($A650, RotoWire!$B$2:$E$681, 4, false)), 0, vlookup($A650, RotoWire!$B$2:$E$681, 4, false)) -> 0 | J650: =Average(F650:I650) -> 0 | K650: =max(F650:I650)-min(F650:I650) -> 0
A651: Preston Williams | B651: No | C651: MIA | D651: WR | E651: =vlookup(C651,'Team Bye List'!$A$1:$B$33,2,False) -> 5 | F651: =if(ISNA(vlookup($A651, ESPN!$B$2:$E$257, 4, false)), 0, vlookup($A651, ESPN!$B$2:$E$257, 4, false)) -> 0 | G651: =if(ISNA(vlookup($A651, FFToolbox!$B$2:$E$239, 4, false)), 0, vlookup($A651, FFToolbox!$B$2:$E$239, 4, false)) -> 0 | H651: =if(ISNA(vlookup($A651, FantasyPro!$B$2:$E$316, 4, false)), 0, vlookup($A651, FantasyPro!$B$2:$E$316, 4, false)) -> 0 | I651: =if(ISNA(vlookup($A651, RotoWire!$B$2:$E$681, 4, false)), 0, vlookup($A651, RotoWire!$B$2:$E$681, 4, false)) -> 0 | J651: =Average(F651:I651) -> 0 | K651: =max(F651:I651)-min(F651:I651) -> 0
A652: Qadree Ollison | B652: No | C652: ATL | D652: RB | E652: =vlookup(C652,'Team Bye List'!$A$1:$B$33,2,False) -> 9 | F652: =if(ISNA(vlookup($A652, ESPN!$B$2:$E$257, 4, false)), 0, vlookup($A652, ESPN!$B$2:$E$257, 4, false)) -> 0 | G652: =if(ISNA(vlookup($A652, FFToolbox!$B$2:$E$239, 4, false)), 0, vlookup($A652, FFToolbox!$B$2:$E$239, 4, false)) -> 0 | H652: =if(ISNA(vlookup($A652, FantasyPro!$B$2:$E$316, 4, false)), 0, vlookup($A652, FantasyPro!$B$2:$E$316, 4, false)) -> 0 | I652: =if(ISNA(vlookup($A652, RotoWire!$B$2:$E$681, 4, false)), 0, vlookup($A652, RotoWire!$B$2:$E$681, 4, false)) -> 0 | J652: =Average(F652:I652) -> 0 | K652: =max(F652:I652)-min(F652:I652) -> 0
...

Sheet Players We Want
A1: Name | B1: Team | C1: Position | D1: Bye Week | E1: Keeper Price | F1: Start Bid | G1: Avg Price | H1: Max Bid | L1: =200-L19 -> 144
A2: Antonio Brown | B2: OAK | C2: WR | D2: 6 | E2: 80 | J2: Position | K2: Name | L2: Amount
A3: Odell Beckham | B3: CLE | C3: WR | D3: 7 | E3: 66 | G3: 43 | J3: QB1
A4: Julio Jones | B4: ATL | C4: WR | D4: 9 | E4: 62 | G4: 52 | J4: RB1 | K4: Christian McCaffrey | L4: 44
A5: JuJu Smith Schuster | B5: PIT | C5: WR | D5: 7 | E5: 36 | J5: WR1 | K5: Calvin Ridley | L5: 12
A6: Mike Evans | B6: TB | C6: WR | D6: 7 | E6: 52 | J6: WR2
A7: Saquon Barkley | B7: NYG | C7: RB | D7: 11 | E7: 82 | J7: TE
A8: Le'Veon Bell | B8: NYJ | C8: RB | D8: 4 | E8: 86 | J8: RB2
A9: Dalvin Cook | B9: MIN | C9: RB | D9: 12 | E9: 46 | J9: D/ST
A10: Devonta Freeman | B10: ATL | C10: RB | D10: 9 | E10: 46 | J10: K
A11: Chris Carson | B11: SEA | C11: RB | D11: 11 | E11: 20 | J11: WR3
A12: David Montgomery | B12: CHI | C12: RB | D12: 6 | E12: 0 | J12: WR4
A13: Duke Johnson | B13: HOU | C13: RB | D13: 10 | E13: 12 | J13: QB2
A14: Drew Brees | B14: NO | C14: QB | D14: 9 | E14: 36 | J14: RB3
A15: Aaron Rodgers | B15: GB | C15: QB | D15: 11 | E15: 50 | J15: WR5
A16: Jared Goff | B16: LAR | C16: QB | D16: 9 | E16: 12 | J16: TE2
A17: Zach Ertz | B17: PHI | C17: TE | D17: 10 | E17: 30 | J17: RB4
A18: OJ Howard | B18: TB | C18: TE | D18: 7 | E18: 12 | J18: D/ST2
A19: Austin Hooper | B19: ATL | C19: TE | D19: 9 | E19: 12 | L19: =sum(L3:L18) -> 56
A20: David Njoku | B20: CLE | C20: TE | D20: 7 | E20: 20
A21: Jimmy Graham | B21: GB | C21: TE | D21: 11 | E21: 24
A22: Kyle Rudolph | B22: MIN | C22: TE | D22: 12 | E22: 20
A23: Will Lutz | B23: NO | C23: K | D23: 9 | E23: 12
A24: Stephen Gostkowski | B24: NE | C24: K | D24: 10 | E24: 14
A25: Chicago Bears | B25: CHI | C25: D/ST | D25: 6 | E25: 22
A26: Los Angeles Chargers | B26: LAC | C26: D/ST | D26: 12 | E26: 12
A27: Los Angeles Rams | B27: LAR | C27: D/ST | D27: 9 | E27: 14
A28: Houston Texans | B28: HOU | C28: D/ST | D28: 10 | E28: 14

Sheet Team Bye List
A1: Team | B1: Bye Week
A2: ARI | B2: 12
A3: ATL | B3: 9
A4: BAL | B4: 8
A5: BUF | B5: 6
A6: CAR | B6: 7
A7: CHI | B7: 6
A8: CIN | B8: 9
A9: CLE | B9: 7
A10: DAL | B10: 8
A11: DEN | B11: 10
A12: DET | B12: 5
A13: GB | B13: 11
... A33: WAS | B33: 10

Sheet Keepers
A1: Name | B1: Pos | C1: Value
A2: Tarik Cohen | B2: RB | C2: 14
A3: Evan Engram | B3: TE | C3: 18
A4: Tyler Lockett | B4: WR | C4: 14
A5: Larmar Jackson | B5: QB | C5: 12
A6: James Conner | B6: RB | C6: 14
A7: Chris Godwin | B7: WR | C7: 12
A8: Deshaun Watson | B8: QB | C8: 16
A9: Stefon Diggs | B9: WR | C9: 26
A10: Todd Gurley | B10: RB | C10: 52
A11: Michael Thomas | B11: WR | C11: 36
A12: George Kittle | B12: TE | C12: 16
A13: Adam Thielen | B13: WR | C13: 26
... A29: Nick Chubb | B29: RB | C29: 16
