Workbook

Sheet ESPN
A1: Rank | B1: Name | C1: Team | D1: Position | E1: Value
A2: 1 | B2: Christian McCaffrey | C2: CAR | D2: RB | E2: 59
A3: 2 | B3: Patrick Mahomes | C3: KC | D3: QB | E3: 57
A4: 3 | B4: Lamar Jackson | C4: BAL | D4: QB | E4: 52
A5: 4 | B5: Ezekiel Elliott | C5: DAL | D5: RB | E5: 51
A6: 5 | B6: Travis Kelce | C6: KC | D6: TE | E6: 50
A7: 6 | B7: Josh Jacobs | C7: LV | D7: RB | E7: 49
A8: 7 | B8: Deshaun Watson | C8: HOU | D8: QB | E8: 48
A9: 8 | B9: Dalvin Cook | C9: MIN | D9: RB | E9: 46
A10: 9 | B10: Michael Thomas | C10: NO | D10: WR | E10: 42
A11: 10 | B11: George Kittle | C11: SF | D11: TE | E11: 42
A12: 11 | B12: Saquon Barkley | C12: NYG | D12: RB | E12: 39
A13: 12 | B13: Tyreek Hill | C13: KC | D13: WR | E13: 39
... A1031: 1030 | B1031: Clayton Thorson | C1031: DAL | D1031: QB | E1031: 0

Sheet FantasyPro
A1: Rank | B1: Name | C1: Team | D1: Position | E1: Value
A2: 1 | B2: Christian McCaffrey | C2: CAR | D2: RB | E2: 63
A3: 2 | B3: Saquon Barkley | C3: NYG | D3: RB | E3: 53
A4: 3 | B4: Ezekiel Elliott | C4: DAL | D4: RB | E4: 52
A5: 4 | B5: Alvin Kamara | C5: NO | D5: RB | E5: 52
A6: 5 | B6: Dalvin Cook | C6: MIN | D6: RB | E6: 49
A7: 6 | B7: Derrick Henry | C7: TEN | D7: RB | E7: 48
A8: 7 | B8: Michael Thomas | C8: NO | D8: WR | E8: 45
A9: 8 | B9: Davante Adams | C9: GB | D9: WR | E9: 45
A10: 9 | B10: Clyde Edwards-Helaire | C10: KC | D10: RB | E10: 42
A11: 10 | B11: Joe Mixon | C11: CIN | D11: RB | E11: 37
A12: 11 | B12: Julio Jones | C12: ATL | D12: WR | E12: 36
A13: 12 | B13: Tyreek Hill | C13: KC | D13: WR | E13: 36
... A514: 513 | B514: Hunter Bryant | C514: DET | D514: TE | E514: 0

Sheet Ultimate Draft Kit
A1: Rank | B1: Name | C1: Team | D1: Position | E1: Value
A2: 1 | B2: Christian McCaffrey | C2: CAR | D2: RB | E2: 64
A3: 2 | B3: Saquon Barkley | C3: NYG | D3: RB | E3: 55
A4: 3 | B4: Ezekiel Elliott | C4: DAL | D4: RB | E4: 50
A5: 4 | B5: Michael Thomas | C5: NO | D5: WR | E5: 48
A6: 5 | B6: Dalvin Cook | C6: MIN | D6: RB | E6: 46
A7: 6 | B7: Clyde Edwards-Helaire | C7: KC | D7: RB | E7: 45
A8: 7 | B8: Alvin Kamara | C8: NO | D8: RB | E8: 44
A9: 8 | B9: Davante Adams | C9: GB | D9: WR | E9: 42
A10: 9 | B10: Derrick Henry | C10: TEN | D10: RB | E10: 42
A11: 10 | B11: Julio Jones | C11: ATL | D11: WR | E11: 41
A12: 11 | B12: Josh Jacobs | C12: LV | D12: RB | E12: 41
A13: 12 | B13: Aaron Jones | C13: GB | D13: RB | E13: 40
... A261: 260 | B261: Anthony McFarland Jr. | C261: PIT | D261: RB | E261: 1

Sheet FFToolbox
A1: Rank | B1: Name | C1: Team | D1: Position | E1: Value
A2: 1 | B2: Ezekiel Elliott | C2: =vlookup(B2,Masterview!$A$2:$C$977, 3, FALSE) -> DAL | D2: RB | E2: 54
A3: 2 | B3: Christian McCaffrey | C3: =vlookup(B3,Masterview!$A$2:$C$977, 3, FALSE) -> CAR | D3: RB | E3: 52
A4: 3 | B4: Saquon Barkley | C4: =vlookup(B4,Masterview!$A$2:$C$977, 3, FALSE) -> NYG | D4: RB | E4: 52
A5: 4 | B5: Julio Jones | C5: =vlookup(B5,Masterview!$A$2:$C$977, 3, FALSE) -> ATL | D5: WR | E5: 50
A6: 5 | B6: Clyde Edwards-Helaire | C6: =vlookup(B6,Masterview!$A$2:$C$977, 3, FALSE) -> KC | D6: RB | E6: 48
A7: 6 | B7: Michael Thomas | C7: =vlookup(B7,Masterview!$A$2:$C$977, 3, FALSE) -> NO | D7: WR | E7: 48
A8: 7 | B8: Alvin Kamara | C8: =vlookup(B8,Masterview!$A$2:$C$977, 3, FALSE) -> NO | D8: RB | E8: 46
A9: 8 | B9: Davante Adams | C9: =vlookup(B9,Masterview!$A$2:$C$977, 3, FALSE) -> GB | D9: WR | E9: 46
A10: 9 | B10: Patrick Mahomes | C10: =vlookup(B10,Masterview!$A$2:$C$977, 3, FALSE) -> KC | D10: QB | E10: 46
A11: 10 | B11: Dalvin Cook | C11: =vlookup(B11,Masterview!$A$2:$C$977, 3, FALSE) -> MIN | D11: RB | E11: 42
A12: 11 | B12: DeAndre Hopkins | C12: =vlookup(B12,Masterview!$A$2:$C$977, 3, FALSE) -> ARI | D12: WR | E12: 42
A13: 12 | B13: Tyreek Hill | C13: =vlookup(B13,Masterview!$A$2:$C$977, 3, FALSE) -> KC | D13: WR | E13: 40
... A416: 416 | B416: John Ursua | C416: =vlookup(B416,Masterview!$A$2:$C$977, 3, FALSE) -> SEA | D416: WR | E416: 0
A417: 417 | B417: John Wolford | C417: LAR | D417: QB | E417: 0
A418: 418 | B418: John Wolford | C418: LAR | D418: QB | E418: 0
A419: 419 | B419: Jordan Chunn | C419: =vlookup(B419,Masterview!$A$2:$C$977, 3, FALSE) -> DAL | D419: RB | E419: 0
A420: 420 | B420: Jordan Reed | C420: =vlookup(B420,Masterview!$A$2:$C$977, 3, FALSE) -> #N/A | D420: TE | E420: 0
A421: 421 | B421: Jordan Wilkins | C421: =vlookup(B421,Masterview!$A$2:$C$977, 3, FALSE) -> IND | D421: RB | E421: 0
A422: 422 | B422: Joshua Dobbs | C422: =vlookup(B422,Masterview!$A$2:$C$977, 3, FALSE) -> JAC | D422: QB | E422: 0
A423: 423 | B423: Justice Hill | C423: =vlookup(B423,Masterview!$A$2:$C$977, 3, FALSE) -> BAL | D423: RB | E423: 0
A424: 424 | B424: Justin Watson | C424: =vlookup(B424,Masterview!$A$2:$C$977, 3, FALSE) -> TB | D424: WR | E424: 0
A425: 425 | B425: Kalif Raymond | C425: =vlookup(B425,Masterview!$A$2:$C$977, 3, FALSE) -> TEN | D425: WR | E425: 0
A426: 426 | B426: Kansas City Chiefs | C426: =vlookup(B426,Masterview!$A$2:$C$977, 3, FALSE) -> KC | D426: DST | E426: 0
A427: 427 | B427: Keelan Cole | C427: =vlookup(B427,Masterview!$A$2:$C$977, 3, FALSE) -> JAC | D427: WR | E427: 0
A428: 428 | B428: KeeSean Johnson | C428: =vlookup(B428,Masterview!$A$2:$C$977, 3, FALSE) -> ARI | D428: WR | E428: 0
A429: 429 | B429: Kelvin Harmon | C429: =vlookup(B429,Masterview!$A$2:$C$977, 3, FALSE) -> WAS | D429: WR | E429: 0
A430: 430 | B430: Kenneth Dixon | C430: =vlookup(B430,Masterview!$A$2:$C$977, 3, FALSE) -> NYJ | D430: RB | E430: 0
... A475: 475 | B475: Will Grier | C475: =vlookup(B475,Masterview!$A$2:$C$977, 3, FALSE) -> CAR | D475: QB | E475: 0

Sheet Masterview
A1: Name | B1: Keeper | C1: Team | D1: Pos | E1: Bye Week | F1: ESPN | G1: UDK | H1: FantasyPro | I1: FFToolbox | J1: Avg Going Rate | K1: Variation
A2: Christian McCaffrey | B2: Yes | C2: CAR | D2: RB | E2: =vlookup(C2,'Team Bye List'!$A$1:$B$33,2,False) -> 12 | F2: =if(ISNA(vlookup($A2, ESPN!$B$2:$E$1010, 4, false)), 0, vlookup($A2, ESPN!$B$2:$E$1010, 4, false)) -> 59 | G2: =if(ISNA(vlookup($A2,'Ultimate Draft Kit'!$B$2:$E$261,4, false)), 0, vlookup($A2,'Ultimate Draft Kit'!$B$2:$E$261, 4, false)) -> 64 | H2: =if(ISNA(vlookup($A2, FantasyPro!$B$2:$E$514,4,false)),0,vlookup($A2,FantasyPro!$B$2:$E$514,4,false)) -> 63 | I2: =if(ISNA(vlookup($A2, FFToolbox!$B$2:$E$618, 4, false)), 0, vlookup($A2, FFToolbox!$B$2:$E$618, 4, false)) -> 52 | J2: =Average(F2:I2) -> 59.5 | K2: =max(F2:I2)-min(F2:I2) -> 12
A3: Ezekiel Elliott | B3: Yes | C3: DAL | D3: RB | E3: =vlookup(C3,'Team Bye List'!$A$1:$B$33,2,False) -> 10 | F3: =if(ISNA(vlookup($A3, ESPN!$B$2:$E$1010, 4, false)), 0, vlookup($A3, ESPN!$B$2:$E$1010, 4, false)) -> 51 | G3: =if(ISNA(vlookup($A3,'Ultimate Draft Kit'!$B$2:$E$261,4, false)), 0, vlookup($A3,'Ultimate Draft Kit'!$B$2:$E$261, 4, false)) -> 50 | H3: =if(ISNA(vlookup($A3, FantasyPro!$B$2:$E$514,4,false)),0,vlookup($A3,FantasyPro!$B$2:$E$514,4,false)) -> 52 | I3: =if(ISNA(vlookup($A3, FFToolbox!$B$2:$E$618, 4, false)), 0, vlookup($A3, FFToolbox!$B$2:$E$618, 4, false)) -> 54 | J3: =Average(F3:I3) -> 51.75 | K3: =max(F3:I3)-min(F3:I3) -> 4
A4: Saquon Barkley | B4: Yes | C4: NYG | D4: RB | E4: =vlookup(C4,'Team Bye List'!$A$1:$B$33,2,False) -> 11 | F4: =if(ISNA(vlookup($A4, ESPN!$B$2:$E$1010, 4, false)), 0, vlookup($A4, ESPN!$B$2:$E$1010, 4, false)) -> 39 | G4: =if(ISNA(vlookup($A4,'Ultimate Draft Kit'!$B$2:$E$261,4, false)), 0, vlookup($A4,'Ultimate Draft Kit'!$B$2:$E$261, 4, false)) -> 55 | H4: =if(ISNA(vlookup($A4, FantasyPro!$B$2:$E$514,4,false)),0,vlookup($A4,FantasyPro!$B$2:$E$514,4,false)) -> 53 | I4: =if(ISNA(vlookup($A4, FFToolbox!$B$2:$E$618, 4, false)), 0, vlookup($A4, FFToolbox!$B$2:$E$618, 4, false)) -> 52 | J4: =Average(F4:I4) -> 49.75 | K4: =max(F4:I4)-min(F4:I4) -> 16
A5: Dalvin Cook | B5: Yes | C5: MIN | D5: RB | E5: =vlookup(C5,'Team Bye List'!$A$1:$B$33,2,False) -> 7 | F5: =if(ISNA(vlookup($A5, ESPN!$B$2:$E$1010, 4, false)), 0, vlookup($A5, ESPN!$B$2:$E$1010, 4, false)) -> 46 | G5: =if(ISNA(vlookup($A5,'Ultimate Draft Kit'!$B$2:$E$261,4, false)), 0, vlookup($A5,'Ultimate Draft Kit'!$B$2:$E$261, 4, false)) -> 46 | H5: =if(ISNA(vlookup($A5, FantasyPro!$B$2:$E$514,4,false)),0,vlookup($A5,FantasyPro!$B$2:$E$514,4,false)) -> 49 | I5: =if(ISNA(vlookup($A5, FFToolbox!$B$2:$E$618, 4, false)), 0, vlookup($A5, FFToolbox!$B$2:$E$618, 4, false)) -> 42 | J5: =Average(F5:I5) -> 45.75 | K5: =max(F5:I5)-min(F5:I5) -> 7
A6: Michael Thomas | B6: Yes | C6: NO | D6: WR | E6: =vlookup(C6,'Team Bye List'!$A$1:$B$33,2,False) -> 6 | F6: =if(ISNA(vlookup($A6, ESPN!$B$2:$E$1010, 4, false)), 0, vlookup($A6, ESPN!$B$2:$E$1010, 4, false)) -> 42 | G6: =if(ISNA(vlookup($A6,'Ultimate Draft Kit'!$B$2:$E$261,4, false)), 0, vlookup($A6,'Ultimate Draft Kit'!$B$2:$E$261, 4, false)) -> 48 | H6: =if(ISNA(vlookup($A6, FantasyPro!$B$2:$E$514,4,false)),0,vlookup($A6,FantasyPro!$B$2:$E$514,4,false)) -> 45 | I6: =if(ISNA(vlookup($A6, FFToolbox!$B$2:$E$618, 4, false)), 0, vlookup($A6, FFToolbox!$B$2:$E$618, 4, false)) -> 48 | J6: =Average(F6:I6) -> 45.75 | K6: =max(F6:I6)-min(F6:I6) -> 6
A7: Alvin Kamara | B7: Yes | C7: NO | D7: RB | E7: =vlookup(C7,'Team Bye List'!$A$1:$B$33,2,False) -> 6 | F7: =if(ISNA(vlookup($A7, ESPN!$B$2:$E$1010, 4, false)), 0, vlookup($A7, ESPN!$B$2:$E$1010, 4, false)) -> 35 | G7: =if(ISNA(vlookup($A7,'Ultimate Draft Kit'!$B$2:$E$261,4, false)), 0, vlookup($A7,'Ultimate Draft Kit'!$B$2:$E$261, 4, false)) -> 44 | H7: =if(ISNA(vlookup($A7, FantasyPro!$B$2:$E$514,4,false)),0,vlookup($A7,FantasyPro!$B$2:$E$514,4,false)) -> 52 | I7: =if(ISNA(vlookup($A7, FFToolbox!$B$2:$E$618, 4, false)), 0, vlookup($A7, FFToolbox!$B$2:$E$618, 4, false)) -> 46 | J7: =Average(F7:I7) -> 44.25 | K7: =max(F7:I7)-min(F7:I7) -> 17
A8: Clyde Edwards-Helaire | B8: Yes | C8: KC | D8: RB | E8: =vlookup(C8,'Team Bye List'!$A$1:$B$33,2,False) -> 10 | F8: =if(ISNA(vlookup($A8, ESPN!$B$2:$E$1010, 4, false)), 0, vlookup($A8, ESPN!$B$2:$E$1010, 4, false)) -> 36 | G8: =if(ISNA(vlookup($A8,'Ultimate Draft Kit'!$B$2:$E$261,4, false)), 0, vlookup($A8,'Ultimate Draft Kit'!$B$2:$E$261, 4, false)) -> 45 | H8: =if(ISNA(vlookup($A8, FantasyPro!$B$2:$E$514,4,false)),0,vlookup($A8,FantasyPro!$B$2:$E$514,4,false)) -> 42 | I8: =if(ISNA(vlookup($A8, FFToolbox!$B$2:$E$618, 4, false)), 0, vlookup($A8, FFToolbox!$B$2:$E$618, 4, false)) -> 48 | J8: =Average(F8:I8) -> 42.75 | K8: =max(F8:I8)-min(F8:I8) -> 12
A9: Derrick Henry | B9: Yes | C9: TEN | D9: RB | E9: =vlookup(C9,'Team Bye List'!$A$1:$B$33,2,False) -> 7 | F9: =if(ISNA(vlookup($A9, ESPN!$B$2:$E$1010, 4, false)), 0, vlookup($A9, ESPN!$B$2:$E$1010, 4, false)) -> 36 | G9: =if(ISNA(vlookup($A9,'Ultimate Draft Kit'!$B$2:$E$261,4, false)), 0, vlookup($A9,'Ultimate Draft Kit'!$B$2:$E$261, 4, false)) -> 42 | H9: =if(ISNA(vlookup($A9, FantasyPro!$B$2:$E$514,4,false)),0,vlookup($A9,FantasyPro!$B$2:$E$514,4,false)) -> 48 | I9: =if(ISNA(vlookup($A9, FFToolbox!$B$2:$E$618, 4, false)), 0, vlookup($A9, FFToolbox!$B$2:$E$618, 4, false)) -> 38 | J9: =Average(F9:I9) -> 41 | K9: =max(F9:I9)-min(F9:I9) -> 12
A10: Davante Adams | B10: Yes | C10: GB | D10: WR | E10: =vlookup(C10,'Team Bye List'!$A$1:$B$33,2,False) -> 5 | F10: =if(ISNA(vlookup($A10, ESPN!$B$2:$E$1010, 4, false)), 0, vlookup($A10, ESPN!$B$2:$E$1010, 4, false)) -> 28 | G10: =if(ISNA(vlookup($A10,'Ultimate Draft Kit'!$B$2:$E$261,4, false)), 0, vlookup($A10,'Ultimate Draft Kit'!$B$2:$E$261, 4, false)) -> 42 | H10: =if(ISNA(vlookup($A10, FantasyPro!$B$2:$E$514,4,false)),0,vlookup($A10,FantasyPro!$B$2:$E$514,4,false)) -> 45 | I10: =if(ISNA(vlookup($A10, FFToolbox!$B$2:$E$618, 4, false)), 0, vlookup($A10, FFToolbox!$B$2:$E$618, 4, false)) -> 46 | J10: =Average(F10:I10) -> 40.25 | K10: =max(F10:I10)-min(F10:I10) -> 18
A11: Julio Jones | B11: Yes | C11: ATL | D11: WR | E11: =vlookup(C11,'Team Bye List'!$A$1:$B$33,2,False) -> 10 | F11: =if(ISNA(vlookup($A11, ESPN!$B$2:$E$1010, 4, false)), 0, vlookup($A11, ESPN!$B$2:$E$1010, 4, false)) -> 32 | G11: =if(ISNA(vlookup($A11,'Ultimate Draft Kit'!$B$2:$E$261,4, false)), 0, vlookup($A11,'Ultimate Draft Kit'!$B$2:$E$261, 4, false)) -> 41 | H11: =if(ISNA(vlookup($A11, FantasyPro!$B$2:$E$514,4,false)),0,vlookup($A11,FantasyPro!$B$2:$E$514,4,false)) -> 36 | I11: =if(ISNA(vlookup($A11, FFToolbox!$B$2:$E$618, 4, false)), 0, vlookup($A11, FFToolbox!$B$2:$E$618, 4, false)) -> 50 | J11: =Average(F11:I11) -> 39.75 | K11: =max(F11:I11)-min(F11:I11) -> 18
A12: Josh Jacobs | B12: Yes | C12: LV | D12: RB | E12: =vlookup(C12,'Team Bye List'!$A$1:$B$33,2,False) -> 6 | F12: =if(ISNA(vlookup($A12, ESPN!$B$2:$E$1010, 4, false)), 0, vlookup($A12, ESPN!$B$2:$E$1010, 4, false)) -> 49 | G12: =if(ISNA(vlookup($A12,'Ultimate Draft Kit'!$B$2:$E$261,4, false)), 0, vlookup($A12,'Ultimate Draft Kit'!$B$2:$E$261, 4, false)) -> 41 | H12: =if(ISNA(vlookup($A12, FantasyPro!$B$2:$E$514,4,false)),0,vlookup($A12,FantasyPro!$B$2:$E$514,4,false)) -> 34 | I12: =if(ISNA(vlookup($A12, FFToolbox!$B$2:$E$618, 4, false)), 0, vlookup($A12, FFToolbox!$B$2:$E$618, 4, false)) -> 32 | J12: =Average(F12:I12) -> 39 | K12: =max(F12:I12)-min(F12:I12) -> 17
A13: Patrick Mahomes | B13: Yes | C13: KC | D13: QB | E13: =vlookup(C13,'Team Bye List'!$A$1:$B$33,2,False) -> 10 | F13: =if(ISNA(vlookup($A13, ESPN!$B$2:$E$1010, 4, false)), 0, vlookup($A13, ESPN!$B$2:$E$1010, 4, false)) -> 57 | G13: =if(ISNA(vlookup($A13,'Ultimate Draft Kit'!$B$2:$E$261,4, false)), 0, vlookup($A13,'Ultimate Draft Kit'!$B$2:$E$261, 4, false)) -> 22 | H13: =if(ISNA(vlookup($A13, FantasyPro!$B$2:$E$514,4,false)),0,vlookup($A13,FantasyPro!$B$2:$E$514,4,false)) -> 28 | I13: =if(ISNA(vlookup($A13, FFToolbox!$B$2:$E$618, 4, false)), 0, vlookup($A13, FFToolbox!$B$2:$E$618, 4, false)) -> 46 | J13: =Average(F13:I13) -> 38.25 | K13: =max(F13:I13)-min(F13:I13) -> 35
... A367: Jason Sanders | B367: No | C367: MIA | D367: K | E367: =vlookup(C367,'Team Bye List'!$A$1:$B$33,2,False) -> 11 | F367: =if(ISNA(vlookup($A367, ESPN!$B$2:$E$1010, 4, false)), 0, vlookup($A367, ESPN!$B$2:$E$1010, 4, false)) -> 0 | G367: =if(ISNA(vlookup($A367,'Ultimate Draft Kit'!$B$2:$E$261,4, false)), 0, vlookup($A367,'Ultimate Draft Kit'!$B$2:$E$261, 4, false)) -> 0 | H367: =if(ISNA(vlookup($A367, FantasyPro!$B$2:$E$514,4,false)),0,vlookup($A367,FantasyPro!$B$2:$E$514,4,false)) -> 0 | I367: =if(ISNA(vlookup($A367, FFToolbox!$B$2:$E$618, 4, false)), 0, vlookup($A367, FFToolbox!$B$2:$E$618, 4, false)) -> 2 | J367: =Average(F367:I367) -> 0.5 | K367: =max(F367:I367)-min(F367:I367) -> 2
A368: Arizona Cardinals | B368: No | C368: ARI | D368: DST | E368: =vlookup(C368,'Team Bye List'!$A$1:$B$33,2,False) -> 8 | F368: =if(ISNA(vlookup($A368, ESPN!$B$2:$E$1010, 4, false)), 0, vlookup($A368, ESPN!$B$2:$E$1010, 4, false)) -> 1 | G368: =if(ISNA(vlookup($A368,'Ultimate Draft Kit'!$B$2:$E$201,4, false)), 0, vlookup($A368,'Ultimate Draft Kit'!$B$2:$E$201, 4, false)) -> 0 | H368: =if(ISNA(vlookup($A368, FantasyPro!$B$2:$E$514,4,false)),0,vlookup($A368,FantasyPro!$B$2:$E$514,4,false)) -> 0 | I368: =if(ISNA(vlookup($A368, FFToolbox!$B$2:$E$618, 4, false)), 0, vlookup($A368, FFToolbox!$B$2:$E$618, 4, false)) -> 0 | J368: =Average(F368:I368) -> 0.25 | K368: =max(F368:I368)-min(F368:I368) -> 1
A369: Atlanta Falcons | B369: No | C369: ATL | D369: DST | E369: =vlookup(C369,'Team Bye List'!$A$1:$B$33,2,False) -> 10 | F369: =if(ISNA(vlookup($A369, ESPN!$B$2:$E$1010, 4, false)), 0, vlookup($A369, ESPN!$B$2:$E$1010, 4, false)) -> 1 | G369: =if(ISNA(vlookup($A369,'Ultimate Draft Kit'!$B$2:$E$201,4, false)), 0, vlookup($A369,'Ultimate Draft Kit'!$B$2:$E$201, 4, false)) -> 0 | H369: =if(ISNA(vlookup($A369, FantasyPro!$B$2:$E$514,4,false)),0,vlookup($A369,FantasyPro!$B$2:$E$514,4,false)) -> 0 | I369: =if(ISNA(vlookup($A369, FFToolbox!$B$2:$E$618, 4, false)), 0, vlookup($A369, FFToolbox!$B$2:$E$618, 4, false)) -> 0 | J369: =Average(F369:I369) -> 0.25 | K369: =max(F369:I369)-min(F369:I369) -> 1
A370: Carolina Panthers | B370: No | C370: CAR | D370: DST | E370: =vlookup(C370,'Team Bye List'!$A$1:$B$33,2,False) -> 12 | F370: =if(ISNA(vlookup($A370, ESPN!$B$2:$E$1010, 4, false)), 0, vlookup($A370, ESPN!$B$2:$E$1010, 4, false)) -> 1 | G370: =if(ISNA(vlookup($A370,'Ultimate Draft Kit'!$B$2:$E$201,4, false)), 0, vlookup($A370,'Ultimate Draft Kit'!$B$2:$E$201, 4, false)) -> 0 | H370: =if(ISNA(vlookup($A370, FantasyPro!$B$2:$E$514,4,false)),0,vlookup($A370,FantasyPro!$B$2:$E$514,4,false)) -> 0 | I370: =if(ISNA(vlookup($A370, FFToolbox!$B$2:$E$618, 4, false)), 0, vlookup($A370, FFToolbox!$B$2:$E$618, 4, false)) -> 0 | J370: =Average(F370:I370) -> 0.25 | K370: =max(F370:I370)-min(F370:I370) -> 1
A371: Cincinnati Bengals | B371: No | C371: CIN | D371: DST | E371: =vlookup(C371,'Team Bye List'!$A$1:$B$33,2,False) -> 9 | F371: =if(ISNA(vlookup($A371, ESPN!$B$2:$E$1010, 4, false)), 0, vlookup($A371, ESPN!$B$2:$E$1010, 4, false)) -> 1 | G371: =if(ISNA(vlookup($A371,'Ultimate Draft Kit'!$B$2:$E$201,4, false)), 0, vlookup($A371,'Ultimate Draft Kit'!$B$2:$E$201, 4, false)) -> 0 | H371: =if(ISNA(vlookup($A371, FantasyPro!$B$2:$E$514,4,false)),0,vlookup($A371,FantasyPro!$B$2:$E$514,4,false)) -> 0 | I371: =if(ISNA(vlookup($A371, FFToolbox!$B$2:$E$618, 4, false)), 0, vlookup($A371, FFToolbox!$B$2:$E$618, 4, false)) -> 0 | J371: =Average(F371:I371) -> 0.25 | K371: =max(F371:I371)-min(F371:I371) -> 1
A372: Cleveland Browns | B372: No | C372: CLE | D372: DST | E372: =vlookup(C372,'Team Bye List'!$A$1:$B$33,2,False) -> 9 | F372: =if(ISNA(vlookup($A372, ESPN!$B$2:$E$1010, 4, false)), 0, vlookup($A372, ESPN!$B$2:$E$1010, 4, false)) -> 1 | G372: =if(ISNA(vlookup($A372,'Ultimate Draft Kit'!$B$2:$E$201,4, false)), 0, vlookup($A372,'Ultimate Draft Kit'!$B$2:$E$201, 4, false)) -> 0 | H372: =if(ISNA(vlookup($A372, FantasyPro!$B$2:$E$514,4,false)),0,vlookup($A372,FantasyPro!$B$2:$E$514,4,false)) -> 0 | I372: =if(ISNA(vlookup($A372, FFToolbox!$B$2:$E$618, 4, false)), 0, vlookup($A372, FFToolbox!$B$2:$E$618, 4, false)) -> 0 | J372: =Average(F372:I372) -> 0.25 | K372: =max(F372:I372)-min(F372:I372) -> 1
A373: Dallas Cowboys | B373: No | C373: DAL | D373: DST | E373: =vlookup(C373,'Team Bye List'!$A$1:$B$33,2,False) -> 10 | F373: =if(ISNA(vlookup($A373, ESPN!$B$2:$E$1010, 4, false)), 0, vlookup($A373, ESPN!$B$2:$E$1010, 4, false)) -> 1 | G373: =if(ISNA(vlookup($A373,'Ultimate Draft Kit'!$B$2:$E$201,4, false)), 0, vlookup($A373,'Ultimate Draft Kit'!$B$2:$E$201, 4, false)) -> 0 | H373: =if(ISNA(vlookup($A373, FantasyPro!$B$2:$E$514,4,false)),0,vlookup($A373,FantasyPro!$B$2:$E$514,4,false)) -> 0 | I373: =if(ISNA(vlookup($A373, FFToolbox!$B$2:$E$618, 4, false)), 0, vlookup($A373, FFToolbox!$B$2:$E$618, 4, false)) -> 0 | J373: =Average(F373:I373) -> 0.25 | K373: =max(F373:I373)-min(F373:I373) -> 1
A374: Denver Broncos | B374: No | C374: DEN | D374: DST | E374: =vlookup(C374,'Team Bye List'!$A$1:$B$33,2,False) -> 8 | F374: =if(ISNA(vlookup($A374, ESPN!$B$2:$E$1010, 4, false)), 0, vlookup($A374, ESPN!$B$2:$E$1010, 4, false)) -> 1 | G374: =if(ISNA(vlookup($A374,'Ultimate Draft Kit'!$B$2:$E$201,4, false)), 0, vlookup($A374,'Ultimate Draft Kit'!$B$2:$E$201, 4, false)) -> 0 | H374: =if(ISNA(vlookup($A374, FantasyPro!$B$2:$E$514,4,false)),0,vlookup($A374,FantasyPro!$B$2:$E$514,4,false)) -> 0 | I374: =if(ISNA(vlookup($A374, FFToolbox!$B$2:$E$618, 4, false)), 0, vlookup($A374, FFToolbox!$B$2:$E$618, 4, false)) -> 0 | J374: =Average(F374:I374) -> 0.25 | K374: =max(F374:I374)-min(F374:I374) -> 1
A375: Detroit Lions | B375: No | C375: DET | D375: DST | E375: =vlookup(C375,'Team Bye List'!$A$1:$B$33,2,False) -> 5 | F375: =if(ISNA(vlookup($A375, ESPN!$B$2:$E$1010, 4, false)), 0, vlookup($A375, ESPN!$B$2:$E$1010, 4, false)) -> 1 | G375: =if(ISNA(vlookup($A375,'Ultimate Draft Kit'!$B$2:$E$201,4, false)), 0, vlookup($A375,'Ultimate Draft Kit'!$B$2:$E$201, 4, false)) -> 0 | H375: =if(ISNA(vlookup($A375, FantasyPro!$B$2:$E$514,4,false)),0,vlookup($A375,FantasyPro!$B$2:$E$514,4,false)) -> 0 | I375: =if(ISNA(vlookup($A375, FFToolbox!$B$2:$E$618, 4, false)), 0, vlookup($A375, FFToolbox!$B$2:$E$618, 4, false)) -> 0 | J375: =Average(F375:I375) -> 0.25 | K375: =max(F375:I375)-min(F375:I375) -> 1
A376: Green Bay Packers | B376: No | C376: GB | D376: DST | E376: =vlookup(C376,'Team Bye List'!$A$1:$B$33,2,False) -> 5 | F376: =if(ISNA(vlookup($A376, ESPN!$B$2:$E$1010, 4, false)), 0, vlookup($A376, ESPN!$B$2:$E$1010, 4, false)) -> 1 | G376: =if(ISNA(vlookup($A376,'Ultimate Draft Kit'!$B$2:$E$201,4, false)), 0, vlookup($A376,'Ultimate Draft Kit'!$B$2:$E$201, 4, false)) -> 0 | H376: =if(ISNA(vlookup($A376, FantasyPro!$B$2:$E$514,4,false)),0,vlookup($A376,FantasyPro!$B$2:$E$514,4,false)) -> 0 | I376: =if(ISNA(vlookup($A376, FFToolbox!$B$2:$E$618, 4, false)), 0, vlookup($A376, FFToolbox!$B$2:$E$618, 4, false)) -> 0 | J376: =Average(F376:I376) -> 0.25 | K376: =max(F376:I376)-min(F376:I376) -> 1
A377: Houston Texans | B377: No | C377: HOU | D377: DST | E377: =vlookup(C377,'Team Bye List'!$A$1:$B$33,2,False) -> 8 | F377: =if(ISNA(vlookup($A377, ESPN!$B$2:$E$1010, 4, false)), 0, vlookup($A377, ESPN!$B$2:$E$1010, 4, false)) -> 1 | G377: =if(ISNA(vlookup($A377,'Ultimate Draft Kit'!$B$2:$E$201,4, false)), 0, vlookup($A377,'Ultimate Draft Kit'!$B$2:$E$201, 4, false)) -> 0 | H377: =if(ISNA(vlookup($A377, FantasyPro!$B$2:$E$514,4,false)),0,vlookup($A377,FantasyPro!$B$2:$E$514,4,false)) -> 0 | I377: =if(ISNA(vlookup($A377, FFToolbox!$B$2:$E$618, 4, false)), 0, vlookup($A377, FFToolbox!$B$2:$E$618, 4, false)) -> 0 | J377: =Average(F377:I377) -> 0.25 | K377: =max(F377:I377)-min(F377:I377) -> 1
A378: Indianapolis Colts | B378: Yes | C378: IND | D378: DST | E378: =vlookup(C378,'Team Bye List'!$A$1:$B$33,2,False) -> 7 | F378: =if(ISNA(vlookup($A378, ESPN!$B$2:$E$1010, 4, false)), 0, vlookup($A378, ESPN!$B$2:$E$1010, 4, false)) -> 1 | G378: =if(ISNA(vlookup($A378,'Ultimate Draft Kit'!$B$2:$E$201,4, false)), 0, vlookup($A378,'Ultimate Draft Kit'!$B$2:$E$201, 4, false)) -> 0 | H378: =if(ISNA(vlookup($A378, FantasyPro!$B$2:$E$514,4,false)),0,vlookup($A378,FantasyPro!$B$2:$E$514,4,false)) -> 0 | I378: =if(ISNA(vlookup($A378, FFToolbox!$B$2:$E$618, 4, false)), 0, vlookup($A378, FFToolbox!$B$2:$E$618, 4, false)) -> 0 | J378: =Average(F378:I378) -> 0.25 | K378: =max(F378:I378)-min(F378:I378) -> 1
A379: Jacksonville Jaguars | B379: No | C379: JAC | D379: DST | E379: =vlookup(C379,'Team Bye List'!$A$1:$B$33,2,False) -> 7 | F379: =if(ISNA(vlookup($A379, ESPN!$B$2:$E$1010, 4, false)), 0, vlookup($A379, ESPN!$B$2:$E$1010, 4, false)) -> 1 | G379: =if(ISNA(vlookup($A379,'Ultimate Draft Kit'!$B$2:$E$201,4, false)), 0, vlookup($A379,'Ultimate Draft Kit'!$B$2:$E$201, 4, false)) -> 0 | H379: =if(ISNA(vlookup($A379, FantasyPro!$B$2:$E$514,4,false)),0,vlookup($A379,FantasyPro!$B$2:$E$514,4,false)) -> 0 | I379: =if(ISNA(vlookup($A379, FFToolbox!$B$2:$E$618, 4, false)), 0, vlookup($A379, FFToolbox!$B$2:$E$618, 4, false)) -> 0 | J379: =Average(F379:I379) -> 0.25 | K379: =max(F379:I379)-min(F379:I379) -> 1
... A1010: Stephen Gostkowski | B1010: No | C1010: FA | D1010: K | E1010: =vlookup(C1010,'Team Bye List'!$A$1:$B$33,2,False) -> #N/A | F1010: =if(ISNA(vlookup($A1010, ESPN!$B$2:$E$1010, 4, false)), 0, vlookup($A1010, ESPN!$B$2:$E$1010, 4, false)) -> 0 | G1010: =if(ISNA(vlookup($A1010,'Ultimate Draft Kit'!$B$2:$E$201,4, false)), 0, vlookup($A1010,'Ultimate Draft Kit'!$B$2:$E$201, 4, false)) -> 0 | H1010: =if(ISNA(vlookup($A1010, FantasyPro!$B$2:$E$514,4,false)),0,vlookup($A1010,FantasyPro!$B$2:$E$514,4,false)) -> 0 | I1010: =if(ISNA(vlookup($A1010, FFToolbox!$B$2:$E$618, 4, false)), 0, vlookup($A1010, FFToolbox!$B$2:$E$618, 4, false)) -> 0 | J1010: =Average(F1010:I1010) -> 0 | K1010: =max(F1010:I1010)-min(F1010:I1010) -> 0

Sheet Players We Want
A1: Name | B1: Team | C1: Position | D1: Bye Week | E1: Keeper Price | F1: Start Bid | G1: Avg Price | H1: Max Bid | L1: =200-L19 -> 1
A2: Tyreek Hill | B2: =vlookup(A2,Masterview!A$2:K$994, 3, False) -> KC | C2: =vlookup(A2,Masterview!A$2:K$994, 4, False) -> WR | D2: =vlookup(A2,Masterview!A$2:K$994,5, False) -> 10 | G2: =vlookup(A2,Masterview!A$2:K$994, 10, False) -> 38 | H2: 35 | J2: Position | K2: Name | L2: Amount
A3: Harrison Butker | B3: =vlookup(A3,Masterview!A$2:K$994, 3, False) -> KC | C3: =vlookup(A3,Masterview!A$2:K$994, 4, False) -> K | D3: =vlookup(A3,Masterview!A$2:K$994,5, False) -> 10 | G3: =vlookup(A3,Masterview!A$2:K$994, 10, False) -> 2 | H3: 2 | J3: QB1 | K3: Deshaun Watson | L3: 18
A4: Wil Lutz | B4: =vlookup(A4,Masterview!A$2:K$994, 3, False) -> NO | C4: =vlookup(A4,Masterview!A$2:K$994, 4, False) -> K | D4: =vlookup(A4,Masterview!A$2:K$994,5, False) -> 6 | G4: =vlookup(A4,Masterview!A$2:K$994, 10, False) -> 2 | H4: 2 | J4: RB1 | K4: Christian McCaffrey | L4: 54
A5: Baltimore Ravens | B5: =vlookup(A5,Masterview!A$2:K$994, 3, False) -> BAL | C5: =vlookup(A5,Masterview!A$2:K$994, 4, False) -> DST | D5: =vlookup(A5,Masterview!A$2:K$994,5, False) -> 8 | G5: =vlookup(A5,Masterview!A$2:K$994, 10, False) -> 0.5 | H5: 2 | J5: WR1 | K5: Calvin Ridley | L5: 22
A6: Kansas City Chiefs | B6: =vlookup(A6,Masterview!A$2:K$994, 3, False) -> KC | C6: =vlookup(A6,Masterview!A$2:K$994, 4, False) -> DST | D6: =vlookup(A6,Masterview!A$2:K$994,5, False) -> 10 | G6: =vlookup(A6,Masterview!A$2:K$994, 10, False) -> 0.5 | H6: 2 | J6: WR2 | K6: DK Metcalf | L6: 17
A7: Chicago Bears | B7: =vlookup(A7,Masterview!A$2:K$994, 3, False) -> CHI | C7: =vlookup(A7,Masterview!A$2:K$994, 4, False) -> DST | D7: =vlookup(A7,Masterview!A$2:K$994,5, False) -> 11 | G7: =vlookup(A7,Masterview!A$2:K$994, 10, False) -> 0.5 | H7: 2 | J7: TE | K7: George Kittle | L7: 26
A8: DeAndre Hopkins | B8: =vlookup(A8,Masterview!A$2:K$994, 3, False) -> ARI | C8: =vlookup(A8,Masterview!A$2:K$994, 4, False) -> WR | D8: =vlookup(A8,Masterview!A$2:K$994,5, False) -> 8 | G8: =vlookup(A8,Masterview!A$2:K$994, 10, False) -> 34 | H8: 30 | J8: RB2 | K8: Raheem Mostert | L8: 10
A9: A.J. Green | B9: =vlookup(A9,Masterview!A$2:K$994, 3, False) -> CIN | C9: =vlookup(A9,Masterview!A$2:K$994, 4, False) -> WR | D9: =vlookup(A9,Masterview!A$2:K$994,5, False) -> 9 | G9: =vlookup(A9,Masterview!A$2:K$994, 10, False) -> 15 | H9: 15 | J9: D/ST | K9: Ravens | L9: 2
A10: T.Y. Hilton | B10: =vlookup(A10,Masterview!A$2:K$994, 3, False) -> IND | C10: =vlookup(A10,Masterview!A$2:K$994, 4, False) -> WR | D10: =vlookup(A10,Masterview!A$2:K$994,5, False) -> 7 | G10: =vlookup(A10,Masterview!A$2:K$994, 10, False) -> 20.25 | H10: 20 | J10: K | K10: Matt Prater | L10: 4
A11: Philip Rivers | B11: =vlookup(A11,Masterview!A$2:K$994, 3, False) -> IND | C11: =vlookup(A11,Masterview!A$2:K$994, 4, False) -> QB | D11: =vlookup(A11,Masterview!A$2:K$994,5, False) -> 7 | G11: =vlookup(A11,Masterview!A$2:K$994, 10, False) -> 4 | H11: 4 | J11: WR3 | K11: Brandin Cooks | L11: 7
A12: Matthew Stafford | B12: =vlookup(A12,Masterview!A$2:K$994, 3, False) -> DET | C12: =vlookup(A12,Masterview!A$2:K$994, 4, False) -> QB | D12: =vlookup(A12,Masterview!A$2:K$994,5, False) -> 5 | G12: =vlookup(A12,Masterview!A$2:K$994, 10, False) -> 9 | H12: 5 | J12: WR4 | K12: Jarvis landry | L12: 10
A13: Hayden Hurst | B13: =vlookup(A13,Masterview!A$2:K$994, 3, False) -> ATL | C13: =vlookup(A13,Masterview!A$2:K$994, 4, False) -> TE | D13: =vlookup(A13,Masterview!A$2:K$994,5, False) -> 10 | G13: =vlookup(A13,Masterview!A$2:K$994, 10, False) -> 8 | H13: 6 | J13: QB2 | K13: Drew Brees | L13: 7
A14: Antonio Gibson | B14: =vlookup(A14,Masterview!A$2:K$994, 3, False) -> WAS | C14: =vlookup(A14,Masterview!A$2:K$994, 4, False) -> RB | D14: =vlookup(A14,Masterview!A$2:K$994,5, False) -> 8 | G14: =vlookup(A14,Masterview!A$2:K$994, 10, False) -> 6 | H14: 6 | J14: RB3 | K14: Jordan Howard | L14: 7
A15: Mark Ingram II | B15: =vlookup(A15,Masterview!A$2:K$994, 3, False) -> BAL | C15: =vlookup(A15,Masterview!A$2:K$994, 4, False) -> RB | D15: =vlookup(A15,Masterview!A$2:K$994,5, False) -> 8 | G15: =vlookup(A15,Masterview!A$2:K$994, 10, False) -> 19.5 | H15: 15 | J15: WR5 | K15: Bryan Edwards | L15: 2
B16: =vlookup(A16,Masterview!A$2:K$994, 3, False) -> #N/A | C16: =vlookup(A16,Masterview!A$2:K$994, 4, False) -> #N/A | D16: =vlookup(A16,Masterview!A$2:K$994,5, False) -> #N/A | G16: =vlookup(A16,Masterview!A$2:K$994, 10, False) -> #N/A | J16: TE2 | K16: Gronk | L16: 4
B17: =vlookup(A17,Masterview!A$2:K$994, 3, False) -> #N/A | C17: =vlookup(A17,Masterview!A$2:K$994, 4, False) -> #N/A | D17: =vlookup(A17,Masterview!A$2:K$994,5, False) -> #N/A | G17: =vlookup(A17,Masterview!A$2:K$994, 10, False) -> #N/A | J17: DST | K17: Bears | L17: 1
B18: =vlookup(A18,Masterview!A$2:K$994, 3, False) -> #N/A | C18: =vlookup(A18,Masterview!A$2:K$994, 4, False) -> #N/A | D18: =vlookup(A18,Masterview!A$2:K$994,5, False) -> #N/A | G18: =vlookup(A18,Masterview!A$2:K$994, 10, False) -> #N/A | J18: WR6 | K18: Marvin Jones | L18: 8
B19: =vlookup(A19,Masterview!A$2:K$994, 3, False) -> #N/A | C19: =vlookup(A19,Masterview!A$2:K$994, 4, False) -> #N/A | D19: =vlookup(A19,Masterview!A$2:K$994,5, False) -> #N/A | G19: =vlookup(A19,Masterview!A$2:K$994, 10, False) -> #N/A | L19: =sum(L3:L18) -> 199
B20: =vlookup(A20,Masterview!A$2:K$994, 3, False) -> #N/A | C20: =vlookup(A20,Masterview!A$2:K$994, 4, False) -> #N/A | D20: =vlookup(A20,Masterview!A$2:K$994,5, False) -> #N/A | G20: =vlookup(A20,Masterview!A$2:K$994, 10, False) -> #N/A
B21: =vlookup(A21,Masterview!A$2:K$994, 3, False) -> #N/A | C21: =vlookup(A21,Masterview!A$2:K$994, 4, False) -> #N/A | D21: =vlookup(A21,Masterview!A$2:K$994,5, False) -> #N/A | G21: =vlookup(A21,Masterview!A$2:K$994, 10, False) -> #N/A
B22: =vlookup(A22,Masterview!A$2:K$994, 3, False) -> #N/A | C22: =vlookup(A22,Masterview!A$2:K$994, 4, False) -> #N/A | D22: =vlookup(A22,Masterview!A$2:K$994,5, False) -> #N/A | G22: =vlookup(A22,Masterview!A$2:K$994, 10, False) -> #N/A
B23: =vlookup(A23,Masterview!A$2:K$994, 3, False) -> #N/A | C23: =vlookup(A23,Masterview!A$2:K$994, 4, False) -> #N/A | D23: =vlookup(A23,Masterview!A$2:K$994,5, False) -> #N/A | G23: =vlookup(A23,Masterview!A$2:K$994, 10, False) -> #N/A
B24: =vlookup(A24,Masterview!A$2:K$994, 3, False) -> #N/A | C24: =vlookup(A24,Masterview!A$2:K$994, 4, False) -> #N/A | D24: =vlookup(A24,Masterview!A$2:K$994,5, False) -> #N/A | G24: =vlookup(A24,Masterview!A$2:K$994, 10, False) -> #N/A
B25: =vlookup(A25,Masterview!A$2:K$994, 3, False) -> #N/A | C25: =vlookup(A25,Masterview!A$2:K$994, 4, False) -> #N/A | D25: =vlookup(A25,Masterview!A$2:K$994,5, False) -> #N/A | G25: =vlookup(A25,Masterview!A$2:K$994, 10, False) -> #N/A
B26: =vlookup(A26,Masterview!A$2:K$994, 3, False) -> #N/A | C26: =vlookup(A26,Masterview!A$2:K$994, 4, False) -> #N/A | D26: =vlookup(A26,Masterview!A$2:K$994,5, False) -> #N/A | G26: =vlookup(A26,Masterview!A$2:K$994, 10, False) -> #N/A
B27: =vlookup(A27,Masterview!A$2:K$994, 3, False) -> #N/A | C27: =vlookup(A27,Masterview!A$2:K$994, 4, False) -> #N/A | D27: =vlookup(A27,Masterview!A$2:K$994,5, False) -> #N/A | G27: =vlookup(A27,Masterview!A$2:K$994, 10, False) -> #N/A
B28: =vlookup(A28,Masterview!A$2:K$994, 3, False) -> #N/A | C28: =vlookup(A28,Masterview!A$2:K$994, 4, False) -> #N/A | D28: =vlookup(A28,Masterview!A$2:K$994,5, False) -> #N/A | G28: =vlookup(A28,Masterview!A$2:K$994, 10, False) -> #N/A
B29: =vlookup(A29,Masterview!A$2:K$994, 3, False) -> #N/A | C29: =vlookup(A29,Masterview!A$2:K$994, 4, False) -> #N/A | D29: =vlookup(A29,Masterview!A$2:K$994,5, False) -> #N/A | G29: =vlookup(A29,Masterview!A$2:K$994, 10, False) -> #N/A
B30: =vlookup(A30,Masterview!A$2:K$994, 3, False) -> #N/A | C30: =vlookup(A30,Masterview!A$2:K$994, 4, False) -> #N/A | D30: =vlookup(A30,Masterview!A$2:K$994,5, False) -> #N/A | G30: =vlookup(A30,Masterview!A$2:K$994, 10, False) -> #N/A
B31: =vlookup(A31,Masterview!A$2:K$994, 3, False) -> #N/A | C31: =vlookup(A31,Masterview!A$2:K$994, 4, False) -> #N/A | D31: =vlookup(A31,Masterview!A$2:K$994,5, False) -> #N/A | G31: =vlookup(A31,Masterview!A$2:K$994, 10, False) -> #N/A

Sheet Team Bye List
A1: Team | B1: Bye Week
A2: ARI | B2: 8
A3: ATL | B3: 10
A4: BAL | B4: 8
A5: BUF | B5: 11
A6: CAR | B6: 12
A7: CHI | B7: 11
A8: CIN | B8: 9
A9: CLE | B9: 9
A10: DAL | B10: 10
A11: DEN | B11: 8
A12: DET | B12: 5
A13: GB | B13: 5
... A33: WAS | B33: 8

Sheet Keepers

Sheet Player Name
A1: Name | B1: Team | C1: Pos | D1: Bye Week
A2: A.J. Brown | B2: TEN | C2: WR | D2: 7
A3: A.J. Derby | B3: FA | C3: TE
A4: A.J. Green | B4: CIN | C4: WR | D4: 9
A5: Aaron Jones | B5: GB | C5: RB | D5: 5
A6: Aaron Rodgers | B6: GB | C6: QB | D6: 5
A7: Adam Humphries | B7: TEN | C7: WR | D7: 7
A8: Adam Shaheen | B8: CHI | C8: TE | D8: 11
A9: Adam Thielen | B9: MIN | C9: WR | D9: 7
A10: Adam Trautman | B10: NO | C10: TE | D10: 6
A11: Adam Vinatieri | B11: FA | C11: K
A12: Adrian Peterson | B12: WAS | C12: RB | D12: 8
A13: AJ Dillon | B13: GB | C13: RB | D13: 5
A14: AJ McCarron | B14: HOU | C14: QB | D14: 8
A15: Akrum Wadley | B15: FA | C15: RB
A16: Alan Cross | B16: FA | C16: TE
A17: Albert Okwuegbunam | B17: DEN | C17: TE | D17: 8
A18: Albert Wilson | B18: MIA | C18: WR | D18: 11
A19: Aldrick Robinson | B19: FA | C19: WR
A20: Aldrick Robinson | B20: FA | C20: WR
A21: Aldrick Rosas | B21: NYG | C21: K | D21: 11
A22: Alec Ingold | B22: LV | C22: RB | D22: 6
A23: Alex Armah | B23: CAR | C23: RB | D23: 12
A24: Alex Collins | B24: FA | C24: RB
A25: Alex Ellis | B25: PHI | C25: TE | D25: 9
A26: Alex Erickson | B26: CIN | C26: WR | D26: 9
A27: Alex McGough | B27: HOU | C27: QB | D27: 8
A28: Alex Smith | B28: WAS | C28: QB | D28: 8
A29: Alex Tanney | B29: NYG | C29: QB | D29: 11
A30: Alexander Hollins | B30: MIN | C30: WR | D30: 7
A31: Alexander Mattison | B31: MIN | C31: RB | D31: 7
A32: Alfred Blue | B32: FA | C32: RB
A33: Alize Mack | B33: FA | C33: TE
A34: Allen Hurns | B34: MIA | C34: WR | D34: 11
A35: Allen Lazard | B35: GB | C35: WR | D35: 5
A36: Allen Robinson | B36: CHI | C36: WR | D36: 11
A37: Alonzo Russell | B37: FA | C37: WR
A38: Alshon Jeffery | B38: PHI | C38: WR | D38: 9
A39: Alvin Kamara | B39: NO | C39: RB | D39: 6
A40: Amara Darboh | B40: PIT | C40: WR | D40: 8
...
