Workbook

Sheet ESPN
A1: Rank | B1: Name | C1: Team | D1: Position | E1: Value | G1: Last Updated: 8/18/22
A2: 1 | B2: Jonathan Taylor | C2: IND | D2: RB | E2: 61
A3: 2 | B3: Christian McCaffrey | C3: CAR | D3: RB | E3: 59
A4: 3 | B4: Cooper Kupp | C4: LAR | D4: WR | E4: 59
A5: 4 | B5: Austin Ekeler | C5: LAC | D5: RB | E5: 58
A6: 5 | B6: Justin Jefferson | C6: MIN | D6: WR | E6: 55
A7: 6 | B7: Ja'Marr Chase | C7: CIN | D7: WR | E7: 54
A8: 7 | B8: Derrick Henry | C8: TEN | D8: RB | E8: 52
A9: 8 | B9: Najee Harris | C9: PIT | D9: RB | E9: 50
A10: 9 | B10: Davante Adams | C10: LV | D10: WR | E10: 49
A11: 10 | B11: Dalvin Cook | C11: MIN | D11: RB | E11: 46
A12: 11 | B12: Deebo Samuel | C12: SF | D12: WR | E12: 45
A13: 12 | B13: Stefon Diggs | C13: BUF | D13: WR | E13: 44
... A297: 296 | B297: Houston Texans | C297: HOU | D297: DST | E297: 0

Sheet FantasyPro
A1: Rank | B1: Name | C1: Team | D1: Position | E1: Value | G1: Last Updated: 8/18/22
A2: 1 | B2: Jonathan Taylor | C2: IND | D2: RB | E2: 76
A3: 2 | B3: Christian McCaffrey | C3: CAR | D3: RB | E3: 64
A4: 3 | B4: Austin Ekeler | C4: LAC | D4: RB | E4: 63
A5: 4 | B5: Dalvin Cook | C5: MIN | D5: RB | E5: 58
A6: 5 | B6: Justin Jefferson | C6: MIN | D6: WR | E6: 56
A7: 6 | B7: Derrick Henry | C7: TEN | D7: RB | E7: 51
A8: 7 | B8: Cooper Kupp | C8: LAR | D8: WR | E8: 50
A9: 8 | B9: Najee Harris | C9: PIT | D9: RB | E9: 45
A10: 9 | B10: Ja'Marr Chase | C10: CIN | D10: WR | E10: 44
A11: 10 | B11: Joe Mixon | C11: CIN | D11: RB | E11: 43
A12: 11 | B12: Stefon Diggs | C12: BUF | D12: WR | E12: 41
A13: 12 | B13: D'Andre Swift | C13: DET | D13: RB | E13: 40
... A773: 772 | B773: Houston Texans | C773: HOU | D773: DST | E773: 0

Sheet FFToolbox
A1: Rank | B1: Name | C1: Team | D1: Position | E1: Value | G1: Last Updated: 8/18/22
A2: 1 | B2: Jonathan Taylor | C2: IND | D2: RB | E2: 62
A3: 2 | B3: Christian McCaffrey | C3: CAR | D3: RB | E3: 60
A4: 3 | B4: Justin Jefferson | C4: MIN | D4: WR | E4: 59
A5: 4 | B5: Cooper Kupp | C5: LAR | D5: WR | E5: 54
A6: 5 | B6: Ja'Marr Chase | C6: CIN | D6: WR | E6: 48
A7: 7 | B7: Austin Ekeler | C7: LAC | D7: RB | E7: 47
A8: 6 | B8: Stefon Diggs | C8: BUF | D8: WR | E8: 44
A9: 8 | B9: D'Andre Swift | C9: DET | D9: RB | E9: 43
A10: 9 | B10: Davante Adams | C10: LVR | D10: WR | E10: 43
A11: 10 | B11: Dalvin Cook | C11: MIN | D11: RB | E11: 42
A12: 10.933333 | B12: Najee Harris | C12: PIT | D12: RB | E12: 41
A13: 11.921212 | B13: CeeDee Lamb | C13: DAL | D13: WR | E13: 41
... A414: 408.06061 | B414: Irv Smith | C414: MIN | D414: TE | E414: 0

Sheet Rotowire
A1: Rank | B1: Name | C1: Team | D1: Position | E1: Value | G1: Last Updated: 8/14/22
A2: 1 | B2: Josh Allen | C2: BUF | D2: QB | E2: 95
A3: 2 | B3: Jonathan Taylor | C3: IND | D3: RB | E3: 91
A4: 3 | B4: Patrick Mahomes | C4: KC | D4: QB | E4: 77
A5: 4 | B5: Cooper Kupp | C5: LAR | D5: WR | E5: 62
A6: 5 | B6: Deebo Samuel | C6: SF | D6: WR | E6: 61
A7: 6 | B7: Justin Herbert | C7: LAC | D7: QB | E7: 60
A8: 7 | B8: Derrick Henry | C8: TEN | D8: RB | E8: 58
A9: 8 | B9: Ja'Marr Chase | C9: CIN | D9: WR | E9: 58
A10: 9 | B10: Austin Ekeler | C10: LAC | D10: RB | E10: 58
A11: 10 | B11: Justin Jefferson | C11: MIN | D11: WR | E11: 56
A12: 11 | B12: Mark Andrews | C12: BAL | D12: TE | E12: 56
A13: 12 | B13: Travis Kelce | C13: KC | D13: TE | E13: 54
... A1076: 1075 | B1076: Anthony Gordon | C1076: KC | D1076: QB | E1076: 0

Sheet Ultimate Draft Kit
A1: Rank | B1: Name | C1: Team | D1: Position | E1: Value | G1: Last Updated: 8/18/22
A2: 1 | B2: Cooper Kupp | C2: LAR | D2: WR | E2: 70
A3: 2 | B3: Justin Jefferson | C3: MIN | D3: WR | E3: 69
A4: 3 | B4: Jonathan Taylor | C4: IND | D4: RB | E4: 67
A5: 4 | B5: Christian McCaffrey | C5: CAR | D5: RB | E5: 58
A6: 5 | B6: Josh Allen | C6: BUF | D6: QB | E6: 55
A7: 6 | B7: Austin Ekeler | C7: LAC | D7: RB | E7: 47
A8: 7 | B8: Justin Herbert | C8: LAC | D8: QB | E8: 45
A9: 8 | B9: Stefon Diggs | C9: BUF | D9: WR | E9: 45
A10: 9 | B10: Ja'Marr Chase | C10: CIN | D10: WR | E10: 44
A11: 10 | B11: Davante Adams | C11: LV | D11: WR | E11: 44
A12: 11 | B12: Derrick Henry | C12: TEN | D12: RB | E12: 43
A13: 12 | B13: Jalen Hurts | C13: PHI | D13: QB | E13: 39
... A325: 324 | B325: Ka'imi Fairbairn | C325: HOU | D325: K | E325: 1

Sheet Sleeper
A1: Rank | B1: Name | C1: Team | D1: Position | E1: Value | G1: Last Updated: 8/18/22
A2: 1 | B2: Jonathan Taylor | C2: IND | D2: RB | E2: 78
A3: 2 | B3: Christian McCaffrey | C3: CAR | D3: RB | E3: 64
A4: 3 | B4: Derrick Henry | C4: TEN | D4: RB | E4: 61
A5: 4 | B5: Dalvin Cook | C5: MIN | D5: RB | E5: 58
A6: 5 | B6: Austin Ekeler | C6: LAC | D6: RB | E6: 57
A7: 6 | B7: Joe Mixon | C7: CIN | D7: RB | E7: 56
A8: 7 | B8: Justin Jefferson | C8: MIN | D8: WR | E8: 54
A9: 8 | B9: Najee Harris | C9: PIT | D9: RB | E9: 54
A10: 9 | B10: Cooper Kupp | C10: LAR | D10: WR | E10: 52
A11: 10 | B11: Ja'Marr Chase | C11: CIN | D11: WR | E11: 46
A12: 11 | B12: Travis Kelce | C12: KC | D12: TE | E12: 45
A13: 12 | B13: James Conner | C13: ARI | D13: RB | E13: 45
... A155: 154 | B155: Joey Slye | C155: WAS | D155: K | E155: 1
A156: 155 | B156: Aldrick Rosas | D156: K | E156: 1
A157: 156 | B157: Greg Zuerlein | C157: NYJ | D157: K | E157: 1
A158: 157 | B158: Randy Bullock | C158: TEN | D158: K | E158: 1
A159: 158 | B159: Ryan Santoso | C159: JAX | D159: K | E159: 1
A160: 159 | B160: Jason Myers | C160: SEA | D160: K | E160: 1
A161: 160 | B161: Cairo Santos | C161: CHI | D161: K | E161: 1
A162: 161 | B162: Graham Gano | C162: NYG | D162: K | E162: 1
A163: 162 | B163: Zane Gonzalez | C163: CAR | D163: K | E163: 1
A164: 163 | B164: Chris Boswell | C164: PIT | D164: K | E164: 1
A165: 164 | B165: Ka'imi Fairbairn | C165: HOU | D165: K | E165: 1
A166: 165 | B166: Denver Broncos | C166: DEN | D166: DST | E166: 1
A167: 166 | B167: Los Angeles Chargers | C167: LAC | D167: DST | E167: 1
A168: 167 | B168: New York Giants | C168: NYG | D168: DST | E168: 1
... A330: 329 | B330: Jacoby Brissett | C330: CLE | D330: QB | E330: 1

Sheet Masterview
A1: Name | B1: JAK | C1: Tier | D1: Team | E1: Pos | F1: Bye Week | G1: Sleeper | H1: ESPN | I1: UDK | J1: Rotowire | K1: FantasyPro | L1: FFToolbox | M1: Avg Going Rate | N1: Variation
A2: Jonathan Taylor | B2: Yes | C2: 1 | D2: IND | E2: RB | F2: =vlookup(D2,'Team Bye List'!$A$1:$B$33,2,False) -> 14 | G2: =if(ISNA(vlookup($A2, Sleeper!$B$2:$E$330, 4, false)), 0, vlookup($A2, Sleeper!$B$2:$E$330, 4, false)) -> 78 | H2: =if(ISNA(vlookup($A2, ESPN!$B$2:$E$297, 4, false)), 0, vlookup($A2, ESPN!$B$2:$E$297, 4, false)) -> 61 | I2: =if(ISNA(vlookup($A2,'Ultimate Draft Kit'!$B$2:$E$324,4, false)), 0, vlookup($A2,'Ultimate Draft Kit'!$B$2:$E$324, 4, false)) -> 67 | J2: =if(ISNA(vlookup($A2,Rotowire!$B$2:$E$1075,4, false)), 0, vlookup($A2,Rotowire!$B$2:$E$1075, 4, false)) -> 91 | K2: =if(ISNA(vlookup($A2, FantasyPro!$B$2:$E$341,4,false)),0,vlookup($A2,FantasyPro!$B$2:$E$341,4,false)) -> 76 | L2: =if(ISNA(vlookup($A2, FFToolbox!$B$2:$E$414, 4, false)), 0, vlookup($A2, FFToolbox!$B$2:$E$414, 4, false)) -> 62 | M2: =Average(G2:L2) -> 72.5 | N2: =max(G2:L2)-min(G2:L2) -> 30
A3: Cooper Kupp | B3: Yes | C3: 1 | D3: LAR | E3: WR | F3: =vlookup(D3,'Team Bye List'!$A$1:$B$33,2,False) -> 8 | G3: =if(ISNA(vlookup($A3, Sleeper!$B$2:$E$330, 4, false)), 0, vlookup($A3, Sleeper!$B$2:$E$330, 4, false)) -> 52 | H3: =if(ISNA(vlookup($A3, ESPN!$B$2:$E$297, 4, false)), 0, vlookup($A3, ESPN!$B$2:$E$297, 4, false)) -> 59 | I3: =if(ISNA(vlookup($A3,'Ultimate Draft Kit'!$B$2:$E$324,4, false)), 0, vlookup($A3,'Ultimate Draft Kit'!$B$2:$E$324, 4, false)) -> 70 | J3: =if(ISNA(vlookup($A3,Rotowire!$B$2:$E$1075,4, false)), 0, vlookup($A3,Rotowire!$B$2:$E$1075, 4, false)) -> 62 | K3: =if(ISNA(vlookup($A3, FantasyPro!$B$2:$E$341,4,false)),0,vlookup($A3,FantasyPro!$B$2:$E$341,4,false)) -> 50 | L3: =if(ISNA(vlookup($A3, FFToolbox!$B$2:$E$414, 4, false)), 0, vlookup($A3, FFToolbox!$B$2:$E$414, 4, false)) -> 54 | M3: =Average(G3:L3) -> 57.833333 | N3: =max(G3:L3)-min(G3:L3) -> 20
A4: Justin Jefferson | B4: Yes | C4: 1 | D4: MIN | E4: WR | F4: =vlookup(D4,'Team Bye List'!$A$1:$B$33,2,False) -> 7 | G4: =if(ISNA(vlookup($A4, Sleeper!$B$2:$E$330, 4, false)), 0, vlookup($A4, Sleeper!$B$2:$E$330, 4, false)) -> 54 | H4: =if(ISNA(vlookup($A4, ESPN!$B$2:$E$297, 4, false)), 0, vlookup($A4, ESPN!$B$2:$E$297, 4, false)) -> 55 | I4: =if(ISNA(vlookup($A4,'Ultimate Draft Kit'!$B$2:$E$324,4, false)), 0, vlookup($A4,'Ultimate Draft Kit'!$B$2:$E$324, 4, false)) -> 69 | J4: =if(ISNA(vlookup($A4,Rotowire!$B$2:$E$1075,4, false)), 0, vlookup($A4,Rotowire!$B$2:$E$1075, 4, false)) -> 56 | K4: =if(ISNA(vlookup($A4, FantasyPro!$B$2:$E$341,4,false)),0,vlookup($A4,FantasyPro!$B$2:$E$341,4,false)) -> 56 | L4: =if(ISNA(vlookup($A4, FFToolbox!$B$2:$E$414, 4, false)), 0, vlookup($A4, FFToolbox!$B$2:$E$414, 4, false)) -> 59 | M4: =Average(G4:L4) -> 58.166667 | N4: =max(G4:L4)-min(G4:L4) -> 15
A5: Christian McCaffrey | B5: Yes | C5: 1 | D5: CAR | E5: RB | F5: =vlookup(D5,'Team Bye List'!$A$1:$B$33,2,False) -> 13 | G5: =if(ISNA(vlookup($A5, Sleeper!$B$2:$E$330, 4, false)), 0, vlookup($A5, Sleeper!$B$2:$E$330, 4, false)) -> 64 | H5: =if(ISNA(vlookup($A5, ESPN!$B$2:$E$297, 4, false)), 0, vlookup($A5, ESPN!$B$2:$E$297, 4, false)) -> 59 | I5: =if(ISNA(vlookup($A5,'Ultimate Draft Kit'!$B$2:$E$324,4, false)), 0, vlookup($A5,'Ultimate Draft Kit'!$B$2:$E$324, 4, false)) -> 58 | J5: =if(ISNA(vlookup($A5,Rotowire!$B$2:$E$1075,4, false)), 0, vlookup($A5,Rotowire!$B$2:$E$1075, 4, false)) -> 35 | K5: =if(ISNA(vlookup($A5, FantasyPro!$B$2:$E$341,4,false)),0,vlookup($A5,FantasyPro!$B$2:$E$341,4,false)) -> 64 | L5: =if(ISNA(vlookup($A5, FFToolbox!$B$2:$E$414, 4, false)), 0, vlookup($A5, FFToolbox!$B$2:$E$414, 4, false)) -> 60 | M5: =Average(G5:L5) -> 56.666667 | N5: =max(G5:L5)-min(G5:L5) -> 29
A6: Austin Ekeler | B6: Yes | C6: 2 | D6: LAC | E6: RB | F6: =vlookup(D6,'Team Bye List'!$A$1:$B$33,2,False) -> 6 | G6: =if(ISNA(vlookup($A6, Sleeper!$B$2:$E$330, 4, false)), 0, vlookup($A6, Sleeper!$B$2:$E$330, 4, false)) -> 57 | H6: =if(ISNA(vlookup($A6, ESPN!$B$2:$E$297, 4, false)), 0, vlookup($A6, ESPN!$B$2:$E$297, 4, false)) -> 58 | I6: =if(ISNA(vlookup($A6,'Ultimate Draft Kit'!$B$2:$E$324,4, false)), 0, vlookup($A6,'Ultimate Draft Kit'!$B$2:$E$324, 4, false)) -> 47 | J6: =if(ISNA(vlookup($A6,Rotowire!$B$2:$E$1075,4, false)), 0, vlookup($A6,Rotowire!$B$2:$E$1075, 4, false)) -> 58 | K6: =if(ISNA(vlookup($A6, FantasyPro!$B$2:$E$341,4,false)),0,vlookup($A6,FantasyPro!$B$2:$E$341,4,false)) -> 63 | L6: =if(ISNA(vlookup($A6, FFToolbox!$B$2:$E$414, 4, false)), 0, vlookup($A6, FFToolbox!$B$2:$E$414, 4, false)) -> 47 | M6: =Average(G6:L6) -> 55 | N6: =max(G6:L6)-min(G6:L6) -> 16
A7: Ja'Marr Chase | B7: Yes | C7: 2 | D7: CIN | E7: WR | F7: =vlookup(D7,'Team Bye List'!$A$1:$B$33,2,False) -> 10 | G7: =if(ISNA(vlookup($A7, Sleeper!$B$2:$E$330, 4, false)), 0, vlookup($A7, Sleeper!$B$2:$E$330, 4, false)) -> 46 | H7: =if(ISNA(vlookup($A7, ESPN!$B$2:$E$297, 4, false)), 0, vlookup($A7, ESPN!$B$2:$E$297, 4, false)) -> 54 | I7: =if(ISNA(vlookup($A7,'Ultimate Draft Kit'!$B$2:$E$324,4, false)), 0, vlookup($A7,'Ultimate Draft Kit'!$B$2:$E$324, 4, false)) -> 44 | J7: =if(ISNA(vlookup($A7,Rotowire!$B$2:$E$1075,4, false)), 0, vlookup($A7,Rotowire!$B$2:$E$1075, 4, false)) -> 58 | K7: =if(ISNA(vlookup($A7, FantasyPro!$B$2:$E$341,4,false)),0,vlookup($A7,FantasyPro!$B$2:$E$341,4,false)) -> 44 | L7: =if(ISNA(vlookup($A7, FFToolbox!$B$2:$E$414, 4, false)), 0, vlookup($A7, FFToolbox!$B$2:$E$414, 4, false)) -> 48 | M7: =Average(G7:L7) -> 49 | N7: =max(G7:L7)-min(G7:L7) -> 14
A8: Derrick Henry | B8: Yes | C8: 2 | D8: TEN | E8: RB | F8: =vlookup(D8,'Team Bye List'!$A$1:$B$33,2,False) -> 6 | G8: =if(ISNA(vlookup($A8, Sleeper!$B$2:$E$330, 4, false)), 0, vlookup($A8, Sleeper!$B$2:$E$330, 4, false)) -> 61 | H8: =if(ISNA(vlookup($A8, ESPN!$B$2:$E$297, 4, false)), 0, vlookup($A8, ESPN!$B$2:$E$297, 4, false)) -> 52 | I8: =if(ISNA(vlookup($A8,'Ultimate Draft Kit'!$B$2:$E$324,4, false)), 0, vlookup($A8,'Ultimate Draft Kit'!$B$2:$E$324, 4, false)) -> 43 | J8: =if(ISNA(vlookup($A8,Rotowire!$B$2:$E$1075,4, false)), 0, vlookup($A8,Rotowire!$B$2:$E$1075, 4, false)) -> 58 | K8: =if(ISNA(vlookup($A8, FantasyPro!$B$2:$E$341,4,false)),0,vlookup($A8,FantasyPro!$B$2:$E$341,4,false)) -> 51 | L8: =if(ISNA(vlookup($A8, FFToolbox!$B$2:$E$414, 4, false)), 0, vlookup($A8, FFToolbox!$B$2:$E$414, 4, false)) -> 39 | M8: =Average(G8:L8) -> 50.666667 | N8: =max(G8:L8)-min(G8:L8) -> 22
A9: Josh Allen | B9: Yes | C9: 1 | D9: BUF | E9: QB | F9: =vlookup(D9,'Team Bye List'!$A$1:$B$33,2,False) -> 7 | G9: =if(ISNA(vlookup($A9, Sleeper!$B$2:$E$330, 4, false)), 0, vlookup($A9, Sleeper!$B$2:$E$330, 4, false)) -> 39 | H9: =if(ISNA(vlookup($A9, ESPN!$B$2:$E$297, 4, false)), 0, vlookup($A9, ESPN!$B$2:$E$297, 4, false)) -> 19 | I9: =if(ISNA(vlookup($A9,'Ultimate Draft Kit'!$B$2:$E$324,4, false)), 0, vlookup($A9,'Ultimate Draft Kit'!$B$2:$E$324, 4, false)) -> 55 | J9: =if(ISNA(vlookup($A9,Rotowire!$B$2:$E$1075,4, false)), 0, vlookup($A9,Rotowire!$B$2:$E$1075, 4, false)) -> 95 | K9: =if(ISNA(vlookup($A9, FantasyPro!$B$2:$E$341,4,false)),0,vlookup($A9,FantasyPro!$B$2:$E$341,4,false)) -> 25 | L9: =if(ISNA(vlookup($A9, FFToolbox!$B$2:$E$414, 4, false)), 0, vlookup($A9, FFToolbox!$B$2:$E$414, 4, false)) -> 24 | M9: =Average(G9:L9) -> 42.833333 | N9: =max(G9:L9)-min(G9:L9) -> 76
A10: Deebo Samuel | B10: Yes | C10: 3 | D10: SF | E10: WR | F10: =vlookup(D10,'Team Bye List'!$A$1:$B$33,2,False) -> 11 | G10: =if(ISNA(vlookup($A10, Sleeper!$B$2:$E$330, 4, false)), 0, vlookup($A10, Sleeper!$B$2:$E$330, 4, false)) -> 33 | H10: =if(ISNA(vlookup($A10, ESPN!$B$2:$E$297, 4, false)), 0, vlookup($A10, ESPN!$B$2:$E$297, 4, false)) -> 45 | I10: =if(ISNA(vlookup($A10,'Ultimate Draft Kit'!$B$2:$E$324,4, false)), 0, vlookup($A10,'Ultimate Draft Kit'!$B$2:$E$324, 4, false)) -> 33 | J10: =if(ISNA(vlookup($A10,Rotowire!$B$2:$E$1075,4, false)), 0, vlookup($A10,Rotowire!$B$2:$E$1075, 4, false)) -> 61 | K10: =if(ISNA(vlookup($A10, FantasyPro!$B$2:$E$341,4,false)),0,vlookup($A10,FantasyPro!$B$2:$E$341,4,false)) -> 34 | L10: =if(ISNA(vlookup($A10, FFToolbox!$B$2:$E$414, 4, false)), 0, vlookup($A10, FFToolbox!$B$2:$E$414, 4, false)) -> 33 | M10: =Average(G10:L10) -> 39.833333 | N10: =max(G10:L10)-min(G10:L10) -> 28
A11: Davante Adams | B11: Yes | C11: 2 | D11: LV | E11: WR | F11: =vlookup(D11,'Team Bye List'!$A$1:$B$33,2,False) -> 7 | G11: =if(ISNA(vlookup($A11, Sleeper!$B$2:$E$330, 4, false)), 0, vlookup($A11, Sleeper!$B$2:$E$330, 4, false)) -> 34 | H11: =if(ISNA(vlookup($A11, ESPN!$B$2:$E$297, 4, false)), 0, vlookup($A11, ESPN!$B$2:$E$297, 4, false)) -> 49 | I11: =if(ISNA(vlookup($A11,'Ultimate Draft Kit'!$B$2:$E$324,4, false)), 0, vlookup($A11,'Ultimate Draft Kit'!$B$2:$E$324, 4, false)) -> 44 | J11: =if(ISNA(vlookup($A11,Rotowire!$B$2:$E$1075,4, false)), 0, vlookup($A11,Rotowire!$B$2:$E$1075, 4, false)) -> 33 | K11: =if(ISNA(vlookup($A11, FantasyPro!$B$2:$E$341,4,false)),0,vlookup($A11,FantasyPro!$B$2:$E$341,4,false)) -> 39 | L11: =if(ISNA(vlookup($A11, FFToolbox!$B$2:$E$414, 4, false)), 0, vlookup($A11, FFToolbox!$B$2:$E$414, 4, false)) -> 43 | M11: =Average(G11:L11) -> 40.333333 | N11: =max(G11:L11)-min(G11:L11) -> 16
A12: Stefon Diggs | B12: Yes | C12: 2 | D12: BUF | E12: WR | F12: =vlookup(D12,'Team Bye List'!$A$1:$B$33,2,False) -> 7 | G12: =if(ISNA(vlookup($A12, Sleeper!$B$2:$E$330, 4, false)), 0, vlookup($A12, Sleeper!$B$2:$E$330, 4, false)) -> 35 | H12: =if(ISNA(vlookup($A12, ESPN!$B$2:$E$297, 4, false)), 0, vlookup($A12, ESPN!$B$2:$E$297, 4, false)) -> 44 | I12: =if(ISNA(vlookup($A12,'Ultimate Draft Kit'!$B$2:$E$324,4, false)), 0, vlookup($A12,'Ultimate Draft Kit'!$B$2:$E$324, 4, false)) -> 45 | J12: =if(ISNA(vlookup($A12,Rotowire!$B$2:$E$1075,4, false)), 0, vlookup($A12,Rotowire!$B$2:$E$1075, 4, false)) -> 38 | K12: =if(ISNA(vlookup($A12, FantasyPro!$B$2:$E$341,4,false)),0,vlookup($A12,FantasyPro!$B$2:$E$341,4,false)) -> 41 | L12: =if(ISNA(vlookup($A12, FFToolbox!$B$2:$E$414, 4, false)), 0, vlookup($A12, FFToolbox!$B$2:$E$414, 4, false)) -> 44 | M12: =Average(G12:L12) -> 41.166667 | N12: =max(G12:L12)-min(G12:L12) -> 10
A13: Dalvin Cook | B13: Yes | C13: 2 | D13: MIN | E13: RB | F13: =vlookup(D13,'Team Bye List'!$A$1:$B$33,2,False) -> 7 | G13: =if(ISNA(vlookup($A13, Sleeper!$B$2:$E$330, 4, false)), 0, vlookup($A13, Sleeper!$B$2:$E$330, 4, false)) -> 58 | H13: =if(ISNA(vlookup($A13, ESPN!$B$2:$E$297, 4, false)), 0, vlookup($A13, ESPN!$B$2:$E$297, 4, false)) -> 46 | I13: =if(ISNA(vlookup($A13,'Ultimate Draft Kit'!$B$2:$E$324,4, false)), 0, vlookup($A13,'Ultimate Draft Kit'!$B$2:$E$324, 4, false)) -> 39 | J13: =if(ISNA(vlookup($A13,Rotowire!$B$2:$E$1075,4, false)), 0, vlookup($A13,Rotowire!$B$2:$E$1075, 4, false)) -> 36 | K13: =if(ISNA(vlookup($A13, FantasyPro!$B$2:$E$341,4,false)),0,vlookup($A13,FantasyPro!$B$2:$E$341,4,false)) -> 58 | L13: =if(ISNA(vlookup($A13, FFToolbox!$B$2:$E$414, 4, false)), 0, vlookup($A13, FFToolbox!$B$2:$E$414, 4, false)) -> 42 | M13: =Average(G13:L13) -> 46.5 | N13: =max(G13:L13)-min(G13:L13) -> 22
... A189: Miami Dolphins | B189: No | C189: 24 | D189: MIA | E189: DST | F189: =vlookup(D189,'Team Bye List'!$A$1:$B$33,2,False) -> 11 | G189: =if(ISNA(vlookup($A189, Sleeper!$B$2:$E$330, 4, false)), 0, vlookup($A189, Sleeper!$B$2:$E$330, 4, false)) -> 1 | H189: =if(ISNA(vlookup($A189, ESPN!$B$2:$E$297, 4, false)), 0, vlookup($A189, ESPN!$B$2:$E$297, 4, false)) -> 0 | I189: =if(ISNA(vlookup($A189,'Ultimate Draft Kit'!$B$2:$E$324,4, false)), 0, vlookup($A189,'Ultimate Draft Kit'!$B$2:$E$324, 4, false)) -> 1 | J189: =if(ISNA(vlookup($A189,Rotowire!$B$2:$E$1075,4, false)), 0, vlookup($A189,Rotowire!$B$2:$E$1075, 4, false)) -> 0 | K189: =if(ISNA(vlookup($A189, FantasyPro!$B$2:$E$341,4,false)),0,vlookup($A189,FantasyPro!$B$2:$E$341,4,false)) -> 0 | L189: =if(ISNA(vlookup($A189, FFToolbox!$B$2:$E$414, 4, false)), 0, vlookup($A189, FFToolbox!$B$2:$E$414, 4, false)) -> 0 | M189: =Average(G189:L189) -> 0.33333333 | N189: =max(G189:L189)-min(G189:L189) -> 1
A190: Jonathan Garibay | B190: No | C190: NR | D190: DAL | E190: K | F190: =vlookup(D190,'Team Bye List'!$A$1:$B$33,2,False) -> 9 | G190: =if(ISNA(vlookup($A190, Sleeper!$B$2:$E$330, 4, false)), 0, vlookup($A190, Sleeper!$B$2:$E$330, 4, false)) -> 1 | H190: =if(ISNA(vlookup($A190, ESPN!$B$2:$E$297, 4, false)), 0, vlookup($A190, ESPN!$B$2:$E$297, 4, false)) -> 0 | I190: =if(ISNA(vlookup($A190,'Ultimate Draft Kit'!$B$2:$E$324,4, false)), 0, vlookup($A190,'Ultimate Draft Kit'!$B$2:$E$324, 4, false)) -> 0 | J190: =if(ISNA(vlookup($A190,Rotowire!$B$2:$E$1075,4, false)), 0, vlookup($A190,Rotowire!$B$2:$E$1075, 4, false)) -> 0 | K190: =if(ISNA(vlookup($A190, FantasyPro!$B$2:$E$341,4,false)),0,vlookup($A190,FantasyPro!$B$2:$E$341,4,false)) -> 0 | L190: =if(ISNA(vlookup($A190, FFToolbox!$B$2:$E$414, 4, false)), 0, vlookup($A190, FFToolbox!$B$2:$E$414, 4, false)) -> 0 | M190: =Average(G190:L190) -> 0.16666667 | N190: =max(G190:L190)-min(G190:L190) -> 1
A191: Mason Crosby | B191: No | C191: 19 | D191: GB | E191: K | F191: =vlookup(D191,'Team Bye List'!$A$1:$B$33,2,False) -> 14 | G191: =if(ISNA(vlookup($A191, Sleeper!$B$2:$E$330, 4, false)), 0, vlookup($A191, Sleeper!$B$2:$E$330, 4, false)) -> 1 | H191: =if(ISNA(vlookup($A191, ESPN!$B$2:$E$297, 4, false)), 0, vlookup($A191, ESPN!$B$2:$E$297, 4, false)) -> 0 | I191: =if(ISNA(vlookup($A191,'Ultimate Draft Kit'!$B$2:$E$324,4, false)), 0, vlookup($A191,'Ultimate Draft Kit'!$B$2:$E$324, 4, false)) -> 1 | J191: =if(ISNA(vlookup($A191,Rotowire!$B$2:$E$1075,4, false)), 0, vlookup($A191,Rotowire!$B$2:$E$1075, 4, false)) -> 0 | K191: =if(ISNA(vlookup($A191, FantasyPro!$B$2:$E$341,4,false)),0,vlookup($A191,FantasyPro!$B$2:$E$341,4,false)) -> 0 | L191: =if(ISNA(vlookup($A191, FFToolbox!$B$2:$E$414, 4, false)), 0, vlookup($A191, FFToolbox!$B$2:$E$414, 4, false)) -> 1 | M191: =Average(G191:L191) -> 0.5 | N191: =max(G191:L191)-min(G191:L191) -> 1
A192: Albert Okwuegbunam | B192: No | C192: 5 | D192: DEN | E192: TE | F192: =vlookup(D192,'Team Bye List'!$A$1:$B$33,2,False) -> 9 | G192: =if(ISNA(vlookup($A192, Sleeper!$B$2:$E$330, 4, false)), 0, vlookup($A192, Sleeper!$B$2:$E$330, 4, false)) -> 7 | H192: =if(ISNA(vlookup($A192, ESPN!$B$2:$E$297, 4, false)), 0, vlookup($A192, ESPN!$B$2:$E$297, 4, false)) -> 0 | I192: =if(ISNA(vlookup($A192,'Ultimate Draft Kit'!$B$2:$E$324,4, false)), 0, vlookup($A192,'Ultimate Draft Kit'!$B$2:$E$324, 4, false)) -> 1 | J192: =if(ISNA(vlookup($A192,Rotowire!$B$2:$E$1075,4, false)), 0, vlookup($A192,Rotowire!$B$2:$E$1075, 4, false)) -> 0 | K192: =if(ISNA(vlookup($A192, FantasyPro!$B$2:$E$341,4,false)),0,vlookup($A192,FantasyPro!$B$2:$E$341,4,false)) -> 1 | L192: =if(ISNA(vlookup($A192, FFToolbox!$B$2:$E$414, 4, false)), 0, vlookup($A192, FFToolbox!$B$2:$E$414, 4, false)) -> 3 | M192: =Average(G192:L192) -> 2 | N192: =max(G192:L192)-min(G192:L192) -> 7
A193: Robert Tonyan | B193: No | C193: 6 | D193: GB | E193: TE | F193: =vlookup(D193,'Team Bye List'!$A$1:$B$33,2,False) -> 14 | G193: =if(ISNA(vlookup($A193, Sleeper!$B$2:$E$330, 4, false)), 0, vlookup($A193, Sleeper!$B$2:$E$330, 4, false)) -> 1 | H193: =if(ISNA(vlookup($A193, ESPN!$B$2:$E$297, 4, false)), 0, vlookup($A193, ESPN!$B$2:$E$297, 4, false)) -> 0 | I193: =if(ISNA(vlookup($A193,'Ultimate Draft Kit'!$B$2:$E$324,4, false)), 0, vlookup($A193,'Ultimate Draft Kit'!$B$2:$E$324, 4, false)) -> 1 | J193: =if(ISNA(vlookup($A193,Rotowire!$B$2:$E$1075,4, false)), 0, vlookup($A193,Rotowire!$B$2:$E$1075, 4, false)) -> 0 | K193: =if(ISNA(vlookup($A193, FantasyPro!$B$2:$E$341,4,false)),0,vlookup($A193,FantasyPro!$B$2:$E$341,4,false)) -> 1 | L193: =if(ISNA(vlookup($A193, FFToolbox!$B$2:$E$414, 4, false)), 0, vlookup($A193, FFToolbox!$B$2:$E$414, 4, false)) -> 1 | M193: =Average(G193:L193) -> 0.66666667 | N193: =max(G193:L193)-min(G193:L193) -> 1
A194: Austin Hooper | B194: No | C194: 6 | D194: TEN | E194: TE | F194: =vlookup(D194,'Team Bye List'!$A$1:$B$33,2,False) -> 6 | G194: =if(ISNA(vlookup($A194, Sleeper!$B$2:$E$330, 4, false)), 0, vlookup($A194, Sleeper!$B$2:$E$330, 4, false)) -> 1 | H194: =if(ISNA(vlookup($A194, ESPN!$B$2:$E$297, 4, false)), 0, vlookup($A194, ESPN!$B$2:$E$297, 4, false)) -> 0 | I194: =if(ISNA(vlookup($A194,'Ultimate Draft Kit'!$B$2:$E$324,4, false)), 0, vlookup($A194,'Ultimate Draft Kit'!$B$2:$E$324, 4, false)) -> 1 | J194: =if(ISNA(vlookup($A194,Rotowire!$B$2:$E$1075,4, false)), 0, vlookup($A194,Rotowire!$B$2:$E$1075, 4, false)) -> 0 | K194: =if(ISNA(vlookup($A194, FantasyPro!$B$2:$E$341,4,false)),0,vlookup($A194,FantasyPro!$B$2:$E$341,4,false)) -> 1 | L194: =if(ISNA(vlookup($A194, FFToolbox!$B$2:$E$414, 4, false)), 0, vlookup($A194, FFToolbox!$B$2:$E$414, 4, false)) -> 1 | M194: =Average(G194:L194) -> 0.66666667 | N194: =max(G194:L194)-min(G194:L194) -> 1
A195: Evan Engram | B195: No | C195: 5 | D195: JAC | E195: TE | F195: =vlookup(D195,'Team Bye List'!$A$1:$B$33,2,False) -> 11 | G195: =if(ISNA(vlookup($A195, Sleeper!$B$2:$E$330, 4, false)), 0, vlookup($A195, Sleeper!$B$2:$E$330, 4, false)) -> 1 | H195: =if(ISNA(vlookup($A195, ESPN!$B$2:$E$297, 4, false)), 0, vlookup($A195, ESPN!$B$2:$E$297, 4, false)) -> 0 | I195: =if(ISNA(vlookup($A195,'Ultimate Draft Kit'!$B$2:$E$324,4, false)), 0, vlookup($A195,'Ultimate Draft Kit'!$B$2:$E$324, 4, false)) -> 1 | J195: =if(ISNA(vlookup($A195,Rotowire!$B$2:$E$1075,4, false)), 0, vlookup($A195,Rotowire!$B$2:$E$1075, 4, false)) -> 0 | K195: =if(ISNA(vlookup($A195, FantasyPro!$B$2:$E$341,4,false)),0,vlookup($A195,FantasyPro!$B$2:$E$341,4,false)) -> 1 | L195: =if(ISNA(vlookup($A195, FFToolbox!$B$2:$E$414, 4, false)), 0, vlookup($A195, FFToolbox!$B$2:$E$414, 4, false)) -> 1 | M195: =Average(G195:L195) -> 0.66666667 | N195: =max(G195:L195)-min(G195:L195) -> 1
A196: Gus Edwards | B196: No | C196: 9 | D196: BAL | E196: RB | F196: =vlookup(D196,'Team Bye List'!$A$1:$B$33,2,False) -> 10 | G196: =if(ISNA(vlookup($A196, Sleeper!$B$2:$E$330, 4, false)), 0, vlookup($A196, Sleeper!$B$2:$E$330, 4, false)) -> 1 | H196: =if(ISNA(vlookup($A196, ESPN!$B$2:$E$297, 4, false)), 0, vlookup($A196, ESPN!$B$2:$E$297, 4, false)) -> 0 | I196: =if(ISNA(vlookup($A196,'Ultimate Draft Kit'!$B$2:$E$324,4, false)), 0, vlookup($A196,'Ultimate Draft Kit'!$B$2:$E$324, 4, false)) -> 1 | J196: =if(ISNA(vlookup($A196,Rotowire!$B$2:$E$1075,4, false)), 0, vlookup($A196,Rotowire!$B$2:$E$1075, 4, false)) -> 0 | K196: =if(ISNA(vlookup($A196, FantasyPro!$B$2:$E$341,4,false)),0,vlookup($A196,FantasyPro!$B$2:$E$341,4,false)) -> 1 | L196: =if(ISNA(vlookup($A196, FFToolbox!$B$2:$E$414, 4, false)), 0, vlookup($A196, FFToolbox!$B$2:$E$414, 4, false)) -> 1 | M196: =Average(G196:L196) -> 0.66666667 | N196: =max(G196:L196)-min(G196:L196) -> 1
A197: Isaiah Spiller | B197: No | C197: 9 | D197: LAC | E197: RB | F197: =vlookup(D197,'Team Bye List'!$A$1:$B$33,2,False) -> 6 | G197: =if(ISNA(vlookup($A197, Sleeper!$B$2:$E$330, 4, false)), 0, vlookup($A197, Sleeper!$B$2:$E$330, 4, false)) -> 1 | H197: =if(ISNA(vlookup($A197, ESPN!$B$2:$E$297, 4, false)), 0, vlookup($A197, ESPN!$B$2:$E$297, 4, false)) -> 0 | I197: =if(ISNA(vlookup($A197,'Ultimate Draft Kit'!$B$2:$E$324,4, false)), 0, vlookup($A197,'Ultimate Draft Kit'!$B$2:$E$324, 4, false)) -> 1 | J197: =if(ISNA(vlookup($A197,Rotowire!$B$2:$E$1075,4, false)), 0, vlookup($A197,Rotowire!$B$2:$E$1075, 4, false)) -> 0 | K197: =if(ISNA(vlookup($A197, FantasyPro!$B$2:$E$341,4,false)),0,vlookup($A197,FantasyPro!$B$2:$E$341,4,false)) -> 2 | L197: =if(ISNA(vlookup($A197, FFToolbox!$B$2:$E$414, 4, false)), 0, vlookup($A197, FFToolbox!$B$2:$E$414, 4, false)) -> 2 | M197: =Average(G197:L197) -> 1 | N197: =max(G197:L197)-min(G197:L197) -> 2
A198: Riley Patterson | B198: No | C198: NR | D198: DET | E198: K | F198: =vlookup(D198,'Team Bye List'!$A$1:$B$33,2,False) -> 6 | G198: =if(ISNA(vlookup($A198, Sleeper!$B$2:$E$330, 4, false)), 0, vlookup($A198, Sleeper!$B$2:$E$330, 4, false)) -> 0 | H198: =if(ISNA(vlookup($A198, ESPN!$B$2:$E$297, 4, false)), 0, vlookup($A198, ESPN!$B$2:$E$297, 4, false)) -> 0 | I198: =if(ISNA(vlookup($A198,'Ultimate Draft Kit'!$B$2:$E$324,4, false)), 0, vlookup($A198,'Ultimate Draft Kit'!$B$2:$E$324, 4, false)) -> 0 | J198: =if(ISNA(vlookup($A198,Rotowire!$B$2:$E$1075,4, false)), 0, vlookup($A198,Rotowire!$B$2:$E$1075, 4, false)) -> 1 | K198: =if(ISNA(vlookup($A198, FantasyPro!$B$2:$E$341,4,false)),0,vlookup($A198,FantasyPro!$B$2:$E$341,4,false)) -> 0 | L198: =if(ISNA(vlookup($A198, FFToolbox!$B$2:$E$414, 4, false)), 0, vlookup($A198, FFToolbox!$B$2:$E$414, 4, false)) -> 0 | M198: =Average(G198:L198) -> 0.16666667 | N198: =max(G198:L198)-min(G198:L198) -> 1
A199: Cincinnati Bengals | B199: No | C199: 20 | D199: CIN | E199: DST | F199: =vlookup(D199,'Team Bye List'!$A$1:$B$33,2,False) -> 10 | G199: =if(ISNA(vlookup($A199, Sleeper!$B$2:$E$330, 4, false)), 0, vlookup($A199, Sleeper!$B$2:$E$330, 4, false)) -> 1 | H199: =if(ISNA(vlookup($A199, ESPN!$B$2:$E$297, 4, false)), 0, vlookup($A199, ESPN!$B$2:$E$297, 4, false)) -> 0 | I199: =if(ISNA(vlookup($A199,'Ultimate Draft Kit'!$B$2:$E$324,4, false)), 0, vlookup($A199,'Ultimate Draft Kit'!$B$2:$E$324, 4, false)) -> 1 | J199: =if(ISNA(vlookup($A199,Rotowire!$B$2:$E$1075,4, false)), 0, vlookup($A199,Rotowire!$B$2:$E$1075, 4, false)) -> 0 | K199: =if(ISNA(vlookup($A199, FantasyPro!$B$2:$E$341,4,false)),0,vlookup($A199,FantasyPro!$B$2:$E$341,4,false)) -> 0 | L199: =if(ISNA(vlookup($A199, FFToolbox!$B$2:$E$414, 4, false)), 0, vlookup($A199, FFToolbox!$B$2:$E$414, 4, false)) -> 0 | M199: =Average(G199:L199) -> 0.33333333 | N199: =max(G199:L199)-min(G199:L199) -> 1
A200: Philadelphia Eagles | B200: No | C200: 18 | D200: PHI | E200: DST | F200: =vlookup(D200,'Team Bye List'!$A$1:$B$33,2,False) -> 7 | G200: =if(ISNA(vlookup($A200, Sleeper!$B$2:$E$330, 4, false)), 0, vlookup($A200, Sleeper!$B$2:$E$330, 4, false)) -> 1 | H200: =if(ISNA(vlookup($A200, ESPN!$B$2:$E$297, 4, false)), 0, vlookup($A200, ESPN!$B$2:$E$297, 4, false)) -> 0 | I200: =if(ISNA(vlookup($A200,'Ultimate Draft Kit'!$B$2:$E$324,4, false)), 0, vlookup($A200,'Ultimate Draft Kit'!$B$2:$E$324, 4, false)) -> 1 | J200: =if(ISNA(vlookup($A200,Rotowire!$B$2:$E$1075,4, false)), 0, vlookup($A200,Rotowire!$B$2:$E$1075, 4, false)) -> 0 | K200: =if(ISNA(vlookup($A200, FantasyPro!$B$2:$E$341,4,false)),0,vlookup($A200,FantasyPro!$B$2:$E$341,4,false)) -> 0 | L200: =if(ISNA(vlookup($A200, FFToolbox!$B$2:$E$414, 4, false)), 0, vlookup($A200, FFToolbox!$B$2:$E$414, 4, false)) -> 0 | M200: =Average(G200:L200) -> 0.33333333 | N200: =max(G200:L200)-min(G200:L200) -> 1
A201: Cleveland Browns | B201: No | C201: 13 | D201: CLE | E201: DST | F201: =vlookup(D201,'Team Bye List'!$A$1:$B$33,2,False) -> 9 | G201: =if(ISNA(vlookup($A201, Sleeper!$B$2:$E$330, 4, false)), 0, vlookup($A201, Sleeper!$B$2:$E$330, 4, false)) -> 1 | H201: =if(ISNA(vlookup($A201, ESPN!$B$2:$E$297, 4, false)), 0, vlookup($A201, ESPN!$B$2:$E$297, 4, false)) -> 0 | I201: =if(ISNA(vlookup($A201,'Ultimate Draft Kit'!$B$2:$E$324,4, false)), 0, vlookup($A201,'Ultimate Draft Kit'!$B$2:$E$324, 4, false)) -> 1 | J201: =if(ISNA(vlookup($A201,Rotowire!$B$2:$E$1075,4, false)), 0, vlookup($A201,Rotowire!$B$2:$E$1075, 4, false)) -> 0 | K201: =if(ISNA(vlookup($A201, FantasyPro!$B$2:$E$341,4,false)),0,vlookup($A201,FantasyPro!$B$2:$E$341,4,false)) -> 0 | L201: =if(ISNA(vlookup($A201, FFToolbox!$B$2:$E$414, 4, false)), 0, vlookup($A201, FFToolbox!$B$2:$E$414, 4, false)) -> 0 | M201: =Average(G201:L201) -> 0.33333333 | N201: =max(G201:L201)-min(G201:L201) -> 1
A202: New England Patriots | B202: No | C202: 21 | D202: NE | E202: DST | F202: =vlookup(D202,'Team Bye List'!$A$1:$B$33,2,False) -> 10 | G202: =if(ISNA(vlookup($A202, Sleeper!$B$2:$E$330, 4, false)), 0, vlookup($A202, Sleeper!$B$2:$E$330, 4, false)) -> 1 | H202: =if(ISNA(vlookup($A202, ESPN!$B$2:$E$297, 4, false)), 0, vlookup($A202, ESPN!$B$2:$E$297, 4, false)) -> 0 | I202: =if(ISNA(vlookup($A202,'Ultimate Draft Kit'!$B$2:$E$324,4, false)), 0, vlookup($A202,'Ultimate Draft Kit'!$B$2:$E$324, 4, false)) -> 1 | J202: =if(ISNA(vlookup($A202,Rotowire!$B$2:$E$1075,4, false)), 0, vlookup($A202,Rotowire!$B$2:$E$1075, 4, false)) -> 0 | K202: =if(ISNA(vlookup($A202, FantasyPro!$B$2:$E$341,4,false)),0,vlookup($A202,FantasyPro!$B$2:$E$341,4,false)) -> 1 | L202: =if(ISNA(vlookup($A202, FFToolbox!$B$2:$E$414, 4, false)), 0, vlookup($A202, FFToolbox!$B$2:$E$414, 4, false)) -> 0 | M202: =Average(G202:L202) -> 0.5 | N202: =max(G202:L202)-min(G202:L202) -> 1
A203: Arizona Cardinals | B203: No | C203: 15 | D203: ARI | E203: DST | F203: =vlookup(D203,'Team Bye List'!$A$1:$B$33,2,False) -> 13 | G203: =if(ISNA(vlookup($A203, Sleeper!$B$2:$E$330, 4, false)), 0, vlookup($A203, Sleeper!$B$2:$E$330, 4, false)) -> 1 | H203: =if(ISNA(vlookup($A203, ESPN!$B$2:$E$297, 4, false)), 0, vlookup($A203, ESPN!$B$2:$E$297, 4, false)) -> 0 | I203: =if(ISNA(vlookup($A203,'Ultimate Draft Kit'!$B$2:$E$324,4, false)), 0, vlookup($A203,'Ultimate Draft Kit'!$B$2:$E$324, 4, false)) -> 1 | J203: =if(ISNA(vlookup($A203,Rotowire!$B$2:$E$1075,4, false)), 0, vlookup($A203,Rotowire!$B$2:$E$1075, 4, false)) -> 0 | K203: =if(ISNA(vlookup($A203, FantasyPro!$B$2:$E$341,4,false)),0,vlookup($A203,FantasyPro!$B$2:$E$341,4,false)) -> 0 | L203: =if(ISNA(vlookup($A203, FFToolbox!$B$2:$E$414, 4, false)), 0, vlookup($A203, FFToolbox!$B$2:$E$414, 4, false)) -> 0 | M203: =Average(G203:L203) -> 0.33333333 | N203: =max(G203:L203)-min(G203:L203) -> 1
A204: Denver Broncos | B204: Yes | C204: 6 | D204: DEN | E204: DST | F204: =vlookup(D204,'Team Bye List'!$A$1:$B$33,2,False) -> 9 | G204: =if(ISNA(vlookup($A204, Sleeper!$B$2:$E$330, 4, false)), 0, vlookup($A204, Sleeper!$B$2:$E$330, 4, false)) -> 1 | H204: =if(ISNA(vlookup($A204, ESPN!$B$2:$E$297, 4, false)), 0, vlookup($A204, ESPN!$B$2:$E$297, 4, false)) -> 0 | I204: =if(ISNA(vlookup($A204,'Ultimate Draft Kit'!$B$2:$E$324,4, false)), 0, vlookup($A204,'Ultimate Draft Kit'!$B$2:$E$324, 4, false)) -> 1 | J204: =if(ISNA(vlookup($A204,Rotowire!$B$2:$E$1075,4, false)), 0, vlookup($A204,Rotowire!$B$2:$E$1075, 4, false)) -> 0 | K204: =if(ISNA(vlookup($A204, FantasyPro!$B$2:$E$341,4,false)),0,vlookup($A204,FantasyPro!$B$2:$E$341,4,false)) -> 1 | L204: =if(ISNA(vlookup($A204, FFToolbox!$B$2:$E$414, 4, false)), 0, vlookup($A204, FFToolbox!$B$2:$E$414, 4, false)) -> 0 | M204: =Average(G204:L204) -> 0.5 | N204: =max(G204:L204)-min(G204:L204) -> 1
A205: Tennessee Titans | B205: No | C205: 22 | D205: TEN | E205: DST | F205: =vlookup(D205,'Team Bye List'!$A$1:$B$33,2,False) -> 6 | G205: =if(ISNA(vlookup($A205, Sleeper!$B$2:$E$330, 4, false)), 0, vlookup($A205, Sleeper!$B$2:$E$330, 4, false)) -> 1 | H205: =if(ISNA(vlookup($A205, ESPN!$B$2:$E$297, 4, false)), 0, vlookup($A205, ESPN!$B$2:$E$297, 4, false)) -> 0 | I205: =if(ISNA(vlookup($A205,'Ultimate Draft Kit'!$B$2:$E$324,4, false)), 0, vlookup($A205,'Ultimate Draft Kit'!$B$2:$E$324, 4, false)) -> 1 | J205: =if(ISNA(vlookup($A205,Rotowire!$B$2:$E$1075,4, false)), 0, vlookup($A205,Rotowire!$B$2:$E$1075, 4, false)) -> 0 | K205: =if(ISNA(vlookup($A205, FantasyPro!$B$2:$E$341,4,false)),0,vlookup($A205,FantasyPro!$B$2:$E$341,4,false)) -> 0 | L205: =if(ISNA(vlookup($A205, FFToolbox!$B$2:$E$414, 4, false)), 0, vlookup($A205, FFToolbox!$B$2:$E$414, 4, false)) -> 0 | M205: =Average(G205:L205) -> 0.33333333 | N205: =max(G205:L205)-min(G205:L205) -> 1
A206: Kansas City Chiefs | B206: No | C206: 14 | D206: KC | E206: DST | F206: =vlookup(D206,'Team Bye List'!$A$1:$B$33,2,False) -> 8 | G206: =if(ISNA(vlookup($A206, Sleeper!$B$2:$E$330, 4, false)), 0, vlookup($A206, Sleeper!$B$2:$E$330, 4, false)) -> 1 | H206: =if(ISNA(vlookup($A206, ESPN!$B$2:$E$297, 4, false)), 0, vlookup($A206, ESPN!$B$2:$E$297, 4, false)) -> 0 | I206: =if(ISNA(vlookup($A206,'Ultimate Draft Kit'!$B$2:$E$324,4, false)), 0, vlookup($A206,'Ultimate Draft Kit'!$B$2:$E$324, 4, false)) -> 1 | J206: =if(ISNA(vlookup($A206,Rotowire!$B$2:$E$1075,4, false)), 0, vlookup($A206,Rotowire!$B$2:$E$1075, 4, false)) -> 0 | K206: =if(ISNA(vlookup($A206, FantasyPro!$B$2:$E$341,4,false)),0,vlookup($A206,FantasyPro!$B$2:$E$341,4,false)) -> 0 | L206: =if(ISNA(vlookup($A206, FFToolbox!$B$2:$E$414, 4, false)), 0, vlookup($A206, FFToolbox!$B$2:$E$414, 4, false)) -> 0 | M206: =Average(G206:L206) -> 0.33333333 | N206: =max(G206:L206)-min(G206:L206) -> 1
A207: New York Giants | B207: No | C207: 8 | D207: NYG | E207: DST | F207: =vlookup(D207,'Team Bye List'!$A$1:$B$33,2,False) -> 9 | G207: =if(ISNA(vlookup($A207, Sleeper!$B$2:$E$330, 4, false)), 0, vlookup($A207, Sleeper!$B$2:$E$330, 4, false)) -> 1 | H207: =if(ISNA(vlookup($A207, ESPN!$B$2:$E$297, 4, false)), 0, vlookup($A207, ESPN!$B$2:$E$297, 4, false)) -> 0 | I207: =if(ISNA(vlookup($A207,'Ultimate Draft Kit'!$B$2:$E$324,4, false)), 0, vlookup($A207,'Ultimate Draft Kit'!$B$2:$E$324, 4, false)) -> 1 | J207: =if(ISNA(vlookup($A207,Rotowire!$B$2:$E$1075,4, false)), 0, vlookup($A207,Rotowire!$B$2:$E$1075, 4, false)) -> 0 | K207: =if(ISNA(vlookup($A207, FantasyPro!$B$2:$E$341,4,false)),0,vlookup($A207,FantasyPro!$B$2:$E$341,4,false)) -> 0 | L207: =if(ISNA(vlookup($A207, FFToolbox!$B$2:$E$414, 4, false)), 0, vlookup($A207, FFToolbox!$B$2:$E$414, 4, false)) -> 0 | M207: =Average(G207:L207) -> 0.33333333 | N207: =max(G207:L207)-min(G207:L207) -> 1
A208: Las Vegas Raiders | B208: No | C208: 27 | D208: LV | E208: DST | F208: =vlookup(D208,'Team Bye List'!$A$1:$B$33,2,False) -> 7 | G208: =if(ISNA(vlookup($A208, Sleeper!$B$2:$E$330, 4, false)), 0, vlookup($A208, Sleeper!$B$2:$E$330, 4, false)) -> 1 | H208: =if(ISNA(vlookup($A208, ESPN!$B$2:$E$297, 4, false)), 0, vlookup($A208, ESPN!$B$2:$E$297, 4, false)) -> 0 | I208: =if(ISNA(vlookup($A208,'Ultimate Draft Kit'!$B$2:$E$324,4, false)), 0, vlookup($A208,'Ultimate Draft Kit'!$B$2:$E$324, 4, false)) -> 1 | J208: =if(ISNA(vlookup($A208,Rotowire!$B$2:$E$1075,4, false)), 0, vlookup($A208,Rotowire!$B$2:$E$1075, 4, false)) -> 0 | K208: =if(ISNA(vlookup($A208, FantasyPro!$B$2:$E$341,4,false)),0,vlookup($A208,FantasyPro!$B$2:$E$341,4,false)) -> 0 | L208: =if(ISNA(vlookup($A208, FFToolbox!$B$2:$E$414, 4, false)), 0, vlookup($A208, FFToolbox!$B$2:$E$414, 4, false)) -> 0 | M208: =Average(G208:L208) -> 0.33333333 | N208: =max(G208:L208)-min(G208:L208) -> 1
A209: New York Jets | B209: No | C209: 25 | D209: NYJ | E209: DST | F209: =vlookup(D209,'Team Bye List'!$A$1:$B$33,2,False) -> 10 | G209: =if(ISNA(vlookup($A209, Sleeper!$B$2:$E$330, 4, false)), 0, vlookup($A209, Sleeper!$B$2:$E$330, 4, false)) -> 1 | H209: =if(ISNA(vlookup($A209, ESPN!$B$2:$E$297, 4, false)), 0, vlookup($A209, ESPN!$B$2:$E$297, 4, false)) -> 0 | I209: =if(ISNA(vlookup($A209,'Ultimate Draft Kit'!$B$2:$E$324,4, false)), 0, vlookup($A209,'Ultimate Draft Kit'!$B$2:$E$324, 4, false)) -> 1 | J209: =if(ISNA(vlookup($A209,Rotowire!$B$2:$E$1075,4, false)), 0, vlookup($A209,Rotowire!$B$2:$E$1075, 4, false)) -> 0 | K209: =if(ISNA(vlookup($A209, FantasyPro!$B$2:$E$341,4,false)),0,vlookup($A209,FantasyPro!$B$2:$E$341,4,false)) -> 0 | L209: =if(ISNA(vlookup($A209, FFToolbox!$B$2:$E$414, 4, false)), 0, vlookup($A209, FFToolbox!$B$2:$E$414, 4, false)) -> 0 | M209: =Average(G209:L209) -> 0.33333333 | N209: =max(G209:L209)-min(G209:L209) -> 1
A210: Carolina Panthers | B210: No | C210: 19 | D210: CAR | E210: DST | F210: =vlookup(D210,'Team Bye List'!$A$1:$B$33,2,False) -> 13 | G210: =if(ISNA(vlookup($A210, Sleeper!$B$2:$E$330, 4, false)), 0, vlookup($A210, Sleeper!$B$2:$E$330, 4, false)) -> 1 | H210: =if(ISNA(vlookup($A210, ESPN!$B$2:$E$297, 4, false)), 0, vlookup($A210, ESPN!$B$2:$E$297, 4, false)) -> 0 | I210: =if(ISNA(vlookup($A210,'Ultimate Draft Kit'!$B$2:$E$324,4, false)), 0, vlookup($A210,'Ultimate Draft Kit'!$B$2:$E$324, 4, false)) -> 1 | J210: =if(ISNA(vlookup($A210,Rotowire!$B$2:$E$1075,4, false)), 0, vlookup($A210,Rotowire!$B$2:$E$1075, 4, false)) -> 0 | K210: =if(ISNA(vlookup($A210, FantasyPro!$B$2:$E$341,4,false)),0,vlookup($A210,FantasyPro!$B$2:$E$341,4,false)) -> 0 | L210: =if(ISNA(vlookup($A210, FFToolbox!$B$2:$E$414, 4, false)), 0, vlookup($A210, FFToolbox!$B$2:$E$414, 4, false)) -> 0 | M210: =Average(G210:L210) -> 0.33333333 | N210: =max(G210:L210)-min(G210:L210) -> 1
... A222: Wil Lutz | B222: No | C222: 11 | D222: NO | E222: K | F222: =vlookup(D222,'Team Bye List'!$A$1:$B$33,2,False) -> 14 | G222: =if(ISNA(vlookup($A222, Sleeper!$B$2:$E$330, 4, false)), 0, vlookup($A222, Sleeper!$B$2:$E$330, 4, false)) -> 1 | H222: =if(ISNA(vlookup($A222, ESPN!$B$2:$E$297, 4, false)), 0, vlookup($A222, ESPN!$B$2:$E$297, 4, false)) -> 0 | I222: =if(ISNA(vlookup($A222,'Ultimate Draft Kit'!$B$2:$E$324,4, false)), 0, vlookup($A222,'Ultimate Draft Kit'!$B$2:$E$324, 4, false)) -> 1 | J222: =if(ISNA(vlookup($A222,Rotowire!$B$2:$E$1075,4, false)), 0, vlookup($A222,Rotowire!$B$2:$E$1075, 4, false)) -> 0 | K222: =if(ISNA(vlookup($A222, FantasyPro!$B$2:$E$341,4,false)),0,vlookup($A222,FantasyPro!$B$2:$E$341,4,false)) -> 0 | L222: =if(ISNA(vlookup($A222, FFToolbox!$B$2:$E$414, 4, false)), 0, vlookup($A222, FFToolbox!$B$2:$E$414, 4, false)) -> 1 | M222: =Average(G222:L222) -> 0.5 | N222: =max(G222:L222)-min(G222:L222) -> 1
A223: Greg Zuerlein | B223: No | C223: NR | D223: NYJ | E223: K | F223: =vlookup(D223,'Team Bye List'!$A$1:$B$33,2,False) -> 10 | G223: =if(ISNA(vlookup($A223, Sleeper!$B$2:$E$330, 4, false)), 0, vlookup($A223, Sleeper!$B$2:$E$330, 4, false)) -> 1 | H223: =if(ISNA(vlookup($A223, ESPN!$B$2:$E$297, 4, false)), 0, vlookup($A223, ESPN!$B$2:$E$297, 4, false)) -> 0 | I223: =if(ISNA(vlookup($A223,'Ultimate Draft Kit'!$B$2:$E$324,4, false)), 0, vlookup($A223,'Ultimate Draft Kit'!$B$2:$E$324, 4, false)) -> 1 | J223: =if(ISNA(vlookup($A223,Rotowire!$B$2:$E$1075,4, false)), 0, vlookup($A223,Rotowire!$B$2:$E$1075, 4, false)) -> 0 | K223: =if(ISNA(vlookup($A223, FantasyPro!$B$2:$E$341,4,false)),0,vlookup($A223,FantasyPro!$B$2:$E$341,4,false)) -> 0 | L223: =if(ISNA(vlookup($A223, FFToolbox!$B$2:$E$414, 4, false)), 0, vlookup($A223, FFToolbox!$B$2:$E$414, 4, false)) -> 0 | M223: =Average(G223:L223) -> 0.33333333 | N223: =max(G223:L223)-min(G223:L223) -> 1
A224: Rodrigo Blankenship | B224: No | C224: 18 | D224: IND | E224: K | F224: =vlookup(D224,'Team Bye List'!$A$1:$B$33,2,False) -> 14 | G224: =if(ISNA(vlookup($A224, Sleeper!$B$2:$E$330, 4, false)), 0, vlookup($A224, Sleeper!$B$2:$E$330, 4, false)) -> 1 | H224: =if(ISNA(vlookup($A224, ESPN!$B$2:$E$297, 4, false)), 0, vlookup($A224, ESPN!$B$2:$E$297, 4, false)) -> 0 | I224: =if(ISNA(vlookup($A224,'Ultimate Draft Kit'!$B$2:$E$324,4, false)), 0, vlookup($A224,'Ultimate Draft Kit'!$B$2:$E$324, 4, false)) -> 1 | J224: =if(ISNA(vlookup($A224,Rotowire!$B$2:$E$1075,4, false)), 0, vlookup($A224,Rotowire!$B$2:$E$1075, 4, false)) -> 0 | K224: =if(ISNA(vlookup($A224, FantasyPro!$B$2:$E$341,4,false)),0,vlookup($A224,FantasyPro!$B$2:$E$341,4,false)) -> 0 | L224: =if(ISNA(vlookup($A224, FFToolbox!$B$2:$E$414, 4, false)), 0, vlookup($A224, FFToolbox!$B$2:$E$414, 4, false)) -> 1 | M224: =Average(G224:L224) -> 0.5 | N224: =max(G224:L224)-min(G224:L224) -> 1
A225: Cairo Santos | B225: No | C225: 28 | D225: CHI | E225: K | F225: =vlookup(D225,'Team Bye List'!$A$1:$B$33,2,False) -> 14 | G225: =if(ISNA(vlookup($A225, Sleeper!$B$2:$E$330, 4, false)), 0, vlookup($A225, Sleeper!$B$2:$E$330, 4, false)) -> 1 | H225: =if(ISNA(vlookup($A225, ESPN!$B$2:$E$297, 4, false)), 0, vlookup($A225, ESPN!$B$2:$E$297, 4, false)) -> 0 | I225: =if(ISNA(vlookup($A225,'Ultimate Draft Kit'!$B$2:$E$324,4, false)), 0, vlookup($A225,'Ultimate Draft Kit'!$B$2:$E$324, 4, false)) -> 1 | J225: =if(ISNA(vlookup($A225,Rotowire!$B$2:$E$1075,4, false)), 0, vlookup($A225,Rotowire!$B$2:$E$1075, 4, false)) -> 0 | K225: =if(ISNA(vlookup($A225, FantasyPro!$B$2:$E$341,4,false)),0,vlookup($A225,FantasyPro!$B$2:$E$341,4,false)) -> 0 | L225: =if(ISNA(vlookup($A225, FFToolbox!$B$2:$E$414, 4, false)), 0, vlookup($A225, FFToolbox!$B$2:$E$414, 4, false)) -> 1 | M225: =Average(G225:L225) -> 0.5 | N225: =max(G225:L225)-min(G225:L225) -> 1
A226: Jason Myers | B226: No | C226: 27 | D226: SEA | E226: K | F226: =vlookup(D226,'Team Bye List'!$A$1:$B$33,2,False) -> 9 | G226: =if(ISNA(vlookup($A226, Sleeper!$B$2:$E$330, 4, false)), 0, vlookup($A226, Sleeper!$B$2:$E$330, 4, false)) -> 1 | H226: =if(ISNA(vlookup($A226, ESPN!$B$2:$E$297, 4, false)), 0, vlookup($A226, ESPN!$B$2:$E$297, 4, false)) -> 0 | I226: =if(ISNA(vlookup($A226,'Ultimate Draft Kit'!$B$2:$E$324,4, false)), 0, vlookup($A226,'Ultimate Draft Kit'!$B$2:$E$324, 4, false)) -> 1 | J226: =if(ISNA(vlookup($A226,Rotowire!$B$2:$E$1075,4, false)), 0, vlookup($A226,Rotowire!$B$2:$E$1075, 4, false)) -> 0 | K226: =if(ISNA(vlookup($A226, FantasyPro!$B$2:$E$341,4,false)),0,vlookup($A226,FantasyPro!$B$2:$E$341,4,false)) -> 0 | L226: =if(ISNA(vlookup($A226, FFToolbox!$B$2:$E$414, 4, false)), 0, vlookup($A226, FFToolbox!$B$2:$E$414, 4, false)) -> 0 | M226: =Average(G226:L226) -> 0.33333333 | N226: =max(G226:L226)-min(G226:L226) -> 1
...

Sheet Players We Want
A1: Veterans | L1: =200-L20 -> 10
A2: Name | B2: Tier | C2: Team | D2: Position | E2: Bye Week | F2: Keeper Price | G2: Avg Price | H2: Max Bid | J2: Position | K2: Name | L2: Amount | M2: Bye | N2: Tier
J3: QB1 | K3: Josh Allen | L3: 25 | M3: 7 | N3: 1
J4: RB1 | K4: Cam Akers | L4: 20
J5: WR1 | K5: Tyreek Hill | L5: 27
J6: WR2 | K6: JuJu Smith-Schuster | L6: 12 | P6: Get big WR (Tier 1-2) | Q6: $20-$30 range
J7: TE | K7: TJ Hockenson | L7: 10
J8: RB2 | K8: JK Dobbins | L8: 17
J9: D/ST | K9: San Francisco | L9: 4
J10: K | K10: Matt Gay | L10: 3
J11: RB3 | K11: Elijah Mitchell | L11: 17
J12: RB4 | K12: James Cook | L12: 7
J13: QB1 | K13: Tom Brady | L13: 10
J14: RB5 | K14: Rashaad Penny | L14: 10
J15: D/ST | K15: IND DST | L15: 2
J16: WR3 | K16: Drake London | L16: 8
J17: WR4 | K17: Christian Kirk | L17: 12 | P17: Go D/ST 1st
J18: RB6 | K18: Devin Singletary | L18: 6
L20: =sum(L3:L18) -> 190 | N20: =average(N3:N18) -> 1
B43: =vlookup(A43,Masterview!A$2:N$1075, 3, False) -> #N/A | C43: =vlookup(A43,Masterview!A$2:N$1075, 4, False) -> #N/A | D43: =vlookup(A43,Masterview!A$2:N$1075,5, False) -> #N/A | E43: =vlookup(A43,Masterview!A$2:N$1075,6, False) -> #N/A | G43: =vlookup(A43,Masterview!A$2:N$928, 10, False) -> #N/A

Sheet Team Bye List
A1: Team | B1: Bye Week
A2: ARI | B2: 13
A3: ATL | B3: 14
A4: BAL | B4: 10
A5: BUF | B5: 7
A6: CAR | B6: 13
A7: CHI | B7: 14
A8: CIN | B8: 10
A9: CLE | B9: 9
A10: DAL | B10: 9
A11: DEN | B11: 9
A12: DET | B12: 6
A13: GB | B13: 14
... A33: WAS | B33: 14

Sheet Keepers
A1: Name | B1: Pos | C1: Value
A2: Josh Allen | B2: =VLOOKUP(A2, Rotowire!$B$1:$E$545, 3, FALSE) -> QB | C2: 25
A3: Jaylen Waddle | B3: WR | C3: 14
A4: Mark Andrews | B4: =VLOOKUP(A4, Rotowire!$B$1:$E$545, 3, FALSE) -> TE | C4: 30
A5: Austin Ekeler | B5: =VLOOKUP(A5, Rotowire!$B$1:$E$545, 3, FALSE) -> RB | C5: 50
A6: CeeDee Lamb | B6: =VLOOKUP(A6, Rotowire!$B$1:$E$545, 3, FALSE) -> WR | C6: 23
A7: Kyle Pitts | B7: =VLOOKUP(A7, Rotowire!$B$1:$E$545, 3, FALSE) -> TE | C7: 33
A8: Leonard Fournette | B8: =VLOOKUP(A8, Rotowire!$B$1:$E$545, 3, FALSE) -> RB | C8: 23
A9: Mike Williams | B9: =VLOOKUP(A9, Rotowire!$B$1:$E$545, 3, FALSE) -> WR | C9: 20
A10: Justin Herbert | B10: =VLOOKUP(A10, Rotowire!$B$1:$E$545, 3, FALSE) -> QB | C10: 22
A11: Ja'Marr Chase | B11: =VLOOKUP(A11, Rotowire!$B$1:$E$545, 3, FALSE) -> WR | C11: 17
A12: Joe Burrow | B12: =VLOOKUP(A12, Rotowire!$B$1:$E$545, 3, FALSE) -> QB | C12: 13
A13: Derrick Henry | B13: =VLOOKUP(A13, Rotowire!$B$1:$E$545, 3, FALSE) -> RB | C13: 50
A14: Tee Higgins | B14: =VLOOKUP(A14, Rotowire!$B$1:$E$545, 3, FALSE) -> WR | C14: 28
A15: Cooper Kupp | B15: =VLOOKUP(A15, Rotowire!$B$1:$E$545, 3, FALSE) -> WR | C15: 33
... A22: Stefon Diggs | B22: =VLOOKUP(A22, Rotowire!$B$1:$E$545, 3, FALSE) -> WR | C22: 34

Sheet Player Name
A1: Name | B1: Team | C1: Pos
A2: A.J. Brown | B2: WR | C2: PHI
A3: A.J. Green | B3: WR | C3: ARZ
A4: Aaron Fuller | B4: WR | C4: SEA
A5: Aaron Jones | B5: RB | C5: GB
A6: Aaron Rodgers | B6: QB | C6: GB
A7: Adam Humphries | B7: WR | C7: FA
A8: Adam Prentice | B8: RB | C8: NO
A9: Adam Shaheen | B9: TE | C9: MIA
A10: Adam Thielen | B10: WR | C10: MIN
A11: Adam Trautman | B11: TE | C11: NO
A12: Adrian Killins | B12: RB | C12: FA
... A1076: Zonovan Knight | B1076: RB | C1076: NYJ
