Workbook

Sheet Contact Details
A1: Name | B1: Cell
A2: Ray Long | B2: (804) 647-1100 | C2: Co-Owners
A3: Jeffrey Hudgins | B3: (404) 931-8499
A4: Doug Fordham | B4: (908) 303-8965
A5: Rashad Gresham | B5: (804) 647-5495
A6: Dave Besedich | B6: (615) 557-4118
A7: Jordan Maslyn | B7: (949) 235-2486 | C7: Co-Owners
A8: Landon Elliott | B8: (252) 2020-5263
A9: Stan Schoppe | B9: (540) 413-6532
A10: Aaron Hawkins | B10: (434) 282-3654
A11: Brian Stevens | B11: (614) 565-8100
A12: Travis Miller | B12: (804) 399-1599
A13: Wade Cameron | B13: (804) 698-0260
A14: JD Dowling | B14: (917) 482-1170
A15: Tommy Moore | B15: (318) 464-0061

Sheet Sheet20
G6: Owner Name | H6: Total Paid Out | I6: Total Won | J6: Net (Won or Loss)
G7: Tommy | H7: 500 | I7: 1060 | J7: 560
G8: David | H8: 350 | I8: 670 | J8: 320
G9: Minnix | H9: 100 | I9: 245 | J9: 145
G10: JD | H10: 500 | I10: 635 | J10: 135
G11: Adam | H11: 100 | I11: 105 | J11: 5
G12: Gordie | H12: 50 | I12: 50 | J12: 0
G13: Brian | H13: 500 | I13: 490 | J13: -10
G14: Patrick | H14: 100 | I14: 80 | J14: -20
G15: Jordan | H15: 450 | I15: 425 | J15: -25
G16: Ricky | H16: 50 | I16: 0 | J16: -50
G17: Stan | H17: 50 | I17: 0 | J17: -50
G18: Aaron | H18: 50 | I18: 0 | J18: -50
... G28: Travis | H28: 500 | I28: 195 | J28: -305

Sheet Paid_Earnings
A1: Year/Metric | B1: Tommy | C1: David | D1: Jordan | E1: JD | F1: Aaron | G1: Rashad | H1: Brian | I1: Wade | J1: Travis | K1: Ray | L1: Doug | M1: Stan | N1: Billy | O1: Landon | P1: Adam | Q1: Patrick | R1: Chris | S1: Ricky | T1: Garet | U1: Minnix | V1: Gordie | W1: Bryan
A2: 2025 Paid | B2: 50 | C2: 50 | D2: 50 | E2: 50 | F2: 50 | G2: 50 | H2: 50 | I2: 50 | J2: 50 | K2: 50 | L2: 50 | M2: 50 | N2: 0 | O2: 0 | P2: 0 | Q2: 0 | R2: 0 | S2: 0 | T2: 0 | U2: 0 | V2: 0 | W2: 0
A3: 2025 Won | B3: 10 | C3: 30 | D3: 10 | E3: 30 | F3: 0 | G3: 10 | H3: 10 | I3: 0 | J3: 10 | K3: 0 | L3: 0 | M3: 0 | N3: 0 | O3: 0 | P3: 0 | Q3: 0 | R3: 0 | S3: 0 | T3: 0 | U3: 0 | V3: 0 | W3: 0
A4: 2024 Paid | B4: 50 | C4: 50 | D4: 50 | E4: 50 | F4: 0 | G4: 50 | H4: 50 | I4: 50 | J4: 50 | K4: 50 | L4: 50 | M4: 0 | N4: 50 | O4: 50 | P4: 0 | Q4: 0 | R4: 0 | S4: 0 | T4: 0 | U4: 0 | V4: 0 | W4: 0
A5: 2024 Won | B5: 20 | C5: 80 | D5: 250 | E5: 10 | F5: 0 | G5: 0 | H5: 0 | I5: 110 | J5: 0 | K5: 0 | L5: 125 | M5: 0 | N5: 0 | O5: 0 | P5: 0 | Q5: 0 | R5: 0 | S5: 0 | T5: 0 | U5: 0 | V5: 0 | W5: 0
A6: 2023 Paid | B6: 50 | C6: 50 | D6: 50 | E6: 50 | F6: 0 | G6: 50 | H6: 50 | I6: 50 | J6: 50 | K6: 50 | L6: 50 | M6: 0 | N6: 50 | O6: 50 | P6: 0 | Q6: 0 | R6: 0 | S6: 0 | T6: 0 | U6: 0 | V6: 0 | W6: 0
A7: 2023 Won | B7: 240 | C7: 10 | D7: 0 | E7: 80 | F7: 0 | G7: 0 | H7: 110 | I7: 0 | J7: 40 | K7: 105 | L7: 0 | M7: 0 | N7: 10 | O7: 0 | P7: 0 | Q7: 0 | R7: 0 | S7: 0 | T7: 0 | U7: 0 | V7: 0 | W7: 0
A8: 2022 Paid | B8: 50 | C8: 50 | D8: 50 | E8: 50 | F8: 0 | G8: 50 | H8: 50 | I8: 50 | J8: 50 | K8: 50 | L8: 50 | M8: 0 | N8: 50 | O8: 50 | P8: 0 | Q8: 0 | R8: 0 | S8: 0 | T8: 0 | U8: 0 | V8: 0 | W8: 0
A9: 2022 Won | B9: 195 | C9: 215 | D9: 0 | E9: 0 | F9: 0 | G9: 0 | H9: 50 | I9: 0 | J9: 0 | K9: 35 | L9: 20 | M9: 0 | N9: 45 | O9: 10 | P9: 0 | Q9: 0 | R9: 0 | S9: 0 | T9: 0 | U9: 0 | V9: 0 | W9: 0
A10: 2021 Paid | B10: 50 | C10: 50 | D10: 50 | E10: 50 | F10: 0 | G10: 0 | H10: 50 | I10: 50 | J10: 50 | K10: 50 | L10: 50 | M10: 0 | N10: 50 | O10: 50 | P10: 50 | Q10: 0 | R10: 0 | S10: 0 | T10: 0 | U10: 0 | V10: 0 | W10: 0
A11: 2021 Won | B11: 10 | C11: 230 | D11: 10 | E11: 110 | F11: 0 | G11: 0 | H11: 20 | I11: 25 | J11: 0 | K11: 20 | L11: 10 | M11: 0 | N11: 35 | O11: 20 | P11: 105 | Q11: 0 | R11: 0 | S11: 0 | T11: 0 | U11: 0 | V11: 0 | W11: 0
A12: 2020 Paid | B12: 50 | C12: 50 | D12: 50 | E12: 50 | F12: 0 | G12: 0 | H12: 50 | I12: 50 | J12: 50 | K12: 50 | L12: 50 | M12: 0 | N12: 50 | O12: 50 | P12: 50 | Q12: 0 | R12: 0 | S12: 0 | T12: 0 | U12: 0 | V12: 0 | W12: 0
A13: 2020 Won | B13: 0 | C13: 105 | D13: 45 | E13: 240 | F13: 0 | G13: 0 | H13: 45 | I13: 10 | J13: 0 | K13: 40 | L13: 0 | M13: 0 | N13: 0 | O13: 100 | P13: 0 | Q13: 0 | R13: 0 | S13: 0 | T13: 0 | U13: 0 | V13: 0 | W13: 0
... A21: 2016 Won | B21: 245 | C21: 0 | D21: 0 | E21: 0 | F21: 0 | G21: 0 | H21: 0 | I21: 30 | J21: 15 | K21: 65 | L21: 0 | M21: 0 | N21: 0 | O21: 15 | P21: 0 | Q21: 0 | R21: 0 | S21: 0 | T21: 0 | U21: 180 | V21: 50 | W21: 0
B24: Tommy | C24: David | D24: Jordan | E24: JD | F24: Aaron | G24: Rashad | H24: Brian | I24: Wade | J24: Travis | K24: Ray | L24: Doug | M24: Stan | N24: Billy | O24: Landon | P24: Adam | Q24: Patrick | R24: Chris | S24: Ricky | T24: Garet | U24: Minnix | V24: Gordie | W24: Bryan
A25: Total Paid | B25: =sum(B2,B4,B6,B8,B10,B12,B14,B16,B18,B20) -> 500 | C25: =sum(C2,C4,C6,C8,C10,C12,C14,C16,C18,C20) -> 350 | D25: =sum(D2,D4,D6,D8,D10,D12,D14,D16,D18,D20) -> 450 | E25: =sum(E2,E4,E6,E8,E10,E12,E14,E16,E18,E20) -> 500 | F25: =sum(F2,F4,F6,F8,F10,F12,F14,F16,F18,F20) -> 50 | G25: =sum(G2,G4,G6,G8,G10,G12,G14,G16,G18,G20) -> 200 | H25: =sum(H2,H4,H6,H8,H10,H12,H14,H16,H18,H20) -> 500 | I25: =sum(I2,I4,I6,I8,I10,I12,I14,I16,I18,I20) -> 500 | ... W25: =sum(W2,W4,W6,W8,W10,W12,W14,W16,W18,W20) -> 50
A26: Total Won | B26: =sum(B3,B5,B7,B9,B11,B13,B15,B17,B19,B21) -> 1060 | C26: =sum(C3,C5,C7,C9,C11,C13,C15,C17,C19,C21) -> 670 | D26: =sum(D3,D5,D7,D9,D11,D13,D15,D17,D19,D21) -> 425 | E26: =sum(E3,E5,E7,E9,E11,E13,E15,E17,E19,E21) -> 635 | F26: =sum(F3,F5,F7,F9,F11,F13,F15,F17,F19,F21) -> 0 | G26: =sum(G3,G5,G7,G9,G11,G13,G15,G17,G19,G21) -> 10 | H26: =sum(H3,H5,H7,H9,H11,H13,H15,H17,H19,H21) -> 490 | I26: =sum(I3,I5,I7,I9,I11,I13,I15,I17,I19,I21) -> 380 | ... W26: =sum(W3,W5,W7,W9,W11,W13,W15,W17,W19,W21) -> 0
A27: Earnings | B27: =B26-B25 -> 560 | C27: =C26-C25 -> 320 | D27: =D26-D25 -> -25 | E27: =E26-E25 -> 135 | F27: =F26-F25 -> -50 | G27: =G26-G25 -> -190 | H27: =H26-H25 -> -10 | I27: =I26-I25 -> -120 | ... W27: =W26-W25 -> -50

Sheet Past Standings
A1: Place | B1: 2030 | C1: 2029 | D1: 2028 | E1: 2027 | F1: 2026 | G1: 2025 | H1: 2024 | I1: 2023 | J1: 2022 | K1: 2021 | L1: 2020 | M1: 2019 | N1: 2018 | O1: 2017 | P1: 2016 | Q1: 2015 | R1: 2014 | S1: 2013 | T1: 2012 | U1: 2011
A2: 1 | G2: Aaron | H2: Jordan | I2: Tommy | J2: Tommy | K2: Dave | L2: JD | M2: Wade | N2: Brian | O2: Tommy | P2: Tommy | Q2: Keith | R2: Garet | S2: Tommy | T2: Bryan | U2: Gordie
A3: 2 | G3: Travis | H3: Wade | I3: Brian | J3: Dave | K3: JD | L3: Landon | M3: Travis | N3: Tommy | O3: JD | P3: James | Q3: JD | R3: Gordie | S3: James | T3: Chris | U3: Wade
A4: 3 | G4: JD | H4: Doug | I4: Ray | J4: Brian | K4: Adam | L4: Dave | M4: Brian | N4: Ray | O4: James | P4: Ray | Q4: Tommy | R4: Keith | S4: Bryan | T4: Nicholas | U4: Zach
A5: 4 | G5: Dave | H5: Dave | I5: JD | J5: Billy | K5: Wade | L5: Brian | M5: Patrick | N5: Jordan | O5: Travis | P5: Gordie | Q5: Chris | R5: Chris | S5: Landon | T5: James | U5: Keith
A6: 5 | G6: Rashad | H6: JD | I6: Billy | J6: Landon | K6: Landon | L6: Ray | M6: Ray | N6: Chris | O6: Jordan | P6: Landon | Q6: Garet | R6: Bryan | S6: Chris | T6: Tommy | U6: JD
A7: 6 | G7: Stan | H7: Tommy | I7: Travis | J7: Doug | K7: Doug | L7: Doug | M7: Dave | N7: Wade | O7: Ray | P7: Chris | Q7: Ray | R7: Travis | S7: Keith | T7: Landon | U7: Bryan
A8: 7 | G8: Tommy | H8: Travis | I8: Wade | J8: Ray | K8: Billy | L8: Jordan | M8: Landon | N8: Patrick | O8: Garet | P8: Bryan | Q8: James | R8: James | S8: JD | T8: Gordie | U8: Chris
A9: 8 | G9: Jordan | H9: Ray | I9: Dave | J9: Travis | K9: Tommy | L9: Wade | M9: Billy | N9: JD | O9: Landon | P9: JD | Q9: Wade | R9: Wade | S9: Garet | T9: Wade | U9: Ray
A10: 9 | G10: Brian | H10: Landon | I10: Doug | J10: Wade | K10: Travis | L10: Adam | M10: Jordan | N10: Ricky | O10: Patrick | P10: Travis | Q10: Landon | R10: JD | S10: Gordie | T10: Travis | U10: Darren
A11: 10 | G11: Doug | H11: Billy | I11: Rashad | J11: Rashad | K11: Ray | L11: Billy | M11: JD | N11: Billy | O11: Wade | P11: Brian | Q11: Gordie | R11: Ray | S11: Ray | T11: Darren | U11: Rachel
A12: 11 | G12: Wade | H12: Brian | I12: Jordan | J12: Jordan | K12: Brian | L12: Travis | M12: Doug | N12: Travis | O12: Chris | P12: Garet | Q12: Bryan | R12: Tommy | S12: Wade | T12: JD
A13: 12 | G13: Ray | H13: Rashad | I13: Landon | J13: JD | K13: Jordan | L13: Tommy | M13: Tommy | N13: Landon | O13: Brian | P13: Wade | Q13: Travis | R13: Landon | S13: Travis | T13: Zach
A16: Name | B16: Years Involved | C16: Avg Finish | D16: Playoff Appearance | E16: Champs | F16: % to Win | G16: Avg. High Score | K16: Names | L16: 2030 | M16: 2029 | N16: 2028 | O16: 2027 | P16: 2026 | Q16: 2025 | R16: 2024 | S16: 2023 | T16: 2022 | U16: 2021 | V16: 2020 | W16: 2019 | X16: 2018 | Y16: 2017 | Z16: 2016 | AA16: 2015 | AB16: 2014 | AC16: 2013 | AD16: 2012 | AE16: 2011 | AF16: Average
A17: Wade | B17: 15 | C17: =AF17 -> 7.1333333 | D17: 5 | E17: 1 | F17: =E17/B17 -> 0.066666667 | G17: =vlookup(A17,DougMath!$A$2:$B$23,2,FALSE) -> 1.1 | K17: Wade | Q17: 11 | R17: 2 | S17: 7 | T17: 9 | U17: 4 | V17: 8 | W17: 1 | X17: 6 | Y17: 10 | Z17: 12 | AA17: 8 | AB17: 8 | AC17: 11 | AD17: 8 | AE17: 2 | AF17: =AVERAGE(Q17:AE17) -> 7.1333333
A18: Travis | B18: 14 | C18: =AF22 -> 7.7142857 | D18: 5 | E18: 0 | F18: =E18/B18 -> 0 | G18: =vlookup(A18,DougMath!$A$2:$B$23,2,FALSE) -> 0.8 | K18: Ray/Jeffrey | Q18: 12 | R18: 8 | S18: 3 | T18: 7 | U18: 10 | V18: 5 | W18: 5 | X18: 3 | Y18: 6 | Z18: 3 | AA18: 6 | AB18: 10 | AC18: 10 | AE18: 8 | AF18: =AVERAGE(Q18:AE18) -> 6.8571429
A19: Stan | B19: 1 | C19: =AF21 -> 6 | D19: 1 | E19: 0 | F19: =E19/B19 -> 0 | G19: =vlookup(A19,DougMath!$A$2:$B$23,2,FALSE) -> 0.11111111 | K19: Tommy | Q19: 7 | R19: 6 | S19: 1 | T19: 1 | U19: 8 | V19: 12 | W19: 12 | X19: 2 | Y19: 1 | Z19: 1 | AA19: 3 | AB19: 11 | AC19: 1 | AD19: 5 | AE19: ? | AF19: =AVERAGE(Q19:AE19) -> 5.0714286
A20: JD | B20: 15 | C20: =AF20 -> 5.9333333 | D20: 7 | E20: 1 | F20: =E20/B20 -> 0.066666667 | G20: =vlookup(A20,DougMath!$A$2:$B$23,2,FALSE) -> 1.2 | K20: JD | Q20: 3 | R20: 5 | S20: 4 | T20: 12 | U20: 2 | V20: 1 | W20: 10 | X20: 8 | Y20: 2 | Z20: 8 | AA20: 2 | AB20: 9 | AC20: 7 | AD20: 11 | AE20: 5 | AF20: =AVERAGE(Q20:AE20) -> 5.9333333
A21: Ray/Jeffrey | B21: 14 | C21: =AF18 -> 6.8571429 | D21: 7 | E21: 0 | F21: =E21/B21 -> 0 | G21: =vlookup(A21,DougMath!$A$2:$B$23,2,FALSE) -> 1.4 | K21: Stan | Q21: 6 | AE21: ? | AF21: =AVERAGE(Q21:AE21) -> 6
A22: Tommy | B22: 14 | C22: =AF19 -> 5.0714286 | D22: 9 | E22: 5 | F22: =E22/B22 -> 0.35714286 | G22: =vlookup(A22,DougMath!$A$2:$B$23,2,FALSE) -> 1.3 | K22: Travis | Q22: 2 | R22: 7 | S22: 6 | T22: 8 | U22: 9 | V22: 11 | W22: 2 | X22: 11 | Y22: 4 | Z22: 9 | AA22: 12 | AB22: 6 | AC22: 12 | AD22: 9 | AF22: =AVERAGE(Q22:AE22) -> 7.7142857
A23: Brian | B23: 10 | C23: =AF23 -> 6.6 | D23: 5 | E23: 1 | F23: =E23/B23 -> 0.1 | G23: =vlookup(A23,DougMath!$A$2:$B$23,2,FALSE) -> 1.4444444 | K23: Brian | Q23: 9 | R23: 11 | S23: 2 | T23: 3 | U23: 11 | V23: 4 | W23: 3 | X23: 1 | Y23: 12 | Z23: 10 | AF23: =AVERAGE(Q23:AE23) -> 6.6
A24: Jordan | B24: 9 | C24: =AF24 -> 7.5555556 | D24: 3 | E24: 1 | F24: =E24/B24 -> 0.11111111 | G24: =vlookup(A24,DougMath!$A$2:$B$23,2,FALSE) -> 1.1 | K24: Jordan | Q24: 8 | R24: 1 | S24: 11 | T24: 11 | U24: 12 | V24: 7 | W24: 9 | X24: 4 | Y24: 5 | AF24: =AVERAGE(Q24:AE24) -> 7.5555556
A25: Dave | B25: 7 | C25: =AF25 -> 3.8571429 | D25: 6 | E25: 2 | F25: =E25/B25 -> 0.28571429 | G25: =vlookup(A25,DougMath!$A$2:$B$23,2,FALSE) -> 1.4 | K25: Dave | Q25: 4 | R25: 4 | S25: 8 | T25: 1 | U25: 1 | V25: 3 | W25: 6 | AF25: =AVERAGE(Q25:AE25) -> 3.8571429
A26: Doug | B26: 7 | C26: =AF26 -> 7.2857143 | D26: 4 | E26: 0 | F26: =E26/B26 -> 0 | G26: =vlookup(A26,DougMath!$A$2:$B$23,2,FALSE) -> 0.8 | K26: Doug | Q26: 10 | R26: 3 | S26: 9 | T26: 6 | U26: 6 | V26: 6 | W26: 11 | AF26: =AVERAGE(Q26:AE26) -> 7.2857143
A27: Rashad | B27: 4 | C27: =AF27 -> 9.25 | D27: 1 | E27: 0 | F27: =E27/B27 -> 0 | G27: =vlookup(A27,DougMath!$A$2:$B$23,2,FALSE) -> 0.2 | K27: Rashad | Q27: 5 | R27: 12 | S27: 10 | T27: 10 | AF27: =AVERAGE(Q27:AE27) -> 9.25
A28: Aaron | B28: 1 | C28: =AF28 -> 1 | D28: 1 | E28: 1 | F28: =E28/B28 -> 1 | G28: =vlookup(A28,DougMath!$A$2:$B$23,2,FALSE) -> 0 | K28: Aaron | Q28: 1 | AF28: =AVERAGE(Q28:AE28) -> 1
A29: Total | B29: =AVERAGE(B17:B28) -> 9.25 | C29: =AVERAGE(C17:C28) -> 6.1881614 | D29: =AVERAGE(D17:D28) -> 4.5 | E29: =SUM(E17:E28) -> 12 | F29: =AVERAGE(F17:F28) -> 0.16560847
A30: Billy | B30: 7 | C30: 7.71 | D30: 2 | E30: 0 | F30: =E30/B30 -> 0 | G30: =vlookup(A30,DougMath!$A$2:$B$23,2,FALSE) -> 0.77777778
A31: Chris | B31: 8 | C31: 5.5 | D31: 6 | E31: 0 | F31: =E31/B31 -> 0 | G31: =vlookup(A31,DougMath!$A$2:$B$23,2,FALSE) -> 0.25
A32: Adam | B32: 2 | C32: 6 | D32: 1 | E32: 0 | F32: =E32/B32 -> 0 | G32: =vlookup(A32,DougMath!$A$2:$B$23,2,FALSE) -> 0.5
A33: Bryan | B33: 6 | C33: 5.5 | D33: 3 | E33: 1 | F33: =E33/B33 -> 0.16666667 | G33: =vlookup(A33,DougMath!$A$2:$B$23,2,FALSE) -> 0
A34: Gordie | B34: 6 | C34: 5.5 | D34: 3 | E34: 1 | F34: =E34/B34 -> 0.16666667 | G34: =vlookup(A34,DougMath!$A$2:$B$23,2,FALSE) -> 0
A35: James | B35: 6 | C35: 4.33 | D35: 4 | E35: 0 | F35: =E35/B35 -> 0 | G35: =vlookup(A35,DougMath!$A$2:$B$23,2,FALSE) -> 0.75
A36: Garet | B36: 5 | C36: 6.4 | D36: 2 | E36: 1 | F36: =E36/B36 -> 0.2 | G36: =vlookup(A36,DougMath!$A$2:$B$23,2,FALSE) -> 0.125
A37: Landon | B37: 13 | C37: 6.84 | D37: 6 | E37: 0 | F37: =E37/B37 -> 0 | G37: =vlookup(A37,DougMath!$A$2:$B$23,2,FALSE) -> 0.375
A38: Keith | B38: 4 | C38: 3.5 | D38: 3 | E38: 1 | F38: =E38/B38 -> 0.25
A39: Patrick | B39: 3 | C39: 6.67 | D39: 1 | E39: 0 | F39: =E39/B39 -> 0 | G39: =vlookup(A39,DougMath!$A$2:$B$23,2,FALSE) -> 0.375
A40: Zach | B40: 2 | C40: 7.5 | D40: 1 | E40: 0 | F40: =E40/B40 -> 0
A41: Daren | B41: 2 | C41: 10 | D41: 0 | E41: 0 | F41: =E41/B41 -> 0
A42: Nicholas | B42: 1 | C42: 3 | D42: 1 | E42: 0 | F42: =E42/B42 -> 0
...

Sheet DougMath
A1: Owner | B1: Avg | C1: 2025 | D1: 2024 | E1: 2023 | F1: 2022 | G1: 2021 | H1: 2020 | I1: 2019 | J1: 2018 | K1: 2017 | L1: 2016
A2: Tommy | B2: =average(C2:L2) -> 1.3 | C2: 1 | D2: 2 | E2: 1 | F2: 2 | G2: 1 | H2: 0 | I2: 1 | J2: 1 | K2: 1 | L2: 3
A3: Dave | B3: =average(C3:L3) -> 1.4 | C3: 3 | D3: 3 | E3: 1 | F3: 4 | G3: 0 | H3: 3 | I3: 0 | J3: 0 | K3: 0 | L3: 0
A4: Jordan | B4: =average(C4:L4) -> 1.1 | C4: 2 | D4: 2 | E4: 0 | F4: 0 | G4: 1 | H4: 2 | I4: 0 | J4: 3 | K4: 1 | L4: 0
A5: JD | B5: =average(C5:L5) -> 1.2 | C5: 3 | D5: 1 | E5: 3 | F5: 0 | G5: 1 | H5: 0 | I5: 0 | J5: 1 | K5: 3 | L5: 0
A6: Stan | B6: =average(C6:L6) -> 0.11111111 | C6: 1 | E6: 0 | F6: 0 | G6: 0 | H6: 0 | I6: 0 | J6: 0 | K6: 0 | L6: 0
A7: Rashad | B7: =average(C7:L7) -> 0.2 | C7: 2 | D7: 0 | E7: 0 | F7: 0 | G7: 0 | H7: 0 | I7: 0 | J7: 0 | K7: 0 | L7: 0
A8: Brian | B8: =average(C8:L8) -> 1.4444444 | C8: 1 | D8: 0 | E8: 1 | F8: 0 | G8: 2 | H8: 2 | I8: 4 | J8: 2 | K8: 1
A9: Wade | B9: =average(C9:L9) -> 1.1 | C9: 0 | D9: 1 | E9: 0 | F9: 0 | G9: 0 | H9: 1 | I9: 3 | J9: 3 | K9: 1 | L9: 2
A10: Travis | B10: =average(C10:L10) -> 0.8 | C10: 1 | D10: 0 | E10: 4 | F10: 0 | G10: 0 | H10: 0 | I10: 1 | J10: 0 | K10: 1 | L10: 1
A11: Ray/Jeffrey | B11: =average(C11:L11) -> 1.4 | C11: 0 | D11: 0 | E11: 3 | F11: 1 | G11: 2 | H11: 4 | I11: 2 | J11: 0 | K11: 1 | L11: 1
A12: Doug | B12: =average(C12:L12) -> 0.8 | C12: 0 | D12: 5 | E12: 0 | F12: 2 | G12: 1 | H12: 0 | I12: 0 | J12: 0 | K12: 0 | L12: 0
A13: Aaron | B13: =average(C13:L13) -> 0 | C13: 0 | E13: 0 | F13: 0 | G13: 0 | H13: 0 | I13: 0 | J13: 0 | K13: 0 | L13: 0
A14: Landon | B14: =average(D14:L14) -> 0.375 | E14: 0 | F14: 0 | G14: 3 | H14: 0 | I14: 0 | J14: 0 | K14: 0 | L14: 0
A15: Adam | B15: =average(E15:L15) -> 0.5 | D15: 0 | E15: 0 | F15: 1 | G15: 2 | H15: 0 | I15: 0 | J15: 0 | K15: 0 | L15: 1
A16: Billy | B16: =average(D16:L16) -> 0.77777778 | D16: 0 | E16: 1 | F16: 2 | G16: 1 | H16: 1 | I16: 1 | J16: 1 | K16: 0 | L16: 0
A17: Patrick | B17: =average(E17:L17) -> 0.375 | E17: 0 | F17: 0 | G17: 0 | H17: 0 | I17: 1 | J17: 1 | K17: 1 | L17: 0
A18: Chris | B18: =average(E18:L18) -> 0.25 | E18: 0 | F18: 0 | G18: 0 | H18: 0 | I18: 0 | J18: 1 | K18: 1 | L18: 0
A19: Ricky | B19: =average(E19:L19) -> 0 | E19: 0 | F19: 0 | G19: 0 | H19: 0 | I19: 0 | J19: 0 | K19: 0 | L19: 0
A20: Garet | B20: =average(E20:L20) -> 0.125 | E20: 0 | F20: 0 | G20: 0 | H20: 0 | I20: 0 | J20: 0 | K20: 1 | L20: 0
A21: James | B21: =average(E21:L21) -> 0.75 | E21: 0 | F21: 0 | G21: 0 | H21: 0 | I21: 0 | J21: 0 | K21: 1 | L21: 5
A22: Gordie | B22: =average(E22:L22) -> 0 | E22: 0 | F22: 0 | G22: 0 | H22: 0 | I22: 0 | J22: 0 | K22: 0 | L22: 0
A23: Bryan | B23: =average(E23:L23) -> 0 | D23: 0 | E23: 0 | F23: 0 | G23: 0 | H23: 0 | I23: 0 | J23: 0 | K23: 0 | L23: 0

Sheet 2025_Payouts
A1: Name | B1: Weekly Payout | C1: Weekly Payout | D1: Division Winners | E1: Champ Ring | F1: 3rd Place | G1: 2nd Place | H1: 1st Place | I1: Amount Won | J1: Entry Fee Paid | K1: Total Earned | T1: Names | U1: Paid | V1: Owes
A2: Tommy | B2: 1 | C2: =10*B2 -> 10 | D2: 0 | E2: 0 | F2: 0 | G2: 0 | H2: 0 | I2: =sum(C2:H2) -> 10 | J2: =V2 -> 0 | K2: =I2-J2 -> 10 | T2: Tommy | U2: 50 | V2: =U2-50 -> 0
A3: David | B3: 3 | C3: =10*B3 -> 30 | D3: 0 | E3: 0 | F3: 0 | G3: 0 | H3: 0 | I3: =sum(C3:H3) -> 30 | J3: =V3 -> 0 | K3: =I3-J3 -> 30 | T3: David | U3: 50 | V3: =U3-50 -> 0
A4: Jordan | B4: 2 | C4: =10*B4 -> 20 | D4: 0 | E4: 0 | F4: 0 | G4: 0 | H4: 0 | I4: =sum(C4:H4) -> 20 | J4: =V4 -> 0 | K4: =I4-J4 -> 20 | T4: Jordan | U4: 50 | V4: =U4-50 -> 0
A5: JD | B5: 3 | C5: =10*B5 -> 30 | D5: 25 | E5: 0 | F5: 50 | G5: 0 | H5: 0 | I5: =sum(C5:H5) -> 105 | J5: =V5 -> 0 | K5: =I5-J5 -> 105 | T5: JD | U5: 50 | V5: =U5-50 -> 0
A6: Aaron | B6: 0 | C6: =10*B6 -> 0 | D6: 25 | E6: 16 | F6: 0 | G6: 0 | H6: 219 | I6: =sum(C6:H6) -> 260 | J6: =V6 -> 0 | K6: =I6-J6 -> 260 | T6: Aaron | U6: 50 | V6: =U6-50 -> 0
A7: Rashad | B7: 2 | C7: =10*B7 -> 20 | D7: 25 | E7: 0 | F7: 0 | G7: 0 | H7: 0 | I7: =sum(C7:H7) -> 45 | J7: =V7 -> 0 | K7: =I7-J7 -> 45 | T7: Rashad | U7: 50 | V7: =U7-50 -> 0
A8: Brian | B8: 1 | C8: =10*B8 -> 10 | D8: 0 | E8: 0 | F8: 0 | G8: 0 | H8: 0 | I8: =sum(C8:H8) -> 10 | J8: =V8 -> 0 | K8: =I8-J8 -> 10 | T8: Brian | U8: 50 | V8: =U8-50 -> 0
A9: Wade | B9: 0 | C9: =10*B9 -> 0 | D9: 0 | E9: 0 | F9: 0 | G9: 0 | H9: 0 | I9: =sum(C9:H9) -> 0 | J9: =V9 -> 0 | K9: =I9-J9 -> 0 | T9: Wade | U9: 50 | V9: =U9-50 -> 0
A10: Travis | B10: 1 | C10: =10*B10 -> 10 | D10: 0 | E10: 0 | F10: 0 | G10: 100 | H10: 0 | I10: =sum(C10:H10) -> 110 | J10: =V10 -> 0 | K10: =I10-J10 -> 110 | T10: Travis | U10: 50 | V10: =U10-50 -> 0
A11: Ray/Jeffrey | B11: 0 | C11: =10*B11 -> 0 | D11: 0 | E11: 0 | F11: 0 | G11: 0 | H11: 0 | I11: =sum(C11:H11) -> 0 | J11: =V11 -> 0 | K11: =I11-J11 -> 0 | T11: Ray/Jeffrey | U11: 50 | V11: =U11-50 -> 0
A12: Doug | B12: 0 | C12: =10*B12 -> 0 | D12: 0 | E12: 0 | F12: 0 | G12: 0 | H12: 0 | I12: =sum(C12:H12) -> 0 | J12: =V12 -> 0 | K12: =I12-J12 -> 0 | T12: Doug | U12: 50 | V12: =U12-50 -> 0
A13: Stan | B13: 1 | C13: =10*B13 -> 10 | D13: 0 | E13: 0 | F13: 0 | G13: 0 | H13: 0 | I13: =sum(C13:H13) -> 10 | J13: =V13 -> 0 | K13: =I13-J13 -> 10 | T13: Stan | U13: 50 | V13: =U13-50 -> 0
C14: =SUM(C2:C13) -> 140 | D14: =SUM(D2:D13) -> 75 | E14: =SUM(E2:E13) -> 16 | F14: =SUM(F2:F13) -> 50 | G14: =SUM(G2:G13) -> 100 | H14: =SUM(H2:H13) -> 219 | I14: =SUM(I2:I13) -> 600 | J14: =SUM(J2:J13) -> 0 | K14: =SUM(K2:K13) -> 600 | T14: Total | U14: =SUM(U2:U13) -> 600 | V14: =SUM(V2:V13) -> 0
A16: Week | B16: Name | C16: Amount | D16: Paid | E16: High Score
A17: Wk1 | B17: Rashad | C17: 10 | D17: Yes | E17: 112.36
A18: Wk2 | B18: Brian | C18: 10 | D18: Yes | E18: 131.9
A19: Wk3 | B19: David | C19: 10 | D19: Yes | E19: 115.14 | L19: Seed# | M19: River City | N19: W | O19: L | P19: T | Q19: GB | R19: PF | S19: PA | T19: Points Out of Playoffs
A20: Wk4 | B20: Travis | C20: 10 | D20: Yes | E20: 130.82 | L20: 1 | M20: The Mad "Panda" | N20: 10 | O20: 4 | P20: 0 | Q20: 0 | R20: 1424.14 | S20: 1214.04 | T20: =R20-R25 -> 35.48
A21: Wk5 | B21: JD | C21: 10 | D21: Yes | E21: 124.22 | L21: 2 | M21: Nudas Priest | N21: 8 | O21: 6 | P21: 0 | Q21: 2 | R21: 1422.34 | S21: 1226.36 | T21: =R21-R25 -> 33.68
A22: Wk6 | B22: David | C22: 10 | D22: Yes | E22: 122.04 | L22: 3 | M22: #FuckTSwift | N22: 8 | O22: 6 | P22: 0 | Q22: 2 | R22: 1359.46 | S22: 1298.12 | T22: =R22-R25 -> -29.2
A23: Wk7 | B23: JD | C23: 10 | D23: Yes | E23: 133.14 | L23: 4 | M23: Trash Pandas | N23: 8 | O23: 6 | P23: 0 | Q23: 2 | R23: 1314.6 | S23: 1258.3 | T23: 732.64
A24: Wk8 | B24: JD | C24: 10 | D24: Yes | E24: 135.76 | L24: 5 | M24: Stanal Fissures | N24: 7 | O24: 7 | P24: 0 | Q24: 3 | R24: 1391.6 | S24: 1292.16 | T24: =R24-R25 -> 2.94
A25: Wk9 | B25: Jordan | C25: 10 | D25: Yes | E25: 116.74 | L25: 6 | M25: The Schmendricks | N25: 7 | O25: 7 | P25: 0 | Q25: 3 | R25: 1388.66 | S25: 1425.68 | T25: 0
A26: Wk10 | B26: David | C26: 10 | D26: Yes | E26: 135.58 | L26: 7 | M26: The Shake-n-Bakers | N26: 7 | O26: 7 | P26: 0 | Q26: 3 | R26: 1260.96 | S26: 1300.72 | T26: =R25-R26 -> 127.7
A27: Wk11 | B27: Tommy | C27: 10 | D27: Yes | E27: 117.6 | L27: 8 | M27: ETN' Deez Nutz | N27: 7 | O27: 7 | P27: 0 | Q27: 3 | R27: 1280.36 | S27: 1208.06 | T27: =R25-R27 -> 108.3
A28: Wk12 | B28: Stan | C28: 10 | D28: Yes | E28: 142.86 | L28: 9 | M28: Broken Toe Joe | N28: 7 | O28: 7 | P28: 0 | Q28: 3 | R28: 1249.34 | S28: 1358.64 | T28: =R25-R28 -> 139.32
A29: Wk13 | B29: Jordan | C29: 10 | D29: Yes | E29: 124.46 | L29: 10 | M29: Carolina Reapers | N29: 6 | O29: 8 | P29: 0 | Q29: 4 | R29: 1229.16 | S29: 1321.32 | T29: =R25-R29 -> 159.5
A30: Wk14 | B30: Rashad | C30: 10 | D30: Yes | E30: 126.34 | L30: 11 | M30: It's a New Day | N30: 5 | O30: 9 | P30: 0 | Q30: 5 | R30: 1215.36 | S30: 1342.52 | T30: =R25-R30 -> 173.3
A31: Ring | B31: Aaron | C31: 16 | D31: Yes | L31: 12 | M31: Prestigio Mundial | N31: 2 | O31: 12 | P31: 0 | Q31: 8 | R31: 1036.82 | S31: 1326.88 | T31: =R25-R31 -> 351.84
A32: Division Winner | B32: JD | C32: 25 | D32: Yes | M32: s
A33: Division Winner | B33: Aaron | C33: 25 | D33: Yes
A34: Division Winner | B34: Rashad | C34: 25 | D34: Yes
A35: 3rd Place | B35: JD | C35: 50 | D35: Yes | E35: 95.58
A36: 2nd Place | B36: Travis | C36: 100 | D36: Yes | E36: 71.24
A37: Champ | B37: Aaron | C37: 219 | D37: Yes | E37: 75.98
C38: =SUM(C17:C37) -> 600
A44: Give Billy $50 FAAB when he's down to $150

Sheet 2024_Payouts
A1: Name | B1: Weekly Payout | C1: Weekly Payout | D1: 4th Place | E1: 3rd Place | F1: 2nd Place | G1: 1st Place | H1: Amount Won | I1: Entry Fee Paid | J1: Total Earned | T1: Names | U1: Paid | V1: Owes | W1: Damon Food | X1: Owes
A2: Tommy | B2: 2 | C2: =10*B2 -> 20 | D2: 0 | E2: 0 | F2: 0 | G2: 0 | H2: =sum(C2:G2) -> 20 | I2: =U2 -> 50 | J2: =H2-I2 -> -30 | T2: Tommy | U2: 50 | V2: =U2-50 -> 0 | W2: 5 | X2: =W2-5 -> 0
A3: David | B3: 3 | C3: =10*B3 -> 30 | D3: 50 | E3: 0 | F3: 0 | G3: 0 | H3: =sum(C3:G3) -> 80 | I3: =U3 -> 50 | J3: =H3-I3 -> 30 | T3: David | U3: 50 | V3: =U3-50 -> 0 | W3: 5 | X3: =W3-5 -> 0
A4: Jordan | B4: 2 | C4: =10*B4 -> 20 | D4: 0 | E4: 0 | F4: 0 | G4: 230 | H4: =sum(C4:G4) -> 250 | I4: =U4 -> 50 | J4: =H4-I4 -> 200 | T4: Jordan | U4: 50 | V4: =U4-50 -> 0 | W4: 5 | X4: =W4-5 -> 0
A5: JD | B5: 1 | C5: =10*B5 -> 10 | D5: 0 | E5: 0 | F5: 0 | G5: 0 | H5: =sum(C5:G5) -> 10 | I5: =U5 -> 50 | J5: =H5-I5 -> -40 | T5: JD | U5: 50 | V5: =U5-50 -> 0 | W5: 5 | X5: =W5-5 -> 0
A6: Billy | B6: 0 | C6: =10*B6 -> 0 | D6: 0 | E6: 0 | F6: 0 | G6: 0 | H6: =sum(C6:G6) -> 0 | I6: =U6 -> 50 | J6: =H6-I6 -> -50 | T6: Billy | U6: 50 | V6: =U6-50 -> 0 | W6: 5 | X6: =W6-5 -> 0
A7: Rashad | B7: 0 | C7: =10*B7 -> 0 | D7: 0 | E7: 0 | F7: 0 | G7: 0 | H7: =sum(C7:G7) -> 0 | I7: =U7 -> 50 | J7: =H7-I7 -> -50 | T7: Rashad | U7: 50 | V7: =U7-50 -> 0 | W7: 5 | X7: =W7-5 -> 0
A8: Brian | B8: 0 | C8: =10*B8 -> 0 | D8: 0 | E8: 0 | F8: 0 | G8: 0 | H8: =sum(C8:G8) -> 0 | I8: =U8 -> 50 | J8: =H8-I8 -> -50 | T8: Brian | U8: 50 | V8: =U8-50 -> 0 | W8: 5 | X8: =W8-5 -> 0
A9: Wade | B9: 1 | C9: =10*B9 -> 10 | D9: 0 | E9: 0 | F9: 100 | G9: 0 | H9: =sum(C9:G9) -> 110 | I9: =U9 -> 50 | J9: =H9-I9 -> 60 | T9: Wade | U9: 50 | V9: =U9-50 -> 0 | W9: 5 | X9: =W9-5 -> 0
A10: Travis | B10: 0 | C10: =10*B10 -> 0 | D10: 0 | E10: 0 | F10: 0 | G10: 0 | H10: =sum(C10:G10) -> 0 | I10: =U10 -> 50 | J10: =H10-I10 -> -50 | T10: Travis | U10: 50 | V10: =U10-50 -> 0 | W10: 5 | X10: =W10-5 -> 0
A11: Ray/Jeffrey | B11: 0 | C11: =10*B11 -> 0 | D11: 0 | E11: 0 | F11: 0 | G11: 0 | H11: =sum(C11:G11) -> 0 | I11: =U11 -> 50 | J11: =H11-I11 -> -50 | T11: Ray/Jeffrey | U11: 50 | V11: =U11-50 -> 0 | W11: 5 | X11: =W11-5 -> 0
A12: Doug | B12: 5 | C12: =10*B12 -> 50 | D12: 0 | E12: 75 | F12: 0 | G12: 0 | H12: =sum(C12:G12) -> 125 | I12: =U12 -> 50 | J12: =H12-I12 -> 75 | T12: Doug | U12: 50 | V12: =U12-50 -> 0 | W12: 5 | X12: =W12-5 -> 0
A13: Landon | B13: 0 | C13: =10*B13 -> 0 | D13: 0 | E13: 0 | F13: 0 | G13: 0 | H13: =sum(C13:G13) -> 0 | I13: =U13 -> 50 | J13: =H13-I13 -> -50 | T13: Landon | U13: 50 | V13: =U13-50 -> 0 | W13: 5 | X13: =W13-5 -> 0
C14: =SUM(C2:C13) -> 140 | D14: =SUM(D2:D13) -> 50 | E14: =SUM(E2:E13) -> 75 | F14: =SUM(F2:F13) -> 100 | G14: =SUM(G2:G13) -> 230 | H14: =SUM(H2:H13) -> 595 | I14: =SUM(I2:I13) -> 600 | J14: =SUM(J2:J13) -> -5 | T14: Total | U14: =SUM(U2:U13) -> 600 | V14: =SUM(V2:V13) -> 0 | W14: =SUM(W2:W13) -> 60 | X14: =SUM(X2:X13) -> 0
A16: Week | B16: Name | C16: Amount | D16: Paid | E16: High Score
A17: Wk1 | B17: Tommy | C17: 10 | D17: Yes | E17: 137.88
A18: Wk2 | B18: David | C18: 10 | D18: Yes | E18: 141.44
A19: Wk3 | B19: Doug | C19: 10 | D19: Yes | E19: 121.04 | L19: Seed# | M19: River City | N19: W | O19: L | P19: T | Q19: GB | R19: PF | S19: PA | T19: Points Out of Playoffs
A20: Wk4 | B20: David | C20: 10 | D20: Yes | E20: 108.48 | L20: 1 | M20: The Schmendricks | N20: 10 | O20: 4 | P20: 0 | Q20: 0 | R20: 1478.34 | S20: 1242.48 | T20: =R20-R25 -> 172.09
A21: Wk5 | B21: Jordan | C21: 10 | D21: Yes | E21: 117.56 | L21: 2 | M21: NowGiveMeMyThemeMusic | N21: 9 | O21: 5 | P21: 0 | Q21: 1 | R21: 1485.5 | S21: 1234.42 | T21: =R21-R25 -> 179.25
A22: Wk6 | B22: Jordan | C22: 10 | D22: Yes | E22: 132.66 | L22: 3 | M22: Fancy Ass Bitches | N22: 9 | O22: 5 | P22: 0 | Q22: 1 | R22: 1349.54 | S22: 1275.4 | T22: =R22-R25 -> 43.29
A23: Wk7 | B23: Doug | C23: 10 | D23: Yes | E23: 124.36 | L23: 4 | M23: Get.Your.Guy | N23: 10 | O23: 4 | P23: 0 | Q23: 0 | R23: 1472.14 | S23: 1264.04 | T23: =R23-R25 -> 165.89
A24: Wk8 | B24: Wade | C24: 10 | D24: Yes | E24: 122.6 | L24: 5 | M24: The Mad "Panda" | N24: 7 | O24: 7 | P24: 0 | Q24: 3 | R24: 1343.74 | S24: 1226.3 | T24: =R24-R25 -> 37.49
A25: Wk9 | B25: Tommy | C25: 10 | D25: Yes | E25: 123.72 | L25: 6 | M25: Stroud 2B an AmerAchane | N25: 6 | O25: 8 | P25: 0 | Q25: 4 | R25: 1306.25 | S25: 1331.6 | T25: 0
A26: Wk10 | B26: Doug | C26: 10 | D26: Yes | E26: 115.36 | L26: 7 | M26: The Righteous Gemstones | N26: 6 | O26: 8 | P26: 0 | Q26: 4 | R26: 1293.99 | S26: 1437.04 | T26: =R25-R26 -> 12.26
A27: Wk11 | B27: Doug | C27: 10 | D27: Yes | E27: 148.08 | L27: 8 | M27: Love'n Trash Pandas | N27: 6 | O27: 8 | P27: 0 | Q27: 4 | R27: 1230.04 | S27: 1206.6 | T27: =R25-R27 -> 76.21
A28: Wk12 | B28: Doug | C28: 10 | E28: 131.12 | L28: 9 | M28: Brilly | N28: 7 | O28: 7 | P28: 0 | Q28: 3 | R28: 1226.76 | S28: 1318.6 | T28: =R25-R28 -> 79.49
A29: Wk13 | B29: David | C29: 10 | D29: Yes | E29: 125.86 | L29: 10 | M29: Special Brownies | N29: 7 | O29: 7 | P29: 0 | Q29: 3 | R29: 1208.88 | S29: 1226.94 | T29: =R25-R29 -> 97.37
A30: Wk14 | B30: JD | C30: 10 | D30: Yes | E30: 151.42 | L30: 11 | M30: Snyder's Sloppy Seconds | N30: 5 | O30: 9 | P30: 0 | Q30: 5 | R30: 1171.7 | S30: 1391.08 | T30: =R25-R30 -> 134.55
A31: Name Plate | B31: Jordan | C31: 5 | L31: 12 | M31: It's a New Day | N31: 2 | O31: 12 | P31: 0 | Q31: 8 | R31: 1075.82 | S31: 1488.24 | T31: =R25-R31 -> 230.43
A32: 4th Place | B32: Dave | C32: 50 | D32: Yes | E32: 106.34 | M32: s
A33: 3rd Place | B33: Doug | C33: 75 | D33: Yes | E33: 107.64
A34: 2nd Place | B34: Wade | C34: 100 | D34: Yes | E34: 105.26
A35: Champ | B35: Jordan | C35: 230 | D35: Yes | E35: 110.02
C36: =SUM(C17:C35) -> 600
A44: Give Billy $50 FAAB when he's down to $150

Sheet 2023_Payouts
A1: Name | B1: Weekly Payout | C1: Weekly Payout | D1: 4th Place | E1: 3rd Place | F1: 2nd Place | G1: 1st Place | H1: Amount Won | I1: Entry Fee Paid | J1: Total Earned | T1: Names | U1: Paid | V1: Owes
A2: Tommy | B2: 1 | C2: =10*B2 -> 10 | D2: 0 | E2: 0 | F2: 0 | G2: 230 | H2: =sum(C2:G2) -> 240 | I2: =U2 -> 50 | J2: =H2-I2 -> 190 | T2: Tommy | U2: 50 | V2: =U2-50 -> 0
A3: David | B3: 1 | C3: =10*B3 -> 10 | D3: 0 | E3: 0 | F3: 0 | G3: 0 | H3: =sum(C3:G3) -> 10 | I3: =U3 -> 50 | J3: =H3-I3 -> -40 | T3: David | U3: 50 | V3: =U3-50 -> 0
A4: Jordan | B4: 0 | C4: =10*B4 -> 0 | D4: 0 | E4: 0 | F4: 0 | G4: 0 | H4: =sum(C4:G4) -> 0 | I4: =U4 -> 50 | J4: =H4-I4 -> -50 | T4: Jordan | U4: 50 | V4: =U4-50 -> 0
A5: JD | B5: 3 | C5: =10*B5 -> 30 | D5: 50 | E5: 0 | F5: 0 | G5: 0 | H5: =sum(C5:G5) -> 80 | I5: =U5 -> 50 | J5: =H5-I5 -> 30 | T5: JD | U5: 50 | V5: =U5-50 -> 0
A6: Billy | B6: 1 | C6: =10*B6 -> 10 | D6: 0 | E6: 0 | F6: 0 | G6: 0 | H6: =sum(C6:G6) -> 10 | I6: =U6 -> 50 | J6: =H6-I6 -> -40 | T6: Billy | U6: 50 | V6: =U6-50 -> 0
A7: Rashad | B7: 0 | C7: =10*B7 -> 0 | D7: 0 | E7: 0 | F7: 0 | G7: 0 | H7: =sum(C7:G7) -> 0 | I7: =U7 -> 50 | J7: =H7-I7 -> -50 | T7: Rashad | U7: 50 | V7: =U7-50 -> 0
A8: Brian | B8: 1 | C8: =10*B8 -> 10 | D8: 0 | E8: 0 | F8: 100 | G8: 0 | H8: =sum(C8:G8) -> 110 | I8: =U8 -> 50 | J8: =H8-I8 -> 60 | T8: Brian | U8: 50 | V8: =U8-50 -> 0
A9: Wade | B9: 0 | C9: =10*B9 -> 0 | D9: 0 | E9: 0 | F9: 0 | G9: 0 | H9: =sum(C9:G9) -> 0 | I9: =U9 -> 50 | J9: =H9-I9 -> -50 | T9: Wade | U9: 50 | V9: =U9-50 -> 0
A10: Travis | B10: 4 | C10: =10*B10 -> 40 | D10: 0 | E10: 0 | F10: 0 | G10: 0 | H10: =sum(C10:G10) -> 40 | I10: =U10 -> 50 | J10: =H10-I10 -> -10 | T10: Travis | U10: 50 | V10: =U10-50 -> 0
A11: Ray/Jeffrey | B11: 3 | C11: =10*B11 -> 30 | D11: 0 | E11: 75 | F11: 0 | G11: 0 | H11: =sum(C11:G11) -> 105 | I11: =U11 -> 50 | J11: =H11-I11 -> 55 | T11: Ray/Jeffrey | U11: 50 | V11: =U11-50 -> 0
A12: Doug | B12: 0 | C12: =10*B12 -> 0 | D12: 0 | E12: 0 | F12: 0 | G12: 0 | H12: =sum(C12:G12) -> 0 | I12: =U12 -> 50 | J12: =H12-I12 -> -50 | T12: Doug | U12: 50 | V12: =U12-50 -> 0
A13: Landon | B13: 0 | C13: =10*B13 -> 0 | D13: 0 | E13: 0 | F13: 0 | G13: 0 | H13: =sum(C13:G13) -> 0 | I13: =U13 -> 50 | J13: =H13-I13 -> -50 | T13: Landon | U13: 50 | V13: =U13-50 -> 0
C14: =SUM(C2:C13) -> 140 | D14: =SUM(D2:D13) -> 50 | E14: =SUM(E2:E13) -> 75 | F14: =SUM(F2:F13) -> 100 | G14: =SUM(G2:G13) -> 230 | H14: =SUM(H2:H13) -> 595 | I14: =SUM(I2:I13) -> 600 | J14: =SUM(J2:J13) -> -5 | T14: Total | U14: =SUM(U2:U13) -> 600 | V14: =SUM(V2:V13) -> 0
A16: Week | B16: Name | C16: Amount | D16: Paid | E16: High Score
A17: Wk1 | B17: Ray/Jeffrey | C17: 10 | D17: Yes | E17: 121.44 | F17: Paid 1/2 to Jeffrey. Didn't pay myself
A18: Wk2 | B18: Travis | C18: 10 | D18: Yes | E18: 122.54
A19: Wk3 | B19: Travis | C19: 10 | D19: Yes | E19: 140.96 | L19: Seed# | M19: River City | N19: W | O19: L | P19: T | Q19: GB | R19: PF | S19: PA | T19: Points Out of Playoffs
A20: Wk4 | B20: JD | C20: 10 | D20: No | E20: 143.8 | L20: 1 | M20: The Righteous Gemstones | N20: 12 | O20: 2 | P20: 0 | Q20: 0 | R20: 1487.84 | S20: 1164.78 | T20: =R20-R25 -> 137.74
A21: Wk5 | B21: Ray/Jeffrey | C21: 10 | D21: Yes | E21: 143.08 | F21: Paid 1/2 to Jeffrey. Didn't pay myself | L21: 2 | M21: Neaux Chance | N21: 10 | O21: 4 | P21: 0 | Q21: 2 | R21: 1404.54 | S21: 1214.8 | T21: =R21-R25 -> 54.44
A22: Wk6 | B22: JD | C22: 10 | D22: No | E22: 113.06 | L22: 3 | M22: The Playoff Tush Pusher | N22: 8 | O22: 6 | P22: 0 | Q22: 4 | R22: 1311.8 | S22: 1358.84 | T22: =R22-R25 -> -38.3
A23: Wk7 | B23: Billy | C23: 10 | D23: No | E23: 140.56 | L23: 4 | M23: The Ship of Theseus | N23: 9 | O23: 5 | P23: 0 | Q23: 3 | R23: 1486.64 | S23: 1334.92 | T23: =R23-R25 -> 136.54
A24: Wk8 | B24: Brian | C24: 10 | D24: Yes | E24: 135.76 | L24: 5 | M24: KC Punch | N24: 9 | O24: 5 | P24: 0 | Q24: 3 | R24: 1369.7 | S24: 1359 | T24: =R24-R25 -> 19.6
A25: Wk9 | B25: David | C25: 10 | D25: Yes | E25: 135.88 | L25: 6 | M25: It's a New Day | N25: 9 | O25: 5 | P25: 0 | Q25: 3 | R25: 1350.1 | S25: 1216.86 | T25: 0
A26: Wk10 | B26: Tommy | C26: 10 | D26: Yes | E26: 127.38 | L26: 7 | M26: The Tush Pusher | N26: 7 | O26: 6 | P26: 0 | Q26: 5 | R26: 1333.8 | S26: 1358.84 | T26: =R25-R26 -> 16.3
A27: Wk11 | B27: Ray/Jeffrey | C27: 10 | D27: Yes | E27: 121.52 | F27: Paid 1/2 to Jeffrey. Didn't pay myself | L27: 8 | M27: The Dollar Bins | N27: 4 | O27: 10 | P27: 0 | Q27: 8 | R27: 1217.16 | S27: 1211.12 | T27: =R25-R27 -> 132.94
A28: Wk12 | B28: JD | C28: 10 | D28: No | E28: 123.66 | L28: 9 | M28: Sam Hinkie Reborn | N28: 6 | O28: 8 | P28: 0 | Q28: 6 | R28: 1176.94 | S28: 1256.02 | T28: =R25-R28 -> 173.16
A29: Wk13 | B29: Travis | C29: 10 | D29: Yes | E29: 132.28 | L29: 10 | M29: Special Brownies | N29: 5 | O29: 9 | P29: 0 | Q29: 7 | R29: 1141.22 | S29: 1328.9 | T29: =R25-R29 -> 208.88
A30: Wk14 | B30: Travis | C30: 10 | D30: Yes | E30: 109.42 | L30: 11 | M30: Snyder's Sloppy Seconds | N30: 2 | O30: 12 | P30: 0 | Q30: 10 | R30: 1113.92 | S30: 1421.84 | T30: =R25-R30 -> 236.18
A31: Name Plate | B31: Tommy | C31: 5 | L31: 12 | M31: Getting Chiggy Wit It | N31: 3 | O31: 11 | P31: 0 | Q31: 9 | R31: 1094.36 | S31: 1282.84 | T31: =R25-R31 -> 255.74
A32: 4th Place | B32: JD | C32: 50 | D32: Yes | E32: 90.06 | M32: s
A33: 3rd Place | B33: Ray/Jeffrey | C33: 75 | D33: Yes | E33: 90.2
A34: 2nd Place | B34: Brian | C34: 100 | D34: Yes | E34: 117
A35: Champ | B35: Tommy | C35: 230 | D35: Yes | E35: 152.94
C36: =SUM(C17:C35) -> 600
A44: Give Billy $50 FAAB when he's down to $150

Sheet 2022_Payouts
A1: Name | B1: Weekly Payout | C1: Weekly Payout | D1: LB Winner | E1: 4th Place | F1: 3rd Place | G1: 2nd Place | H1: 1st Place | I1: Amount Won | J1: Entry Fee Paid | K1: Total Earned | T1: Names | U1: Paid | V1: Owes
A2: Tommy | B2: 2 | C2: =10*B2 -> 20 | D2: 0 | E2: 0 | F2: 0 | G2: 100 | H2: 75 | I2: =sum(C2:H2) -> 195 | J2: =U2 -> 50 | K2: =I2-J2 -> 145 | T2: Tommy | U2: 50 | V2: =U2-50 -> 0
A3: David | B3: 4 | C3: =10*B3 -> 40 | D3: 0 | E3: 0 | F3: 0 | G3: 100 | H3: 75 | I3: =sum(C3:H3) -> 215 | J3: =U3 -> 50 | K3: =I3-J3 -> 165 | T3: David | U3: 50 | V3: =U3-50 -> 0
A4: Jordan | B4: 0 | C4: =10*B4 -> 0 | D4: 0 | E4: 0 | F4: 0 | G4: 0 | H4: 0 | I4: =sum(C4:H4) -> 0 | J4: =U4 -> 50 | K4: =I4-J4 -> -50 | T4: Jordan | U4: 50 | V4: =U4-50 -> 0
A5: JD | B5: 0 | C5: =10*B5 -> 0 | D5: 0 | E5: 0 | F5: 0 | G5: 0 | H5: 0 | I5: =sum(C5:H5) -> 0 | J5: =U5 -> 50 | K5: =I5-J5 -> -50 | T5: JD | U5: 50 | V5: =U5-50 -> 0
A6: Billy | B6: 2 | C6: =10*B6 -> 20 | D6: 0 | E6: 25 | F6: 0 | G6: 0 | H6: 0 | I6: =sum(C6:H6) -> 45 | J6: =U6 -> 50 | K6: =I6-J6 -> -5 | T6: Billy | U6: 50 | V6: =U6-50 -> 0
A7: Rashad | B7: 0 | C7: =10*B7 -> 0 | D7: 0 | E7: 0 | F7: 0 | G7: 0 | H7: 0 | I7: =sum(C7:H7) -> 0 | J7: =U7 -> 50 | K7: =I7-J7 -> -50 | T7: Rashad | U7: 50 | V7: =U7-50 -> 0
A8: Brian | B8: 0 | C8: =10*B8 -> 0 | D8: 0 | E8: 0 | F8: 50 | G8: 0 | H8: 0 | I8: =sum(C8:H8) -> 50 | J8: =U8 -> 50 | K8: =I8-J8 -> 0 | T8: Brian | U8: 50 | V8: =U8-50 -> 0
A9: Wade | B9: 0 | C9: =10*B9 -> 0 | D9: 0 | E9: 0 | F9: 0 | G9: 0 | H9: 0 | I9: =sum(C9:H9) -> 0 | J9: =U9 -> 50 | K9: =I9-J9 -> -50 | T9: Wade | U9: 50 | V9: =U9-50 -> 0
A10: Travis | B10: 0 | C10: =10*B10 -> 0 | D10: 0 | E10: 0 | F10: 0 | G10: 0 | H10: 0 | I10: =sum(C10:H10) -> 0 | J10: =U10 -> 50 | K10: =I10-J10 -> -50 | T10: Travis | U10: 50 | V10: =U10-50 -> 0
A11: Ray/Jeffrey | B11: 1 | C11: =10*B11 -> 10 | D11: 25 | E11: 0 | F11: 0 | G11: 0 | H11: 0 | I11: =sum(C11:H11) -> 35 | J11: =U11 -> 50 | K11: =I11-J11 -> -15 | T11: Ray/Jeffrey | U11: 50 | V11: =U11-50 -> 0
A12: Doug | B12: 2 | C12: =10*B12 -> 20 | D12: 0 | E12: 0 | F12: 0 | G12: 0 | H12: 0 | I12: =sum(C12:H12) -> 20 | J12: =U12 -> 50 | K12: =I12-J12 -> -30 | T12: Doug | U12: 50 | V12: =U12-50 -> 0
A13: Landon | B13: 1 | C13: =10*B13 -> 10 | D13: 0 | E13: 0 | F13: 0 | G13: 0 | H13: 0 | I13: =sum(C13:H13) -> 10 | J13: =U13 -> 50 | K13: =I13-J13 -> -40 | T13: Landon | U13: 50 | V13: =U13-50 -> 0
C14: =SUM(C2:C13) -> 120 | D14: =SUM(D2:D13) -> 25 | E14: =SUM(E2:E13) -> 25 | F14: =SUM(F2:F13) -> 50 | G14: =SUM(G2:G13) -> 200 | H14: =SUM(H2:H13) -> 150 | I14: =SUM(I2:I13) -> 570 | J14: =SUM(J2:J13) -> 600 | K14: =SUM(K2:K13) -> -30 | T14: Total | U14: =SUM(U2:U13) -> 600 | V14: =SUM(V2:V13) -> 0
A16: Week | B16: Name | C16: Amount | D16: Paid | E16: High Score
A17: Wk1 | B17: David | C17: 10 | D17: Yes | E17: 131.42
A18: Wk2 | B18: Billy | C18: 10 | D18: Yes | E18: 148
A19: Wk3 | B19: Tommy | C19: 10 | D19: Yes | E19: 112.92 | L19: Seed# | M19: River City | N19: W | O19: L | P19: T | Q19: GB | R19: PF | S19: PA | T19: Points Out of Playoffs
A20: Wk4 | B20: Ray/Jeffrey | C20: 10 | D20: Yes | E20: 125.02 | F20: paid hudge full amt | L20: 1 | M20: Billy | N20: 12 | O20: 2 | P20: 0 | Q20: 0 | R20: 1545.02 | S20: 1251.88 | T20: =R20-R25 -> 179.14
A21: Wk5 | B21: Tommy | C21: 10 | D21: Yes | E21: 146.26 | L21: 2 | M21: Brian | N21: 11 | O21: 3 | P21: 0 | Q21: 1 | R21: 1334.08 | S21: 1169.8 | T21: =R21-R25 -> -31.8
A22: Wk6 | B22: David | C22: 10 | D22: Yes | E22: 102.6 | L22: 3 | M22: Doug | N22: 8 | O22: 6 | P22: 0 | Q22: 4 | R22: 1376.08 | S22: 1281.16 | T22: =R22-R25 -> 10.2
A23: Wk7 | B23: Landon | C23: 10 | D23: Yes | E23: 116.24 | F23: took away from what he owed | L23: 4 | M23: Dave | N23: 9 | O23: 5 | P23: 0 | Q23: 3 | R23: 1567.56 | S23: 1393.16 | T23: =R23-R25 -> 201.68
A24: Wk8 | B24: David | C24: 10 | D24: Yes | E24: 155.56 | L24: 5 | M24: Landon | N24: 7 | O24: 7 | P24: 0 | Q24: 5 | R24: 1391.2 | S24: 1196.76 | T24: =R24-R25 -> 25.32
A25: Wk9 | B25: Doug | C25: 10 | D25: Yes | E25: 144 | L25: 6 | M25: Tommy | N25: 8 | O25: 6 | P25: 0 | Q25: 4 | R25: 1365.88 | S25: 1297.32 | T25: 752.18
A26: Wk10 | B26: Billy | C26: 10 | D26: Yes | E26: 133.04 | L26: 7 | M26: Ray | N26: 4 | O26: 10 | P26: 0 | Q26: 8 | R26: 1307.92 | S26: 1355.88 | T26: =R25-R26 -> 57.96
A27: Wk11 | B27: Billy | C27: 10 | D27: No | E27: 141.66 | F27: rolled into the pot | L27: 8 | M27: Wade | N27: 8 | O27: 6 | P27: 0 | Q27: 4 | R27: 1223.62 | S27: 1282.52 | T27: =R25-R27 -> 142.26
A28: Wk12 | B28: Billy | C28: 10 | D28: No | E28: 124.2 | F28: rolled into the pot | L28: 9 | M28: Travis | N28: 5 | O28: 9 | P28: 0 | Q28: 7 | R28: 1210.3 | S28: 1341.58 | T28: =R25-R28 -> 155.58
A29: Wk13 | B29: Doug | C29: 10 | D29: Yes | E29: 123.4 | L29: 10 | M29: Rashad | N29: 5 | O29: 9 | P29: 0 | Q29: 7 | R29: 1190.88 | S29: 1327.74 | T29: =R25-R29 -> 175
A30: Wk14 | B30: David | C30: 10 | D30: Yes | E30: 128.88 | L30: 11 | M30: JD | N30: 3 | O30: 11 | P30: 0 | Q30: 9 | R30: 1090.86 | S30: 1415.92 | T30: =R25-R30 -> 275.02
A31: Name Plate | B31: Tommy/Dave | C31: 5 | L31: 12 | M31: Jordan | N31: 4 | O31: 10 | P31: 0 | Q31: 8 | R31: 1081.9 | S31: 1371.58 | T31: =R25-R31 -> 283.98
A32: LB Winner | B32: Ray/Jeffrey | C32: 25 | D32: Yes | E32: 112.98 | F32: paid what we owed
A33: 4th Place | B33: Billy | C33: 25 | D33: Yes | E33: 80.92
A34: 3rd Place | B34: Brian | C34: 75 | D34: Yes | E34: 121.9
A35: 2nd Place | B35: Dave | C35: 175 | D35: Yes | E35: 93.36
A36: Champ | B36: Tommy | C36: 175 | D36: Yes | E36: 105.48
C37: =SUM(C17:C36) -> 620

Sheet 2021_Payouts
A1: Name | B1: Weekly Payout | C1: Weekly Payout | D1: LB Winner | E1: 4th Place | F1: 3rd Place | G1: 2nd Place | H1: 1st Place | I1: Amount Won | J1: Entry Fee Paid | K1: Total Earned | T1: Names | U1: Paid | V1: Owes
A2: Tommy | B2: 1 | C2: =10*B2 -> 10 | D2: 0 | E2: 0 | F2: 0 | G2: 0 | H2: 0 | I2: =sum(C2:H2) -> 10 | J2: =U2 -> 50 | K2: =I2-J2 -> -40 | T2: Tommy | U2: 50 | V2: =U2-50 -> 0
A3: David | B3: 0 | C3: =10*B3 -> 0 | D3: 0 | E3: 0 | F3: 0 | G3: 0 | H3: 230 | I3: =sum(C3:H3) -> 230 | J3: =U3 -> 50 | K3: =I3-J3 -> 180 | T3: David | U3: 50 | V3: =U3-50 -> 0
A4: Jordan | B4: 1 | C4: =10*B4 -> 10 | D4: 0 | E4: 0 | F4: 0 | G4: 0 | H4: 0 | I4: =sum(C4:H4) -> 10 | J4: =U4 -> 50 | K4: =I4-J4 -> -40 | T4: Jordan | U4: 50 | V4: =U4-50 -> 0
A5: JD | B5: 1 | C5: =10*B5 -> 10 | D5: 0 | E5: 0 | F5: 0 | G5: 100 | H5: 0 | I5: =sum(C5:H5) -> 110 | J5: =U5 -> 50 | K5: =I5-J5 -> 60 | T5: JD | U5: 50 | V5: =U5-50 -> 0
A6: Billy | B6: 1 | C6: =10*B6 -> 10 | D6: 25 | E6: 0 | F6: 0 | G6: 0 | H6: 0 | I6: =sum(C6:H6) -> 35 | J6: =U6 -> 50 | K6: =I6-J6 -> -15 | T6: Billy | U6: 50 | V6: =U6-50 -> 0
A7: Adam | B7: 3 | C7: =10*B7 -> 30 | D7: 0 | E7: 0 | F7: 75 | G7: 0 | H7: 0 | I7: =sum(C7:H7) -> 105 | J7: =U7 -> 50 | K7: =I7-J7 -> 55 | T7: Adam | U7: 50 | V7: =U7-50 -> 0
A8: Brian | B8: 2 | C8: =10*B8 -> 20 | D8: 0 | E8: 0 | F8: 0 | G8: 0 | H8: 0 | I8: =sum(C8:H8) -> 20 | J8: =U8 -> 50 | K8: =I8-J8 -> -30 | T8: Brian | U8: 50 | V8: =U8-50 -> 0
A9: Wade | B9: 0 | C9: =10*B9 -> 0 | D9: 0 | E9: 25 | F9: 0 | G9: 0 | H9: 0 | I9: =sum(C9:H9) -> 25 | J9: =U9 -> 50 | K9: =I9-J9 -> -25 | T9: Wade | U9: 50 | V9: =U9-50 -> 0
A10: Travis | B10: 0 | C10: =10*B10 -> 0 | D10: 0 | E10: 0 | F10: 0 | G10: 0 | H10: 0 | I10: =sum(C10:H10) -> 0 | J10: =U10 -> 50 | K10: =I10-J10 -> -50 | T10: Travis | U10: 50 | V10: =U10-50 -> 0
A11: Ray/Jeffrey | B11: 2 | C11: =10*B11 -> 20 | D11: 0 | E11: 0 | F11: 0 | G11: 0 | H11: 0 | I11: =sum(C11:H11) -> 20 | J11: =U11 -> 50 | K11: =I11-J11 -> -30 | T11: Ray/Jeffrey | U11: 50 | V11: =U11-50 -> 0
A12: Doug | B12: 1 | C12: =10*B12 -> 10 | D12: 0 | E12: 0 | F12: 0 | G12: 0 | H12: 0 | I12: =sum(C12:H12) -> 10 | J12: =U12 -> 50 | K12: =I12-J12 -> -40 | T12: Doug | U12: 50 | V12: =U12-50 -> 0
A13: Landon | B13: 2 | C13: =10*B13 -> 20 | D13: 0 | E13: 0 | F13: 0 | G13: 0 | H13: 0 | I13: =sum(C13:H13) -> 20 | J13: =U13 -> 50 | K13: =I13-J13 -> -30 | T13: Landon | U13: 50 | V13: =U13-50 -> 0
C14: =SUM(C2:C13) -> 140 | D14: =SUM(D2:D13) -> 25 | E14: =SUM(E2:E13) -> 25 | F14: =SUM(F2:F13) -> 75 | G14: =SUM(G2:G13) -> 100 | H14: =SUM(H2:H13) -> 230 | I14: =SUM(I2:I13) -> 595 | J14: =SUM(J2:J13) -> 600 | K14: =SUM(K2:K13) -> -5 | T14: Total | U14: =SUM(U2:U13) -> 600 | V14: =SUM(V2:V13) -> 0
A16: Week | B16: Name | C16: Amount | D16: Paid | E16: High Score
A17: Wk1 | B17: Adam | C17: 10 | D17: Yes | E17: 128.44
A18: Wk2 | B18: Landon | C18: 10 | D18: Yes | E18: 152.3
A19: Wk3 | B19: Tommy | C19: 10 | D19: Yes | E19: 129.72 | L19: Seed# | M19: River City | N19: W | O19: L | P19: T | Q19: GB | R19: PF | S19: PA | T19: Points Out of Playoffs
A20: Wk4 | B20: Landon | C20: 10 | D20: No | E20: 130.92 | F20: No Recap | L20: 1 | M20: The Schmendricks | N20: 12 | O20: 2 | P20: 0 | Q20: 0 | R20: 1484.26 | S20: 1159.52 | T20: =R20-R25 -> 139.22
A21: Wk5 | B21: Brian | C21: 10 | D21: No | E21: 150.28 | F21: No Recap | L21: 2 | M21: Late Round Flyers | N21: 9 | O21: 5 | P21: 0 | Q21: 3 | R21: 1281.84 | S21: 1236.6 | T21: =R21-R25 -> -63.2
A22: Wk6 | B22: Ray/Jeffrey | C22: 10 | D22: Yes | E22: 135.32 | L22: 3 | M22: Symbols | N22: 7 | O22: 7 | P22: 0 | Q22: 5 | R22: 1248.68 | S22: 1297.64 | T22: =R22-R25 -> -96.36
A23: Wk7 | B23: JD | C23: 10 | D23: Yes | E23: 134.84 | L23: 4 | M23: Hot Tub Jellyfish | N23: 9 | O23: 5 | P23: 0 | Q23: 3 | R23: 1520.56 | S23: 1467.82 | T23: =R23-R25 -> 175.52
A24: Wk8 | B24: Jordan | C24: 10 | D24: No | E24: 130.44 | F24: No Recap | L24: 5 | M24: Special Brownies | N24: 7 | O24: 7 | P24: 0 | Q24: 5 | R24: 1381.46 | S24: 1250.08 | T24: =R24-R25 -> 36.42
A25: Wk9 | B25: Brian | C25: 10 | D25: No | E25: 102.84 | F25: No Recap | L25: 6 | M25: Back to Jacksonville | N25: 5 | O25: 9 | P25: 0 | Q25: 7 | R25: 1345.04 | S25: 1386.48 | T25: =R25-R25 -> 0
A26: Wk10 | B26: Adam | C26: 10 | D26: No | E26: 118.02 | F26: No Recap | L26: 7 | M26: Trash Pandas | N26: 6 | O26: 8 | P26: 0 | Q26: 6 | R26: 1325.52 | S26: 1399.4 | T26: =R25-R26 -> 19.52
A27: Wk11 | B27: Adam | C27: 10 | D27: Yes | E27: 152.34 | L27: 8 | M27: The People's Champ | N27: 6 | O27: 8 | P27: 0 | Q27: 6 | R27: 1303.04 | S27: 1424.2 | T27: =R25-R27 -> 42
A28: Wk12 | B28: Billy | C28: 10 | D28: No | E28: 130.28 | F28: No Recap | L28: 9 | M28: Not Mad Just Disappointed | N28: 5 | O28: 9 | P28: 0 | Q28: 7 | R28: 1295.22 | S28: 1429.98 | T28: =R25-R28 -> 49.82
A29: Wk13 | B29: Doug | C29: 10 | D29: Yes | E29: 126.98 | L29: 10 | M29: Let Russ Cook(s) | N29: 6 | O29: 8 | P29: 0 | Q29: 6 | R29: 1293.2 | S29: 1319.99 | T29: =R25-R29 -> 51.84
A30: Wk14 | B30: Ray/Jeffrey | C30: 10 | D30: Yes | E30: 132.82 | L30: 11 | M30: Beer is the Answer | N30: 7 | O30: 7 | P30: 0 | Q30: 5 | R30: 1269.24 | S30: 1315.14 | T30: =R25-R30 -> 75.8
A31: Name Plate | B31: Dave | C31: 5 | L31: 12 | M31: Prestigio Mundial | N31: 5 | O31: 9 | P31: 0 | Q31: 7 | R31: 1206.64 | S31: 1328.5 | T31: =R25-R31 -> 138.4
A32: LB Winner | B32: Billy | C32: 25 | D32: Yes | E32: 100.72
A33: 4th Place | B33: Wade | C33: 25 | D33: Yes | E33: 101.06
A34: 3rd Place | B34: Adam | C34: 75 | D34: Yes | E34: 113.56
A35: 2nd Place | B35: JD | C35: 100 | D35: Yes | E35: 93.66
A36: Champ | B36: Dave | C36: 230 | D36: Yes | E36: 140.9
C37: =SUM(C17:C36) -> 600

Sheet 2020_Payouts
A1: Name | B1: Weekly Payout | C1: Weekly Payout | D1: LB Winner | E1: 4th Place | F1: 3rd Place | G1: 2nd Place | H1: 1st Place | I1: Amount Won | J1: Entry Fee Paid | K1: Total Earned | T1: Names | U1: Paid | V1: Owes
A2: Tommy | B2: 0 | C2: =10*B2 -> 0 | D2: 0 | E2: 0 | F2: 0 | G2: 0 | H2: 0 | I2: =sum(C2:H2) -> 0 | J2: =U2 -> 50 | K2: =I2-J2 -> -50 | T2: Tommy | U2: 50 | V2: =U2-50 -> 0
A3: David | B3: 3 | C3: =10*B3 -> 30 | D3: 0 | E3: 0 | F3: 75 | G3: 0 | H3: 0 | I3: =sum(C3:H3) -> 105 | J3: =U3 -> 50 | K3: =I3-J3 -> 55 | T3: David | U3: 50 | V3: =U3-50 -> 0
A4: Jordan | B4: 2 | C4: =10*B4 -> 20 | D4: 25 | E4: 0 | F4: 0 | G4: 0 | H4: 0 | I4: =sum(C4:H4) -> 45 | J4: =U4 -> 50 | K4: =I4-J4 -> -5 | T4: Jordan | U4: 50 | V4: =U4-50 -> 0
A5: JD | B5: 0 | C5: =10*B5 -> 0 | D5: 0 | E5: 0 | F5: 0 | G5: 0 | H5: 240 | I5: =sum(C5:H5) -> 240 | J5: =U5 -> 50 | K5: =I5-J5 -> 190 | T5: JD | U5: 50 | V5: =U5-50 -> 0
A6: Billy | B6: 1 | C6: =10*B6 -> 10 | D6: 0 | E6: 0 | F6: 0 | G6: 0 | H6: 0 | I6: =sum(C6:H6) -> 10 | J6: =U6 -> 50 | K6: =I6-J6 -> -40 | T6: Billy | U6: 50 | V6: =U6-50 -> 0
A7: Adam | B7: 0 | C7: =10*B7 -> 0 | D7: 0 | E7: 0 | F7: 0 | G7: 0 | H7: 0 | I7: =sum(C7:H7) -> 0 | J7: =U7 -> 50 | K7: =I7-J7 -> -50 | T7: Adam | U7: 50 | V7: =U7-50 -> 0
A8: Brian | B8: 2 | C8: =10*B8 -> 20 | D8: 0 | E8: 25 | F8: 0 | G8: 0 | H8: 0 | I8: =sum(C8:H8) -> 45 | J8: =U8 -> 50 | K8: =I8-J8 -> -5 | T8: Brian | U8: 50 | V8: =U8-50 -> 0
A9: Wade | B9: 1 | C9: =10*B9 -> 10 | D9: 0 | E9: 0 | F9: 0 | G9: 0 | H9: 0 | I9: =sum(C9:H9) -> 10 | J9: =U9 -> 50 | K9: =I9-J9 -> -40 | T9: Wade | U9: 50 | V9: =U9-50 -> 0
A10: Travis | B10: 0 | C10: =10*B10 -> 0 | D10: 0 | E10: 0 | F10: 0 | G10: 0 | H10: 0 | I10: =sum(C10:H10) -> 0 | J10: =U10 -> 50 | K10: =I10-J10 -> -50 | T10: Travis | U10: 50 | V10: =U10-50 -> 0
A11: Ray/Jeffrey | B11: 4 | C11: =10*B11 -> 40 | D11: 0 | E11: 0 | F11: 0 | G11: 0 | H11: 0 | I11: =sum(C11:H11) -> 40 | J11: =U11 -> 50 | K11: =I11-J11 -> -10 | T11: Ray/Jeffrey | U11: 50 | V11: =U11-50 -> 0 | Z11: ray paid $25 at start of season and we've won $40. Hudgins owes $5 and I can pull my $25 out.
A12: Doug | B12: 0 | C12: =10*B12 -> 0 | D12: 0 | E12: 0 | F12: 0 | G12: 0 | H12: 0 | I12: =sum(C12:H12) -> 0 | J12: =U12 -> 50 | K12: =I12-J12 -> -50 | T12: Doug | U12: 50 | V12: =U12-50 -> 0
A13: Landon | B13: 0 | C13: =10*B13 -> 0 | D13: 0 | E13: 0 | F13: 0 | G13: 100 | H13: 0 | I13: =sum(C13:H13) -> 100 | J13: =U13 -> 50 | K13: =I13-J13 -> 50 | T13: Landon | U13: 50 | V13: =U13-50 -> 0
C14: =SUM(C2:C13) -> 130 | D14: =SUM(D2:D13) -> 25 | E14: =SUM(E2:E13) -> 25 | F14: =SUM(F2:F13) -> 75 | G14: =SUM(G2:G13) -> 100 | H14: =SUM(H2:H13) -> 240 | I14: =SUM(I2:I13) -> 595 | J14: =SUM(J2:J13) -> 600 | K14: =SUM(K2:K13) -> -5 | T14: Total | U14: =SUM(U2:U13) -> 600 | V14: =SUM(V2:V13) -> 0
A16: Week | B16: Name | C16: Amount | D16: Paid | E16: High Score
A17: Wk1 | B17: Ray/Jeffrey | C17: 10 | D17: Yes | E17: 152.02
A18: Wk2 | B18: Brian | C18: 10 | D18: Yes | E18: 131.28
A19: Wk3 | B19: Dave | C19: 10 | D19: Yes | E19: 136.28 | L19: Seed# | M19: River City | N19: W | O19: L | P19: T | Q19: GB | R19: PF | S19: PA | T19: Points Out of Playoffs
A20: Wk4 | B20: Jordan | C20: 10 | D20: Yes | E20: 135.38 | L20: 1 | M20: Special Brownies | N20: 11 | O20: 2 | P20: 0 | Q20: 0 | R20: 1315.46 | S20: 1050.42 | T20: =R20-R25 -> -10.04
A21: Wk5 | B21: Ray/Jeffrey | C21: 10 | D21: Yes | E21: 148.96 | L21: 2 | M21: Infinity Chubb | N21: 9 | O21: 4 | P21: 0 | Q21: 2 | R21: 1304.04 | S21: 1259.48 | T21: =R21-R25 -> -21.46
A22: Wk6 | B22: Ray/Jeffrey | C22: 10 | D22: Yes | E22: 120.7 | L22: 3 | M22: Saquon can have my ACL | N22: 8 | O22: 5 | P22: 0 | Q22: 3 | R22: 1172.34 | S22: 1167.18 | T22: =R22-R25 -> -153.16
A23: Wk7 | B23: Dave | C23: 10 | D23: Yes | E23: 156.44 | L23: 4 | M23: BeardSmellsLikeBalls | N23: 8 | O23: 5 | P23: 0 | Q23: 3 | R23: 1415.34 | S23: 1254.38 | T23: =R23-R25 -> 89.84
A24: Wk8 | B24: Wade | C24: 10 | D24: Yes | E24: 116.82 | L24: 5 | M24: Prestigio Mundial | N24: 7 | O24: 6 | P24: 0 | Q24: 4 | R24: 1384.14 | S24: 1325.82 | T24: =R24-R25 -> 58.64
A25: Wk9 | B25: Ray/Jeffrey | C25: 10 | D25: Yes | E25: 135.04 | L25: 6 | M25: F U Minshew | N25: 7 | O25: 6 | P25: 0 | Q25: 4 | R25: 1325.5 | S25: 1260.5 | T25: =R25-R25 -> 0
A26: Wk10 | B26: Jordan | C26: 10 | D26: No | E26: 124 | F26: no recap | L26: 7 | M26: Aaron Jonestown Massacre | N26: 6 | O26: 7 | P26: 0 | Q26: 5 | R26: 1310.52 | S26: 1212.44 | T26: =R25-R26 -> 14.98
A27: Wk11 | B27: Brian | C27: 10 | D27: Yes | E27: 122.82 | L27: 8 | M27: Knights of Chadwick | N27: 6 | O27: 7 | P27: 0 | Q27: 5 | R27: 1256.82 | S27: 1322.28 | T27: =R25-R27 -> 68.68
A28: Wk12 | B28: Billy | C28: 10 | D28: Yes | E28: 140.04 | L28: 9 | M28: Witch Doctors | N28: 6 | O28: 7 | P28: 0 | Q28: 5 | R28: 1189.84 | S28: 1204.12 | T28: =R25-R28 -> 135.66
A29: Wk13 | B29: Dave | C29: 10 | D29: Yes | E29: 127.5 | L29: 10 | M29: Big Dick Nick Pics | N29: 4 | O29: 9 | P29: 0 | Q29: 7 | R29: 1151.58 | S29: 1278.64 | T29: =R25-R29 -> 173.92
A30: Name Plate | B30: N/A | C30: 5 | D30: N/A | E30: N/A | L30: 11 | M30: Trash Pandas | N30: 5 | O30: 8 | P30: 0 | Q30: 6 | R30: 1071.8 | S30: 1207.14 | T30: =R25-R30 -> 253.7
A31: LB Winner | B31: Jordan | C31: 25 | D31: Yes | E31: N/A | L31: 12 | M31: Diamond Dogs | N31: 1 | O31: 12 | P31: 0 | Q31: 11 | R31: 1042.98 | S31: 1401.96 | T31: =R25-R31 -> 282.52
A32: 4th Place | B32: Brian | C32: 25 | D32: Yes | E32: N/A
A33: 3rd Place | B33: Dave | C33: 75 | D33: Yes | E33: N/A
A34: 2nd Place | B34: Landon | C34: 100 | D34: Yes | E34: N/A
A35: Champ | B35: JD | C35: 240 | D35: Yes | E35: N/A
C36: =SUM(C17:C35) -> 600

Sheet 2019_Payouts
C1: Current
A2: Name | B2: Weekly Payout | C2: Weekly Payout | D2: Top 4 | E2: Advancing to Finals | F2: Win Finals | G2: Amount Won | H2: Entry Fee Paid | I2: Total Earned | R2: Names | S2: Paid | T2: Owes
A3: Tommy | B3: 1 | C3: =15*B3 -> 15 | D3: 0 | E3: 0 | F3: 0 | G3: =sum(C3:F3) -> 15 | H3: =S3 -> 50 | I3: =G3-H3 -> -35 | R3: Tommy | S3: 50 | T3: =S3-50 -> 0
A4: David | B4: 0 | C4: =15*B4 -> 0 | D4: 0 | E4: 0 | F4: 0 | G4: =sum(C4:F4) -> 0 | H4: =S4 -> 50 | I4: =G4-H4 -> -50 | R4: David | S4: 50 | T4: =S4-50 -> 0
A5: Jordan | B5: 0 | C5: =15*B5 -> 0 | D5: 0 | E5: 0 | F5: 0 | G5: =sum(C5:F5) -> 0 | H5: =S5 -> 50 | I5: =G5-H5 -> -50 | R5: Jordan | S5: 50 | T5: =S5-50 -> 0
A6: JD | B6: 0 | C6: =15*B6 -> 0 | D6: 0 | E6: 0 | F6: 0 | G6: =sum(C6:F6) -> 0 | H6: =S6 -> 50 | I6: =G6-H6 -> -50 | R6: JD | S6: 50 | T6: =S6-50 -> 0
A7: Billy | B7: 1 | C7: =15*B7 -> 15 | D7: 0 | E7: 0 | F7: 0 | G7: =sum(C7:F7) -> 15 | H7: =S7 -> 50 | I7: =G7-H7 -> -35 | R7: Billy | S7: 50 | T7: =S7-50 -> 0
A8: Patrick | B8: 1 | C8: =15*B8 -> 15 | D8: 50 | E8: 0 | F8: 0 | G8: =sum(C8:F8) -> 65 | H8: =S8 -> 50 | I8: =G8-H8 -> 15 | R8: Patrick | S8: 50 | T8: =S8-50 -> 0
A9: Brian | B9: 4 | C9: =15*B9 -> 60 | D9: 50 | E9: 0 | F9: 0 | G9: =sum(C9:F9) -> 110 | H9: =S9 -> 50 | I9: =G9-H9 -> 60 | R9: Brian | S9: 50 | T9: =S9-50 -> 0
A10: Wade | B10: 3 | C10: =15*B10 -> 45 | D10: 50 | E10: 50 | G10: =sum(C10:F10) -> 145 | H10: =S10 -> 50 | I10: =G10-H10 -> 95 | R10: Wade | S10: 50 | T10: =S10-50 -> 0
A11: Travis | B11: 1 | C11: =15*B11 -> 15 | D11: 50 | E11: $50 | F11: 0 | G11: =sum(C11:F11) -> 65 | H11: =S11 -> 50 | I11: =G11-H11 -> 15 | R11: Travis | S11: 50 | T11: =S11-50 -> 0
A12: Ray/Jeffrey | B12: 2 | C12: =15*B12 -> 30 | D12: 0 | E12: 0 | F12: 0 | G12: =sum(C12:F12) -> 30 | H12: =S12 -> 50 | I12: =G12-H12 -> -20 | R12: Ray/Jeffrey | S12: 50 | T12: =S12-50 -> 0
A13: Doug | B13: 0 | C13: =15*B13 -> 0 | D13: 0 | E13: 0 | F13: 0 | G13: =sum(C13:F13) -> 0 | H13: =S13 -> 50 | I13: =G13-H13 -> -50 | R13: Doug | S13: 50 | T13: =S13-50 -> 0
A14: Landon | B14: 0 | C14: =15*B14 -> 0 | D14: =15*C14 -> 0 | E14: 0 | F14: 0 | G14: =sum(C14:F14) -> 0 | H14: =S14 -> 50 | I14: =G14-H14 -> -50 | R14: Landon | S14: 50 | T14: =S14-50 -> 0
C15: =SUM(C3:C14) -> 195 | D15: =SUM(D3:D14) -> 200 | E15: =SUM(E3:E14) -> 50 | F15: =SUM(F3:F14) -> 0 | G15: =SUM(G3:G14) -> 445 | H15: =SUM(H3:H14) -> 600 | I15: =SUM(I3:I14) -> -155 | R15: Total | S15: =SUM(S3:S14) -> 600 | T15: =SUM(T3:T14) -> 0
A17: Week | B17: Name | C17: Amount | D17: Paid | E17: High Score
A18: Wk1 | B18: Ray/Jeffrey | C18: 15 | D18: Yes | E18: 140.1 | F18: paid Hudgins$7.50. didn't pay myself any winnings
A19: Wk2 | B19: Brian | C19: 15 | D19: Yes | E19: 119.02 | F19: Doug wrote recap on Brian's behalf
A20: Wk3 | B20: Patrick | C20: 15 | D20: Yes | E20: 137.2
A21: Wk4 | B21: Travis | C21: 15 | D21: Yes | E21: 109.18
A22: Wk5 | B22: Ray/Jeffrey | C22: 15 | D22: Yes | E22: 147.7 | F22: paid Hudgins$7.50. didn't pay myself any winnings
A23: Wk6 | B23: Billy | C23: 15 | D23: Yes | E23: 139.5
A24: Wk7 | B24: Wade | C24: 15 | D24: Yes | E24: 140.58
A25: Wk8 | B25: Brian | C25: 15 | D25: No | E25: 135.2 | F25: Didn't write so rolled into Championship Pot
A26: Wk9 | B26: Tommy | C26: 15 | D26: Yes | E26: 130.42
A27: Wk10 | B27: Wade | C27: 15 | D27: Yes | E27: 117.14
A28: Wk11 | B28: Brian | C28: 15 | D28: Yes | E28: 113.48
A29: Wk12 | B29: Brian | C29: 15 | D29: No | E29: 117.5 | F29: Didn't write so rolled into Championship Pot
A30: Wk13 | B30: Wade | C30: 15 | D30: Yes | E30: 117.84 | N30: Seed# | O30: River City | P30: W | Q30: L | R30: T | S30: GB | T30: PF | U30: PA | V30: Points Out of Playoffs
A31: 4th Place | B31: Patrick | C31: 50 | D31: Yes | N31: 1 | O31: Witchdoctors | P31: 11 | Q31: 2 | R31: 0 | S31: 0 | T31: 1389 | U31: 1120 | V31: N/A
A32: 3rd Place | B32: Brian | C32: 50 | D32: Yes | N32: 2 | O32: Stevens24/7 | P32: 10 | Q32: 3 | R32: 0 | S32: 1 | T32: 1382 | U32: 1197 | V32: N/A
A33: 1st Loser | B33: Travis | C33: 100 | D33: Yes | N33: 3 | O33: Trash Panda | P33: 7 | Q33: 6 | R33: 0 | S33: 4 | T33: 1267 | U33: 1220 | V33: N/A
A34: Champ | B34: Wade | C34: 200 | D34: Yes | N34: 4 | O34: Prestigio Mundial | P34: 8 | Q34: 5 | R34: 0 | S34: 3 | T34: 1378 | U34: 1300 | V34: N/A
C35: =SUM(C18:C34) -> 595 | N35: 5 | O35: Deebo and Arrow | P35: 6 | Q35: 7 | R35: 0 | S35: 5 | T35: 1209 | U35: 1323 | V35: N/A
N36: 6 | O36: My Beard Smells Like Dicks | P36: 6 | Q36: 7 | R36: 0 | S36: 5 | T36: 1204 | U36: 1190 | V36: N/A
N37: 7 | O37: Thugs of Thanos | P37: 8 | Q37: 5 | R37: 0 | S37: 3 | T37: 1203 | U37: 1151 | V37: =T36-T37 -> 1
N38: 8 | O38: Special Brownies | P38: 5 | Q38: 8 | R38: 0 | S38: 6 | T38: 1192 | U38: 1212 | V38: =T36-T38 -> 12
N39: 9 | O39: Patrick Jr. | P39: 6 | Q39: 7 | R39: 0 | S39: 5 | T39: 1152 | U39: 1293 | V39: =T36-T39 -> 52
N40: 10 | O40: Moore's Monstars | P40: 6 | Q40: 7 | R40: 0 | S40: 5 | T40: 1130 | U40: 1225 | V40: =T36-T40 -> 74
N41: 11 | O41: Notmillatime27 | P41: 2 | Q41: 11 | R41: 0 | S41: 9 | T41: 1123 | U41: 1249 | V41: =T36-T41 -> 81
...

Sheet 2018_Payouts
C1: Current
A2: Name | B2: Weekly Payout | C2: Weekly Payout | D2: Advance to Playoffs | E2: Advancing to Finals | F2: Win Finals | G2: Amount Won | H2: Entry Fee Paid | I2: Total Earned | R2: Names | S2: Paid | T2: Owes
A3: Tommy | B3: 1 | C3: =15*B3 -> 15 | D3: 0 | E3: 100 | G3: =SUM(C3:F3) -> 115 | H3: 50 | I3: =G3-H3 -> 65 | R3: Tommy | S3: 50 | T3: =S3-50 -> 0 | U3: Venmo
A4: Chris | B4: 1 | C4: =15*B4 -> 15 | D4: 0 | E4: 0 | F4: 0 | G4: =SUM(C4:F4) -> 15 | H4: 50 | I4: =G4-H4 -> -35 | R4: Chris | S4: 50 | T4: =S4-50 -> 0 | U4: Cash
A5: Jordan | B5: 3 | C5: =15*B5 -> 45 | D5: 0 | E5: 50 | F5: 0 | G5: =SUM(C5:F5) -> 95 | H5: 50 | I5: =G5-H5 -> 45 | R5: Jordan | S5: 50 | T5: =S5-50 -> 0 | U5: Venmo
A6: JD | B6: 1 | C6: =15*B6 -> 15 | D6: 0 | E6: 0 | F6: 0 | G6: =SUM(C6:F6) -> 15 | H6: 50 | I6: =G6-H6 -> -35 | R6: JD | S6: 50 | T6: =S6-50 -> 0 | U6: Venmo
A7: Billy | B7: 1 | C7: =15*B7 -> 15 | D7: 0 | E7: 0 | F7: 0 | G7: =SUM(C7:F7) -> 15 | H7: 50 | I7: =G7-H7 -> -35 | R7: Billy | S7: 50 | T7: =S7-50 -> 0 | U7: Venmo
A8: Patrick | B8: 1 | C8: =15*B8 -> 15 | D8: 0 | E8: 0 | F8: 0 | G8: =SUM(C8:F8) -> 15 | H8: 50 | I8: =G8-H8 -> -35 | R8: Patrick | S8: 50 | T8: =S8-50 -> 0 | U8: Venmo
A9: Brian | B9: 2 | C9: =15*B9 -> 30 | D9: 0 | E9: 100 | G9: =SUM(C9:F9) -> 130 | H9: 50 | I9: =G9-H9 -> 80 | R9: Brian | S9: 50 | T9: =S9-50 -> 0 | U9: Venmo
A10: Wade | B10: 3 | C10: =15*B10 -> 45 | D10: 0 | E10: 0 | F10: 0 | G10: =SUM(C10:F10) -> 45 | H10: 50 | I10: =G10-H10 -> -5 | R10: Wade | S10: 50 | T10: =S10-50 -> 0 | U10: Venmo
A11: Travis | B11: 0 | C11: =15*B11 -> 0 | D11: 0 | E11: 0 | F11: 0 | G11: =SUM(C11:F11) -> 0 | H11: 50 | I11: =G11-H11 -> -50 | R11: Travis | S11: 50 | T11: =S11-50 -> 0 | U11: PayPal
A12: Ray/Jeffrey | B12: 0 | C12: =15*B12 -> 0 | D12: 0 | E12: 50 | F12: 0 | G12: =SUM(C12:F12) -> 50 | H12: 50 | I12: =G12-H12 -> 0 | R12: Ray/Jeffrey | S12: 50 | T12: =S12-50 -> 0 | U12: My Bank Acct
A13: Ricky | B13: 0 | C13: =15*B13 -> 0 | D13: 0 | E13: 0 | F13: 0 | G13: =SUM(C13:F13) -> 0 | H13: 50 | I13: =G13-H13 -> -50 | R13: Ricky | S13: 50 | T13: =S13-50 -> 0 | U13: Venmo
A14: Landon | B14: 0 | C14: =15*B14 -> 0 | D14: =15*C14 -> 0 | E14: =15*D14 -> 0 | F14: =15*E14 -> 0 | G14: =SUM(C14:F14) -> 0 | H14: 50 | I14: =G14-H14 -> -50 | R14: Landon | S14: 50 | T14: =S14-50 -> 0 | U14: Venmo
C15: =SUM(C3:C14) -> 195 | D15: =SUM(D3:D14) -> 0 | E15: =SUM(E3:E14) -> 300 | F15: =SUM(F3:F14) -> 0 | G15: =SUM(G3:G14) -> 495 | H15: =SUM(H3:H14) -> 600 | I15: =SUM(I3:I14) -> -105 | R15: Total | S15: =SUM(S3:S14) -> 600 | T15: =SUM(T3:T14) -> 0
A17: Week | B17: Name | C17: Amount | D17: Paid | E17: High Score
A18: Wk1 | B18: JD | C18: 15 | D18: $15 | E18: 132.2 | F18: Venmo
A19: Wk2 | B19: Billy | C19: 15 | D19: 15 | E19: 129.5 | F19: Venmo
A20: Wk3 | B20: Chris | C20: 15 | D20: 15 | E20: 97.4 | F20: Zelle
A21: Wk4 | B21: Wade | C21: 15 | D21: 15 | E21: 127.7 | F21: Venmo
A22: Wk5 | B22: Jordan | C22: 15 | D22: $15 | E22: 135.2 | F22: Venmo
A23: Wk6 | B23: Jordan | C23: 15 | D23: $15 | E23: 142 | F23: Venmo
A24: Wk7 | B24: Jordan | C24: 15 | D24: 15 | E24: 134.1 | F24: Venmo
A25: Wk8 | B25: Patrick | C25: 15 | D25: 15 | E25: 109 | F25: Venmo
A26: Wk9 | B26: Tommy | C26: 15 | D26: 15 | E26: 138.3 | F26: Venmo
A27: Wk10 | B27: Brian | C27: 15 | D27: 15 | E27: 146.4 | F27: no write up/no payout
A28: Wk11 | B28: Wade | C28: 15 | D28: $15 | E28: 143.6 | F28: Venmo
A29: Wk12 | B29: Brian | C29: 15 | D29: 15 | E29: 126.7 | F29: no write up/no payout
A30: Wk13 | B30: Wade | C30: 15 | D30: $15 | E30: 111.3 | F30: Venmo | N30: Seed# | O30: River City | P30: W | Q30: L | R30: T | S30: GB | T30: PF | U30: PA
A31: 4th Place | B31: Jordan | C31: 50 | D31: $50 | E31: Venmo | N31: 1 | O31: In My Thielens | P31: 11 | Q31: 2 | R31: 0 | S31: 0 | T31: 1330.9 | U31: 1137.1
A32: 3rd Place | B32: Ray | C32: 50 | D32: $50 | E32: Venmo | N32: 2 | O32: Prestigo Mundial | P32: 11 | Q32: 2 | R32: 0 | S32: 0 | T32: 1235.1 | U32: 1019
A33: 1st Loser | B33: Tommy | C33: 100 | D33: $100 | E33: Venmo | N33: 3 | O33: O' Saquon You See | P33: 9 | Q33: 4 | R33: 0 | S33: 2 | T33: 1245.9 | U33: 1077.1
